Workbook

Sheet table_all
A1: adj ref | G1: 4 | H1: 7 | J1: 4 | K1: 7 | M1: 4 | N1: 7 | P1: 4 | Q1: 7 | S1: 4 | T1: 7 | V1: 4 | W1: 7 | Y1: 4 | Z1: 7 | AB1: 4 | AC1: 7 | AE1: 4 | AF1: 7
A2: col ref | B2: country | C2: d | D2: fb | E2: spb | G2: main_adjustment | H2: main_adjustment | J2: adverse_r_g | K2: adverse_r_g | M2: lower_spb | N2: lower_spb | P2: financial_stress | Q2: financial_stress | S2: stochastic | T2: stochastic | V2: deficit_reduction | W2: deficit_reduction | Y2: debt_safeguard | Z2: debt_safeguard | AB2: deficit_resilience | AC2: deficit_resilience | AE2: binding | AF2: binding
B3: Fiscal adjustment requirements under the new EU fiscal framework (structural primary balance measured in percent of GDP)
C5: European Commission forecasts for 2024 | G5: Min. SPB required by deterministic DSA | J5: Min. SPB required 'adverse r-g' scenario | M5: Min. SPB required 'lower SPB' scenario | P5: Min. SPB required 'financial stress' scenario | S5: Min. SPB required by stochastic DSA | V5: Min. SPB required by 3% deficit cap | Y5: Min. SPB required by EDP and the debt safeguard | AB5: Min. SPB required by EDP, debt safeguard and the deficit resilience safeguard | AE5: Minimum SPB satisfying all criteria | AH5: Average annual fiscal adjustment need
C7: Debt | D7: Fiscal balance | E7: SPB | G7: 4-year adj. | H7: 7-year adj. | J7: 4-year adj. | K7: 7-year adj. | M7: 4-year adj. | N7: 7-year adj. | P7: 4-year adj. | Q7: 7-year adj. | S7: 4-year adj. | T7: 7-year adj. | V7: 4-year adj. | W7: 7-year adj. | Y7: 4-year adj. | Z7: 7-year adj. | AB7: 4-year adj. | AC7: 7-year adj. | AE7: 4-year adj. | AF7: 7-year adj. | AH7: 4-year adj. | AI7: 7-year adj.
C8: (1) | D8: (2) | E8: (3) | G8: (4) | H8: (5) | J8: (6) | K8: (7) | M8: (8) | N8: (9) | P8: (10) | Q8: (11) | S8: (12) | T8: (13) | V8: (14) | W8: (15) | Y8: (16) | Z8: (17) | AB8: (18) | AC8: (19) | AE8: (19)=max(4,6,8,10,12,14,16,18) | AF8: (20)=max(5,7,9,11,13,15,17,19) | AH8: (21)={(19)-(3)}/4 | AI8: (22)={(20)-(3)}/7 | AK8: Legend
A9: GRC | B9: =INDEX(Table1[#All], MATCH($A9, ameco_2024_data!$A:$A, 0), MATCH(B$2, ameco_2024_data!$1:$1, 0)) -> Greece | C9: =INDEX(Table1[#All], MATCH($A9, ameco_2024_data!$A:$A, 0), MATCH(C$2, ameco_2024_data!$1:$1, 0)) -> 153.8524 | D9: =INDEX(Table1[#All], MATCH($A9, ameco_2024_data!$A:$A, 0), MATCH(D$2, ameco_2024_data!$1:$1, 0)) -> -1.1512785 | E9: =INDEX(Table1[#All], MATCH($A9, ameco_2024_data!$A:$A, 0), MATCH(E$2, ameco_2024_data!$1:$1, 0)) -> 1.7294 | G9: {=IF(INDEX(results_spb!$A$1:$Y$100, MATCH(1, (results_spb!$A$1:$A$100 = table_all!$B9) * (results_spb!$C$1:$C$100 = table_all!G$1), 0), MATCH(table_all!G$2, results_spb!$1:$1, 0)) = 0, "...", INDEX(results_spb!$A$1:$Y$100, MATCH(1, (results_spb!$A$1:$A$100 = table_all!$B9) * (results_spb!$C$1:$C$100 = table_all!G$1), 0), MATCH(table_all!G$2, results_spb!$1:$1, 0)))} -> 1.068 | H9: {=IF(INDEX(results_spb!$A$1:$Y$100, MATCH(1, (results_spb!$A$1:$A$100 = table_all!$B9) * (results_spb!$C$1:$C$100 = table_all!H$1), 0), MATCH(table_all!H$2, results_spb!$1:$1, 0)) = 0, "...", INDEX(results_spb!$A$1:$Y$100, MATCH(1, (results_spb!$A$1:$A$100 = table_all!$B9) * (results_spb!$C$1:$C$100 = table_all!H$1), 0), MATCH(table_all!H$2, results_spb!$1:$1, 0)))} -> 1.337 | J9: {=IF(INDEX(results_spb!$A$1:$Y$100, MATCH(1, (results_spb!$A$1:$A$100 = table_all!$B9) * (results_spb!$C$1:$C$100 = table_all!J$1), 0), MATCH(table_all!J$2, results_spb!$1:$1, 0)) = 0, "...", INDEX(results_spb!$A$1:$Y$100, MATCH(1, (results_spb!$A$1:$A$100 = table_all!$B9) * (results_spb!$C$1:$C$100 = table_all!J$1), 0), MATCH(table_all!J$2, results_spb!$1:$1, 0)))} -> 1.869 | K9: {=IF(INDEX(results_spb!$A$1:$Y$100, MATCH(1, (results_spb!$A$1:$A$100 = table_all!$B9) * (results_spb!$C$1:$C$100 = table_all!K$1), 0), MATCH(table_all!K$2, results_spb!$1:$1, 0)) = 0, "...", INDEX(results_spb!$A$1:$Y$100, MATCH(1, (results_spb!$A$1:$A$100 = table_all!$B9) * (results_spb!$C$1:$C$100 = table_all!K$1), 0), MATCH(table_all!K$2, results_spb!$1:$1, 0)))} -> 2.108 | M9: {=IF(INDEX(results_spb!$A$1:$Y$100, MATCH(1, (results_spb!$A$1:$A$100 = table_all!$B9) * (results_spb!$C$1:$C$100 = table_all!M$1), 0), MATCH(table_all!M$2, results_spb!$1:$1, 0)) = 0, "...", INDEX(results_spb!$A$1:$Y$100, MATCH(1, (results_spb!$A$1:$A$100 = table_all!$B9) * (results_spb!$C$1:$C$100 = table_all!M$1), 0), MATCH(table_all!M$2, results_spb!$1:$1, 0)))} -> 1.557 | N9: {=IF(INDEX(results_spb!$A$1:$Y$100, MATCH(1, (results_spb!$A$1:$A$100 = table_all!$B9) * (results_spb!$C$1:$C$100 = table_all!N$1), 0), MATCH(table_all!N$2, results_spb!$1:$1, 0)) = 0, "...", INDEX(results_spb!$A$1:$Y$100, MATCH(1, (results_spb!$A$1:$A$100 = table_all!$B9) * (results_spb!$C$1:$C$100 = table_all!N$1), 0), MATCH(table_all!N$2, results_spb!$1:$1, 0)))} -> 1.819 | P9: {=IF(INDEX(results_spb!$A$1:$Y$100, MATCH(1, (results_spb!$A$1:$A$100 = table_all!$B9) * (results_spb!$C$1:$C$100 = table_all!P$1), 0), MATCH(table_all!P$2, results_spb!$1:$1, 0)) = 0, "...", INDEX(results_spb!$A$1:$Y$100, MATCH(1, (results_spb!$A$1:$A$100 = table_all!$B9) * (results_spb!$C$1:$C$100 = table_all!P$1), 0), MATCH(table_all!P$2, results_spb!$1:$1, 0)))} -> 1.167 | Q9: {=IF(INDEX(results_spb!$A$1:$Y$100, MATCH(1, (results_spb!$A$1:$A$100 = table_all!$B9) * (results_spb!$C$1:$C$100 = table_all!Q$1), 0), MATCH(table_all!Q$2, results_spb!$1:$1, 0)) = 0, "...", INDEX(results_spb!$A$1:$Y$100, MATCH(1, (results_spb!$A$1:$A$100 = table_all!$B9) * (results_spb!$C$1:$C$100 = table_all!Q$1), 0), MATCH(table_all!Q$2, results_spb!$1:$1, 0)))} -> 1.41 | S9: {=IF(INDEX(results_spb!$A$1:$Y$100, MATCH(1, (results_spb!$A$1:$A$100 = table_all!$B9) * (results_spb!$C$1:$C$100 = table_all!S$1), 0), MATCH(table_all!S$2, results_spb!$1:$1, 0)) = 0, "...", INDEX(results_spb!$A$1:$Y$100, MATCH(1, (results_spb!$A$1:$A$100 = table_all!$B9) * (results_spb!$C$1:$C$100 = table_all!S$1), 0), MATCH(table_all!S$2, results_spb!$1:$1, 0)))} -> 0.897 | T9: {=IF(INDEX(results_spb!$A$1:$Y$100, MATCH(1, (results_spb!$A$1:$A$100 = table_all!$B9) * (results_spb!$C$1:$C$100 = table_all!T$1), 0), MATCH(table_all!T$2, results_spb!$1:$1, 0)) = 0, "...", INDEX(results_spb!$A$1:$Y$100, MATCH(1, (results_spb!$A$1:$A$100 = table_all!$B9) * (results_spb!$C$1:$C$100 = table_all!T$1), 0), MATCH(table_all!T$2, results_spb!$1:$1, 0)))} -> 1.956 | V9: {=IF(INDEX(results_spb!$A$1:$Y$100, MATCH(1, (results_spb!$A$1:$A$100 = table_all!$B9) * (results_spb!$C$1:$C$100 = table_all!V$1), 0), MATCH(table_all!V$2, results_spb!$1:$1, 0)) = 0, "...", INDEX(results_spb!$A$1:$Y$100, MATCH(1, (results_spb!$A$1:$A$100 = table_all!$B9) * (results_spb!$C$1:$C$100 = table_all!V$1), 0), MATCH(table_all!V$2, results_spb!$1:$1, 0)))} -> 1.745 | W9: {=IF(INDEX(results_spb!$A$1:$Y$100, MATCH(1, (results_spb!$A$1:$A$100 = table_all!$B9) * (results_spb!$C$1:$C$100 = table_all!W$1), 0), MATCH(table_all!W$2, results_spb!$1:$1, 0)) = 0, "...", INDEX(results_spb!$A$1:$Y$100, MATCH(1, (results_spb!$A$1:$A$100 = table_all!$B9) * (results_spb!$C$1:$C$100 = table_all!W$1), 0), MATCH(table_all!W$2, results_spb!$1:$1, 0)))} -> 2.056 | Y9: {=IF(INDEX(results_spb!$A$1:$Y$100, MATCH(1, (results_spb!$A$1:$A$100 = table_all!$B9) * (results_spb!$C$1:$C$100 = table_all!Y$1), 0), MATCH(table_all!Y$2, results_spb!$1:$1, 0)) = 0, "...", INDEX(results_spb!$A$1:$Y$100, MATCH(1, (results_spb!$A$1:$A$100 = table_all!$B9) * (results_spb!$C$1:$C$100 = table_all!Y$1), 0), MATCH(table_all!Y$2, results_spb!$1:$1, 0)))} -> ... | Z9: {=IF(INDEX(results_spb!$A$1:$Y$100, MATCH(1, (results_spb!$A$1:$A$100 = table_all!$B9) * (results_spb!$C$1:$C$100 = table_all!Z$1), 0), MATCH(table_all!Z$2, results_spb!$1:$1, 0)) = 0, "...", INDEX(results_spb!$A$1:$Y$100, MATCH(1, (results_spb!$A$1:$A$100 = table_all!$B9) * (results_spb!$C$1:$C$100 = table_all!Z$1), 0), MATCH(table_all!Z$2, results_spb!$1:$1, 0)))} -> ... | AB9: {=IF(INDEX(results_spb!$A$1:$Y$100, MATCH(1, (results_spb!$A$1:$A$100 = table_all!$B9) * (results_spb!$C$1:$C$100 = table_all!AB$1), 0), MATCH(table_all!AB$2, results_spb!$1:$1, 0)) = 0, "...", INDEX(results_spb!$A$1:$Y$100, MATCH(1, (results_spb!$A$1:$A$100 = table_all!$B9) * (results_spb!$C$1:$C$100 = table_all!AB$1), 0), MATCH(table_all!AB$2, results_spb!$1:$1, 0)))} -> ... | AC9: {=IF(INDEX(results_spb!$A$1:$Y$100, MATCH(1, (results_spb!$A$1:$A$100 = table_all!$B9) * (results_spb!$C$1:$C$100 = table_all!AC$1), 0), MATCH(table_all!AC$2, results_spb!$1:$1, 0)) = 0, "...", INDEX(results_spb!$A$1:$Y$100, MATCH(1, (results_spb!$A$1:$A$100 = table_all!$B9) * (results_spb!$C$1:$C$100 = table_all!AC$1), 0), MATCH(table_all!AC$2, results_spb!$1:$1, 0)))} -> ... | AE9: =MAX(G9,J9,M9,P9,S9,V9,Y9,AB9) -> 1.869 | AF9: =MAX(H9,K9,N9,Q9,T9,W9,Z9,AC9) -> 2.108 | AH9: =(AE9-$E9)/4 -> 0.0349 | AI9: =(AF9-$E9)/7 -> 0.054085714 | AL9: Binding deterministic scenario
A10: ITA | B10: =INDEX(Table1[#All], MATCH($A10, ameco_2024_data!$A:$A, 0), MATCH(B$2, ameco_2024_data!$1:$1, 0)) -> Italy | C10: =INDEX(Table1[#All], MATCH($A10, ameco_2024_data!$A:$A, 0), MATCH(C$2, ameco_2024_data!$1:$1, 0)) -> 138.6244 | D10: =INDEX(Table1[#All], MATCH($A10, ameco_2024_data!$A:$A, 0), MATCH(D$2, ameco_2024_data!$1:$1, 0)) -> -4.4258339 | E10: =INDEX(Table1[#All], MATCH($A10, ameco_2024_data!$A:$A, 0), MATCH(E$2, ameco_2024_data!$1:$1, 0)) -> -1.0503 | G10: {=IF(INDEX(results_spb!$A$1:$Y$100, MATCH(1, (results_spb!$A$1:$A$100 = table_all!$B10) * (results_spb!$C$1:$C$100 = table_all!G$1), 0), MATCH(table_all!G$2, results_spb!$1:$1, 0)) = 0, "...", INDEX(results_spb!$A$1:$Y$100, MATCH(1, (results_spb!$A$1:$A$100 = table_all!$B10) * (results_spb!$C$1:$C$100 = table_all!G$1), 0), MATCH(table_all!G$2, results_spb!$1:$1, 0)))} -> 2.224 | H10: {=IF(INDEX(results_spb!$A$1:$Y$100, MATCH(1, (results_spb!$A$1:$A$100 = table_all!$B10) * (results_spb!$C$1:$C$100 = table_all!H$1), 0), MATCH(table_all!H$2, results_spb!$1:$1, 0)) = 0, "...", INDEX(results_spb!$A$1:$Y$100, MATCH(1, (results_spb!$A$1:$A$100 = table_all!$B10) * (results_spb!$C$1:$C$100 = table_all!H$1), 0), MATCH(table_all!H$2, results_spb!$1:$1, 0)))} -> 2.009 | J10: {=IF(INDEX(results_spb!$A$1:$Y$100, MATCH(1, (results_spb!$A$1:$A$100 = table_all!$B10) * (results_spb!$C$1:$C$100 = table_all!J$1), 0), MATCH(table_all!J$2, results_spb!$1:$1, 0)) = 0, "...", INDEX(results_spb!$A$1:$Y$100, MATCH(1, (results_spb!$A$1:$A$100 = table_all!$B10) * (results_spb!$C$1:$C$100 = table_all!J$1), 0), MATCH(table_all!J$2, results_spb!$1:$1, 0)))} -> 3.286 | K10: {=IF(INDEX(results_spb!$A$1:$Y$100, MATCH(1, (results_spb!$A$1:$A$100 = table_all!$B10) * (results_spb!$C$1:$C$100 = table_all!K$1), 0), MATCH(table_all!K$2, results_spb!$1:$1, 0)) = 0, "...", INDEX(results_spb!$A$1:$Y$100, MATCH(1, (results_spb!$A$1:$A$100 = table_all!$B10) * (results_spb!$C$1:$C$100 = table_all!K$1), 0), MATCH(table_all!K$2, results_spb!$1:$1, 0)))} -> 2.997 | M10: {=IF(INDEX(results_spb!$A$1:$Y$100, MATCH(1, (results_spb!$A$1:$A$100 = table_all!$B10) * (results_spb!$C$1:$C$100 = table_all!M$1), 0), MATCH(table_all!M$2, results_spb!$1:$1, 0)) = 0, "...", INDEX(results_spb!$A$1:$Y$100, MATCH(1, (results_spb!$A$1:$A$100 = table_all!$B10) * (results_spb!$C$1:$C$100 = table_all!M$1), 0), MATCH(table_all!M$2, results_spb!$1:$1, 0)))} -> 2.703 | N10: {=IF(INDEX(results_spb!$A$1:$Y$100, MATCH(1, (results_spb!$A$1:$A$100 = table_all!$B10) * (results_spb!$C$1:$C$100 = table_all!N$1), 0), MATCH(table_all!N$2, results_spb!$1:$1, 0)) = 0, "...", INDEX(results_spb!$A$1:$Y$100, MATCH(1, (results_spb!$A$1:$A$100 = table_all!$B10) * (results_spb!$C$1:$C$100 = table_all!N$1), 0), MATCH(table_all!N$2, results_spb!$1:$1, 0)))} -> 2.57 | P10: {=IF(INDEX(results_spb!$A$1:$Y$100, MATCH(1, (results_spb!$A$1:$A$100 = table_all!$B10) * (results_spb!$C$1:$C$100 = table_all!P$1), 0), MATCH(table_all!P$2, results_spb!$1:$1, 0)) = 0, "...", INDEX(results_spb!$A$1:$Y$100, MATCH(1, (results_spb!$A$1:$A$100 = table_all!$B10) * (results_spb!$C$1:$C$100 = table_all!P$1), 0), MATCH(table_all!P$2, results_spb!$1:$1, 0)))} -> 2.542 | Q10: {=IF(INDEX(results_spb!$A$1:$Y$100, MATCH(1, (results_spb!$A$1:$A$100 = table_all!$B10) * (results_spb!$C$1:$C$100 = table_all!Q$1), 0), MATCH(table_all!Q$2, results_spb!$1:$1, 0)) = 0, "...", INDEX(results_spb!$A$1:$Y$100, MATCH(1, (results_spb!$A$1:$A$100 = table_all!$B10) * (results_spb!$C$1:$C$100 = table_all!Q$1), 0), MATCH(table_all!Q$2, results_spb!$1:$1, 0)))} -> 2.742 | S10: {=IF(INDEX(results_spb!$A$1:$Y$100, MATCH(1, (results_spb!$A$1:$A$100 = table_all!$B10) * (results_spb!$C$1:$C$100 = table_all!S$1), 0), MATCH(table_all!S$2, results_spb!$1:$1, 0)) = 0, "...", INDEX(results_spb!$A$1:$Y$100, MATCH(1, (results_spb!$A$1:$A$100 = table_all!$B10) * (results_spb!$C$1:$C$100 = table_all!S$1), 0), MATCH(table_all!S$2, results_spb!$1:$1, 0)))} -> 2.471 | T10: {=IF(INDEX(results_spb!$A$1:$Y$100, MATCH(1, (results_spb!$A$1:$A$100 = table_all!$B10) * (results_spb!$C$1:$C$100 = table_all!T$1), 0), MATCH(table_all!T$2, results_spb!$1:$1, 0)) = 0, "...", INDEX(results_spb!$A$1:$Y$100, MATCH(1, (results_spb!$A$1:$A$100 = table_all!$B10) * (results_spb!$C$1:$C$100 = table_all!T$1), 0), MATCH(table_all!T$2, results_spb!$1:$1, 0)))} -> 2.771 | V10: {=IF(INDEX(results_spb!$A$1:$Y$100, MATCH(1, (results_spb!$A$1:$A$100 = table_all!$B10) * (results_spb!$C$1:$C$100 = table_all!V$1), 0), MATCH(table_all!V$2, results_spb!$1:$1, 0)) = 0, "...", INDEX(results_spb!$A$1:$Y$100, MATCH(1, (results_spb!$A$1:$A$100 = table_all!$B10) * (results_spb!$C$1:$C$100 = table_all!V$1), 0), MATCH(table_all!V$2, results_spb!$1:$1, 0)))} -> 3.168 | W10: {=IF(INDEX(results_spb!$A$1:$Y$100, MATCH(1, (results_spb!$A$1:$A$100 = table_all!$B10) * (results_spb!$C$1:$C$100 = table_all!W$1), 0), MATCH(table_all!W$2, results_spb!$1:$1, 0)) = 0, "...", INDEX(results_spb!$A$1:$Y$100, MATCH(1, (results_spb!$A$1:$A$100 = table_all!$B10) * (results_spb!$C$1:$C$100 = table_all!W$1), 0), MATCH(table_all!W$2, results_spb!$1:$1, 0)))} -> 3.124 | Y10: {=IF(INDEX(results_spb!$A$1:$Y$100, MATCH(1, (results_spb!$A$1:$A$100 = table_all!$B10) * (results_spb!$C$1:$C$100 = table_all!Y$1), 0), MATCH(table_all!Y$2, results_spb!$1:$1, 0)) = 0, "...", INDEX(results_spb!$A$1:$Y$100, MATCH(1, (results_spb!$A$1:$A$100 = table_all!$B10) * (results_spb!$C$1:$C$100 = table_all!Y$1), 0), MATCH(table_all!Y$2, results_spb!$1:$1, 0)))} -> ... | Z10: {=IF(INDEX(results_spb!$A$1:$Y$100, MATCH(1, (results_spb!$A$1:$A$100 = table_all!$B10) * (results_spb!$C$1:$C$100 = table_all!Z$1), 0), MATCH(table_all!Z$2, results_spb!$1:$1, 0)) = 0, "...", INDEX(results_spb!$A$1:$Y$100, MATCH(1, (results_spb!$A$1:$A$100 = table_all!$B10) * (results_spb!$C$1:$C$100 = table_all!Z$1), 0), MATCH(table_all!Z$2, results_spb!$1:$1, 0)))} -> ... | AB10: {=IF(INDEX(results_spb!$A$1:$Y$100, MATCH(1, (results_spb!$A$1:$A$100 = table_all!$B10) * (results_spb!$C$1:$C$100 = table_all!AB$1), 0), MATCH(table_all!AB$2, results_spb!$1:$1, 0)) = 0, "...", INDEX(results_spb!$A$1:$Y$100, MATCH(1, (results_spb!$A$1:$A$100 = table_all!$B10) * (results_spb!$C$1:$C$100 = table_all!AB$1), 0), MATCH(table_all!AB$2, results_spb!$1:$1, 0)))} -> ... | AC10: {=IF(INDEX(results_spb!$A$1:$Y$100, MATCH(1, (results_spb!$A$1:$A$100 = table_all!$B10) * (results_spb!$C$1:$C$100 = table_all!AC$1), 0), MATCH(table_all!AC$2, results_spb!$1:$1, 0)) = 0, "...", INDEX(results_spb!$A$1:$Y$100, MATCH(1, (results_spb!$A$1:$A$100 = table_all!$B10) * (results_spb!$C$1:$C$100 = table_all!AC$1), 0), MATCH(table_all!AC$2, results_spb!$1:$1, 0)))} -> ... | AE10: =MAX(G10,J10,M10,P10,S10,V10,Y10,AB10) -> 3.286 | AF10: =MAX(H10,K10,N10,Q10,T10,W10,Z10,AC10) -> 3.124 | AH10: =(AE10-$E10)/4 -> 1.084075 | AI10: =(AF10-$E10)/7 -> 0.59632857 | AL10: Binding stochastic criterion
A11: FRA | B11: =INDEX(Table1[#All], MATCH($A11, ameco_2024_data!$A:$A, 0), MATCH(B$2, ameco_2024_data!$1:$1, 0)) -> France | C11: =INDEX(Table1[#All], MATCH($A11, ameco_2024_data!$A:$A, 0), MATCH(C$2, ameco_2024_data!$1:$1, 0)) -> 112.4088 | D11: =INDEX(Table1[#All], MATCH($A11, ameco_2024_data!$A:$A, 0), MATCH(D$2, ameco_2024_data!$1:$1, 0)) -> -5.3136057 | E11: =INDEX(Table1[#All], MATCH($A11, ameco_2024_data!$A:$A, 0), MATCH(E$2, ameco_2024_data!$1:$1, 0)) -> -2.9684 | G11: {=IF(INDEX(results_spb!$A$1:$Y$100, MATCH(1, (results_spb!$A$1:$A$100 = table_all!$B11) * (results_spb!$C$1:$C$100 = table_all!G$1), 0), MATCH(table_all!G$2, results_spb!$1:$1, 0)) = 0, "...", INDEX(results_spb!$A$1:$Y$100, MATCH(1, (results_spb!$A$1:$A$100 = table_all!$B11) * (results_spb!$C$1:$C$100 = table_all!G$1), 0), MATCH(table_all!G$2, results_spb!$1:$1, 0)))} -> -0.095 | H11: {=IF(INDEX(results_spb!$A$1:$Y$100, MATCH(1, (results_spb!$A$1:$A$100 = table_all!$B11) * (results_spb!$C$1:$C$100 = table_all!H$1), 0), MATCH(table_all!H$2, results_spb!$1:$1, 0)) = 0, "...", INDEX(results_spb!$A$1:$Y$100, MATCH(1, (results_spb!$A$1:$A$100 = table_all!$B11) * (results_spb!$C$1:$C$100 = table_all!H$1), 0), MATCH(table_all!H$2, results_spb!$1:$1, 0)))} -> -0.023 | J11: {=IF(INDEX(results_spb!$A$1:$Y$100, MATCH(1, (results_spb!$A$1:$A$100 = table_all!$B11) * (results_spb!$C$1:$C$100 = table_all!J$1), 0), MATCH(table_all!J$2, results_spb!$1:$1, 0)) = 0, "...", INDEX(results_spb!$A$1:$Y$100, MATCH(1, (results_spb!$A$1:$A$100 = table_all!$B11) * (results_spb!$C$1:$C$100 = table_all!J$1), 0), MATCH(table_all!J$2, results_spb!$1:$1, 0)))} -> 0.772 | K11: {=IF(INDEX(results_spb!$A$1:$Y$100, MATCH(1, (results_spb!$A$1:$A$100 = table_all!$B11) * (results_spb!$C$1:$C$100 = table_all!K$1), 0), MATCH(table_all!K$2, results_spb!$1:$1, 0)) = 0, "...", INDEX(results_spb!$A$1:$Y$100, MATCH(1, (results_spb!$A$1:$A$100 = table_all!$B11) * (results_spb!$C$1:$C$100 = table_all!K$1), 0), MATCH(table_all!K$2, results_spb!$1:$1, 0)))} -> 0.795 | M11: {=IF(INDEX(results_spb!$A$1:$Y$100, MATCH(1, (results_spb!$A$1:$A$100 = table_all!$B11) * (results_spb!$C$1:$C$100 = table_all!M$1), 0), MATCH(table_all!M$2, results_spb!$1:$1, 0)) = 0, "...", INDEX(results_spb!$A$1:$Y$100, MATCH(1, (results_spb!$A$1:$A$100 = table_all!$B11) * (results_spb!$C$1:$C$100 = table_all!M$1), 0), MATCH(table_all!M$2, results_spb!$1:$1, 0)))} -> 0.495 | N11: {=IF(INDEX(results_spb!$A$1:$Y$100, MATCH(1, (results_spb!$A$1:$A$100 = table_all!$B11) * (results_spb!$C$1:$C$100 = table_all!N$1), 0), MATCH(table_all!N$2, results_spb!$1:$1, 0)) = 0, "...", INDEX(results_spb!$A$1:$Y$100, MATCH(1, (results_spb!$A$1:$A$100 = table_all!$B11) * (results_spb!$C$1:$C$100 = table_all!N$1), 0), MATCH(table_all!N$2, results_spb!$1:$1, 0)))} -> 0.533 | P11: {=IF(INDEX(results_spb!$A$1:$Y$100, MATCH(1, (results_spb!$A$1:$A$100 = table_all!$B11) * (results_spb!$C$1:$C$100 = table_all!P$1), 0), MATCH(table_all!P$2, results_spb!$1:$1, 0)) = 0, "...", INDEX(results_spb!$A$1:$Y$100, MATCH(1, (results_spb!$A$1:$A$100 = table_all!$B11) * (results_spb!$C$1:$C$100 = table_all!P$1), 0), MATCH(table_all!P$2, results_spb!$1:$1, 0)))} -> 0.236 | Q11: {=IF(INDEX(results_spb!$A$1:$Y$100, MATCH(1, (results_spb!$A$1:$A$100 = table_all!$B11) * (results_spb!$C$1:$C$100 = table_all!Q$1), 0), MATCH(table_all!Q$2, results_spb!$1:$1, 0)) = 0, "...", INDEX(results_spb!$A$1:$Y$100, MATCH(1, (results_spb!$A$1:$A$100 = table_all!$B11) * (results_spb!$C$1:$C$100 = table_all!Q$1), 0), MATCH(table_all!Q$2, results_spb!$1:$1, 0)))} -> 0.383 | S11: {=IF(INDEX(results_spb!$A$1:$Y$100, MATCH(1, (results_spb!$A$1:$A$100 = table_all!$B11) * (results_spb!$C$1:$C$100 = table_all!S$1), 0), MATCH(table_all!S$2, results_spb!$1:$1, 0)) = 0, "...", INDEX(results_spb!$A$1:$Y$100, MATCH(1, (results_spb!$A$1:$A$100 = table_all!$B11) * (results_spb!$C$1:$C$100 = table_all!S$1), 0), MATCH(table_all!S$2, results_spb!$1:$1, 0)))} -> 0.482 | T11: {=IF(INDEX(results_spb!$A$1:$Y$100, MATCH(1, (results_spb!$A$1:$A$100 = table_all!$B11) * (results_spb!$C$1:$C$100 = table_all!T$1), 0), MATCH(table_all!T$2, results_spb!$1:$1, 0)) = 0, "...", INDEX(results_spb!$A$1:$Y$100, MATCH(1, (results_spb!$A$1:$A$100 = table_all!$B11) * (results_spb!$C$1:$C$100 = table_all!T$1), 0), MATCH(table_all!T$2, results_spb!$1:$1, 0)))} -> 0.587 | V11: {=IF(INDEX(results_spb!$A$1:$Y$100, MATCH(1, (results_spb!$A$1:$A$100 = table_all!$B11) * (results_spb!$C$1:$C$100 = table_all!V$1), 0), MATCH(table_all!V$2, results_spb!$1:$1, 0)) = 0, "...", INDEX(results_spb!$A$1:$Y$100, MATCH(1, (results_spb!$A$1:$A$100 = table_all!$B11) * (results_spb!$C$1:$C$100 = table_all!V$1), 0), MATCH(table_all!V$2, results_spb!$1:$1, 0)))} -> 0.673 | W11: {=IF(INDEX(results_spb!$A$1:$Y$100, MATCH(1, (results_spb!$A$1:$A$100 = table_all!$B11) * (results_spb!$C$1:$C$100 = table_all!W$1), 0), MATCH(table_all!W$2, results_spb!$1:$1, 0)) = 0, "...", INDEX(results_spb!$A$1:$Y$100, MATCH(1, (results_spb!$A$1:$A$100 = table_all!$B11) * (results_spb!$C$1:$C$100 = table_all!W$1), 0), MATCH(table_all!W$2, results_spb!$1:$1, 0)))} -> 0.753 | Y11: {=IF(INDEX(results_spb!$A$1:$Y$100, MATCH(1, (results_spb!$A$1:$A$100 = table_all!$B11) * (results_spb!$C$1:$C$100 = table_all!Y$1), 0), MATCH(table_all!Y$2, results_spb!$1:$1, 0)) = 0, "...", INDEX(results_spb!$A$1:$Y$100, MATCH(1, (results_spb!$A$1:$A$100 = table_all!$B11) * (results_spb!$C$1:$C$100 = table_all!Y$1), 0), MATCH(table_all!Y$2, results_spb!$1:$1, 0)))} -> ... | Z11: {=IF(INDEX(results_spb!$A$1:$Y$100, MATCH(1, (results_spb!$A$1:$A$100 = table_all!$B11) * (results_spb!$C$1:$C$100 = table_all!Z$1), 0), MATCH(table_all!Z$2, results_spb!$1:$1, 0)) = 0, "...", INDEX(results_spb!$A$1:$Y$100, MATCH(1, (results_spb!$A$1:$A$100 = table_all!$B11) * (results_spb!$C$1:$C$100 = table_all!Z$1), 0), MATCH(table_all!Z$2, results_spb!$1:$1, 0)))} -> ... | AB11: {=IF(INDEX(results_spb!$A$1:$Y$100, MATCH(1, (results_spb!$A$1:$A$100 = table_all!$B11) * (results_spb!$C$1:$C$100 = table_all!AB$1), 0), MATCH(table_all!AB$2, results_spb!$1:$1, 0)) = 0, "...", INDEX(results_spb!$A$1:$Y$100, MATCH(1, (results_spb!$A$1:$A$100 = table_all!$B11) * (results_spb!$C$1:$C$100 = table_all!AB$1), 0), MATCH(table_all!AB$2, results_spb!$1:$1, 0)))} -> ... | AC11: {=IF(INDEX(results_spb!$A$1:$Y$100, MATCH(1, (results_spb!$A$1:$A$100 = table_all!$B11) * (results_spb!$C$1:$C$100 = table_all!AC$1), 0), MATCH(table_all!AC$2, results_spb!$1:$1, 0)) = 0, "...", INDEX(results_spb!$A$1:$Y$100, MATCH(1, (results_spb!$A$1:$A$100 = table_all!$B11) * (results_spb!$C$1:$C$100 = table_all!AC$1), 0), MATCH(table_all!AC$2, results_spb!$1:$1, 0)))} -> 0.814 | AE11: =MAX(G11,J11,M11,P11,S11,V11,Y11,AB11) -> 0.772 | AF11: =MAX(H11,K11,N11,Q11,T11,W11,Z11,AC11) -> 0.814 | AH11: =(AE11-$E11)/4 -> 0.9351 | AI11: =(AF11-$E11)/7 -> 0.54034286 | AL11: Binding 3% deficit cap
A12: ESP | B12: =INDEX(Table1[#All], MATCH($A12, ameco_2024_data!$A:$A, 0), MATCH(B$2, ameco_2024_data!$1:$1, 0)) -> Spain | C12: =INDEX(Table1[#All], MATCH($A12, ameco_2024_data!$A:$A, 0), MATCH(C$2, ameco_2024_data!$1:$1, 0)) -> 105.5079 | D12: =INDEX(Table1[#All], MATCH($A12, ameco_2024_data!$A:$A, 0), MATCH(D$2, ameco_2024_data!$1:$1, 0)) -> -2.986415 | E12: =INDEX(Table1[#All], MATCH($A12, ameco_2024_data!$A:$A, 0), MATCH(E$2, ameco_2024_data!$1:$1, 0)) -> -0.849 | G12: {=IF(INDEX(results_spb!$A$1:$Y$100, MATCH(1, (results_spb!$A$1:$A$100 = table_all!$B12) * (results_spb!$C$1:$C$100 = table_all!G$1), 0), MATCH(table_all!G$2, results_spb!$1:$1, 0)) = 0, "...", INDEX(results_spb!$A$1:$Y$100, MATCH(1, (results_spb!$A$1:$A$100 = table_all!$B12) * (results_spb!$C$1:$C$100 = table_all!G$1), 0), MATCH(table_all!G$2, results_spb!$1:$1, 0)))} -> 2.047 | H12: {=IF(INDEX(results_spb!$A$1:$Y$100, MATCH(1, (results_spb!$A$1:$A$100 = table_all!$B12) * (results_spb!$C$1:$C$100 = table_all!H$1), 0), MATCH(table_all!H$2, results_spb!$1:$1, 0)) = 0, "...", INDEX(results_spb!$A$1:$Y$100, MATCH(1, (results_spb!$A$1:$A$100 = table_all!$B12) * (results_spb!$C$1:$C$100 = table_all!H$1), 0), MATCH(table_all!H$2, results_spb!$1:$1, 0)))} -> 2.108 | J12: {=IF(INDEX(results_spb!$A$1:$Y$100, MATCH(1, (results_spb!$A$1:$A$100 = table_all!$B12) * (results_spb!$C$1:$C$100 = table_all!J$1), 0), MATCH(table_all!J$2, results_spb!$1:$1, 0)) = 0, "...", INDEX(results_spb!$A$1:$Y$100, MATCH(1, (results_spb!$A$1:$A$100 = table_all!$B12) * (results_spb!$C$1:$C$100 = table_all!J$1), 0), MATCH(table_all!J$2, results_spb!$1:$1, 0)))} -> 2.73 | K12: {=IF(INDEX(results_spb!$A$1:$Y$100, MATCH(1, (results_spb!$A$1:$A$100 = table_all!$B12) * (results_spb!$C$1:$C$100 = table_all!K$1), 0), MATCH(table_all!K$2, results_spb!$1:$1, 0)) = 0, "...", INDEX(results_spb!$A$1:$Y$100, MATCH(1, (results_spb!$A$1:$A$100 = table_all!$B12) * (results_spb!$C$1:$C$100 = table_all!K$1), 0), MATCH(table_all!K$2, results_spb!$1:$1, 0)))} -> 2.777 | M12: {=IF(INDEX(results_spb!$A$1:$Y$100, MATCH(1, (results_spb!$A$1:$A$100 = table_all!$B12) * (results_spb!$C$1:$C$100 = table_all!M$1), 0), MATCH(table_all!M$2, results_spb!$1:$1, 0)) = 0, "...", INDEX(results_spb!$A$1:$Y$100, MATCH(1, (results_spb!$A$1:$A$100 = table_all!$B12) * (results_spb!$C$1:$C$100 = table_all!M$1), 0), MATCH(table_all!M$2, results_spb!$1:$1, 0)))} -> 2.541 | N12: {=IF(INDEX(results_spb!$A$1:$Y$100, MATCH(1, (results_spb!$A$1:$A$100 = table_all!$B12) * (results_spb!$C$1:$C$100 = table_all!N$1), 0), MATCH(table_all!N$2, results_spb!$1:$1, 0)) = 0, "...", INDEX(results_spb!$A$1:$Y$100, MATCH(1, (results_spb!$A$1:$A$100 = table_all!$B12) * (results_spb!$C$1:$C$100 = table_all!N$1), 0), MATCH(table_all!N$2, results_spb!$1:$1, 0)))} -> 2.599 | P12: {=IF(INDEX(results_spb!$A$1:$Y$100, MATCH(1, (results_spb!$A$1:$A$100 = table_all!$B12) * (results_spb!$C$1:$C$100 = table_all!P$1), 0), MATCH(table_all!P$2, results_spb!$1:$1, 0)) = 0, "...", INDEX(results_spb!$A$1:$Y$100, MATCH(1, (results_spb!$A$1:$A$100 = table_all!$B12) * (results_spb!$C$1:$C$100 = table_all!P$1), 0), MATCH(table_all!P$2, results_spb!$1:$1, 0)))} -> 2.095 | Q12: {=IF(INDEX(results_spb!$A$1:$Y$100, MATCH(1, (results_spb!$A$1:$A$100 = table_all!$B12) * (results_spb!$C$1:$C$100 = table_all!Q$1), 0), MATCH(table_all!Q$2, results_spb!$1:$1, 0)) = 0, "...", INDEX(results_spb!$A$1:$Y$100, MATCH(1, (results_spb!$A$1:$A$100 = table_all!$B12) * (results_spb!$C$1:$C$100 = table_all!Q$1), 0), MATCH(table_all!Q$2, results_spb!$1:$1, 0)))} -> 2.147 | S12: {=IF(INDEX(results_spb!$A$1:$Y$100, MATCH(1, (results_spb!$A$1:$A$100 = table_all!$B12) * (results_spb!$C$1:$C$100 = table_all!S$1), 0), MATCH(table_all!S$2, results_spb!$1:$1, 0)) = 0, "...", INDEX(results_spb!$A$1:$Y$100, MATCH(1, (results_spb!$A$1:$A$100 = table_all!$B12) * (results_spb!$C$1:$C$100 = table_all!S$1), 0), MATCH(table_all!S$2, results_spb!$1:$1, 0)))} -> 1.075 | T12: {=IF(INDEX(results_spb!$A$1:$Y$100, MATCH(1, (results_spb!$A$1:$A$100 = table_all!$B12) * (results_spb!$C$1:$C$100 = table_all!T$1), 0), MATCH(table_all!T$2, results_spb!$1:$1, 0)) = 0, "...", INDEX(results_spb!$A$1:$Y$100, MATCH(1, (results_spb!$A$1:$A$100 = table_all!$B12) * (results_spb!$C$1:$C$100 = table_all!T$1), 0), MATCH(table_all!T$2, results_spb!$1:$1, 0)))} -> 1.668 | V12: {=IF(INDEX(results_spb!$A$1:$Y$100, MATCH(1, (results_spb!$A$1:$A$100 = table_all!$B12) * (results_spb!$C$1:$C$100 = table_all!V$1), 0), MATCH(table_all!V$2, results_spb!$1:$1, 0)) = 0, "...", INDEX(results_spb!$A$1:$Y$100, MATCH(1, (results_spb!$A$1:$A$100 = table_all!$B12) * (results_spb!$C$1:$C$100 = table_all!V$1), 0), MATCH(table_all!V$2, results_spb!$1:$1, 0)))} -> 2.207 | W12: {=IF(INDEX(results_spb!$A$1:$Y$100, MATCH(1, (results_spb!$A$1:$A$100 = table_all!$B12) * (results_spb!$C$1:$C$100 = table_all!W$1), 0), MATCH(table_all!W$2, results_spb!$1:$1, 0)) = 0, "...", INDEX(results_spb!$A$1:$Y$100, MATCH(1, (results_spb!$A$1:$A$100 = table_all!$B12) * (results_spb!$C$1:$C$100 = table_all!W$1), 0), MATCH(table_all!W$2, results_spb!$1:$1, 0)))} -> 2.274 | Y12: {=IF(INDEX(results_spb!$A$1:$Y$100, MATCH(1, (results_spb!$A$1:$A$100 = table_all!$B12) * (results_spb!$C$1:$C$100 = table_all!Y$1), 0), MATCH(table_all!Y$2, results_spb!$1:$1, 0)) = 0, "...", INDEX(results_spb!$A$1:$Y$100, MATCH(1, (results_spb!$A$1:$A$100 = table_all!$B12) * (results_spb!$C$1:$C$100 = table_all!Y$1), 0), MATCH(table_all!Y$2, results_spb!$1:$1, 0)))} -> ... | Z12: {=IF(INDEX(results_spb!$A$1:$Y$100, MATCH(1, (results_spb!$A$1:$A$100 = table_all!$B12) * (results_spb!$C$1:$C$100 = table_all!Z$1), 0), MATCH(table_all!Z$2, results_spb!$1:$1, 0)) = 0, "...", INDEX(results_spb!$A$1:$Y$100, MATCH(1, (results_spb!$A$1:$A$100 = table_all!$B12) * (results_spb!$C$1:$C$100 = table_all!Z$1), 0), MATCH(table_all!Z$2, results_spb!$1:$1, 0)))} -> ... | AB12: {=IF(INDEX(results_spb!$A$1:$Y$100, MATCH(1, (results_spb!$A$1:$A$100 = table_all!$B12) * (results_spb!$C$1:$C$100 = table_all!AB$1), 0), MATCH(table_all!AB$2, results_spb!$1:$1, 0)) = 0, "...", INDEX(results_spb!$A$1:$Y$100, MATCH(1, (results_spb!$A$1:$A$100 = table_all!$B12) * (results_spb!$C$1:$C$100 = table_all!AB$1), 0), MATCH(table_all!AB$2, results_spb!$1:$1, 0)))} -> ... | AC12: {=IF(INDEX(results_spb!$A$1:$Y$100, MATCH(1, (results_spb!$A$1:$A$100 = table_all!$B12) * (results_spb!$C$1:$C$100 = table_all!AC$1), 0), MATCH(table_all!AC$2, results_spb!$1:$1, 0)) = 0, "...", INDEX(results_spb!$A$1:$Y$100, MATCH(1, (results_spb!$A$1:$A$100 = table_all!$B12) * (results_spb!$C$1:$C$100 = table_all!AC$1), 0), MATCH(table_all!AC$2, results_spb!$1:$1, 0)))} -> ... | AE12: =MAX(G12,J12,M12,P12,S12,V12,Y12,AB12) -> 2.73 | AF12: =MAX(H12,K12,N12,Q12,T12,W12,Z12,AC12) -> 2.777 | AH12: =(AE12-$E12)/4 -> 0.89475 | AI12: =(AF12-$E12)/7 -> 0.518 | AL12: Binding debt sustainability safeguard
A13: BEL | B13: =INDEX(Table1[#All], MATCH($A13, ameco_2024_data!$A:$A, 0), MATCH(B$2, ameco_2024_data!$1:$1, 0)) -> Belgium | C13: =INDEX(Table1[#All], MATCH($A13, ameco_2024_data!$A:$A, 0), MATCH(C$2, ameco_2024_data!$1:$1, 0)) -> 105.0356 | D13: =INDEX(Table1[#All], MATCH($A13, ameco_2024_data!$A:$A, 0), MATCH(D$2, ameco_2024_data!$1:$1, 0)) -> -4.4116011 | E13: =INDEX(Table1[#All], MATCH($A13, ameco_2024_data!$A:$A, 0), MATCH(E$2, ameco_2024_data!$1:$1, 0)) -> -1.8693 | G13: {=IF(INDEX(results_spb!$A$1:$Y$100, MATCH(1, (results_spb!$A$1:$A$100 = table_all!$B13) * (results_spb!$C$1:$C$100 = table_all!G$1), 0), MATCH(table_all!G$2, results_spb!$1:$1, 0)) = 0, "...", INDEX(results_spb!$A$1:$Y$100, MATCH(1, (results_spb!$A$1:$A$100 = table_all!$B13) * (results_spb!$C$1:$C$100 = table_all!G$1), 0), MATCH(table_all!G$2, results_spb!$1:$1, 0)))} -> 0.353 | H13: {=IF(INDEX(results_spb!$A$1:$Y$100, MATCH(1, (results_spb!$A$1:$A$100 = table_all!$B13) * (results_spb!$C$1:$C$100 = table_all!H$1), 0), MATCH(table_all!H$2, results_spb!$1:$1, 0)) = 0, "...", INDEX(results_spb!$A$1:$Y$100, MATCH(1, (results_spb!$A$1:$A$100 = table_all!$B13) * (results_spb!$C$1:$C$100 = table_all!H$1), 0), MATCH(table_all!H$2, results_spb!$1:$1, 0)))} -> 0.39 | J13: {=IF(INDEX(results_spb!$A$1:$Y$100, MATCH(1, (results_spb!$A$1:$A$100 = table_all!$B13) * (results_spb!$C$1:$C$100 = table_all!J$1), 0), MATCH(table_all!J$2, results_spb!$1:$1, 0)) = 0, "...", INDEX(results_spb!$A$1:$Y$100, MATCH(1, (results_spb!$A$1:$A$100 = table_all!$B13) * (results_spb!$C$1:$C$100 = table_all!J$1), 0), MATCH(table_all!J$2, results_spb!$1:$1, 0)))} -> 1.092 | K13: {=IF(INDEX(results_spb!$A$1:$Y$100, MATCH(1, (results_spb!$A$1:$A$100 = table_all!$B13) * (results_spb!$C$1:$C$100 = table_all!K$1), 0), MATCH(table_all!K$2, results_spb!$1:$1, 0)) = 0, "...", INDEX(results_spb!$A$1:$Y$100, MATCH(1, (results_spb!$A$1:$A$100 = table_all!$B13) * (results_spb!$C$1:$C$100 = table_all!K$1), 0), MATCH(table_all!K$2, results_spb!$1:$1, 0)))} -> 1.135 | M13: {=IF(INDEX(results_spb!$A$1:$Y$100, MATCH(1, (results_spb!$A$1:$A$100 = table_all!$B13) * (results_spb!$C$1:$C$100 = table_all!M$1), 0), MATCH(table_all!M$2, results_spb!$1:$1, 0)) = 0, "...", INDEX(results_spb!$A$1:$Y$100, MATCH(1, (results_spb!$A$1:$A$100 = table_all!$B13) * (results_spb!$C$1:$C$100 = table_all!M$1), 0), MATCH(table_all!M$2, results_spb!$1:$1, 0)))} -> 0.855 | N13: {=IF(INDEX(results_spb!$A$1:$Y$100, MATCH(1, (results_spb!$A$1:$A$100 = table_all!$B13) * (results_spb!$C$1:$C$100 = table_all!N$1), 0), MATCH(table_all!N$2, results_spb!$1:$1, 0)) = 0, "...", INDEX(results_spb!$A$1:$Y$100, MATCH(1, (results_spb!$A$1:$A$100 = table_all!$B13) * (results_spb!$C$1:$C$100 = table_all!N$1), 0), MATCH(table_all!N$2, results_spb!$1:$1, 0)))} -> 0.893 | P13: {=IF(INDEX(results_spb!$A$1:$Y$100, MATCH(1, (results_spb!$A$1:$A$100 = table_all!$B13) * (results_spb!$C$1:$C$100 = table_all!P$1), 0), MATCH(table_all!P$2, results_spb!$1:$1, 0)) = 0, "...", INDEX(results_spb!$A$1:$Y$100, MATCH(1, (results_spb!$A$1:$A$100 = table_all!$B13) * (results_spb!$C$1:$C$100 = table_all!P$1), 0), MATCH(table_all!P$2, results_spb!$1:$1, 0)))} -> 0.416 | Q13: {=IF(INDEX(results_spb!$A$1:$Y$100, MATCH(1, (results_spb!$A$1:$A$100 = table_all!$B13) * (results_spb!$C$1:$C$100 = table_all!Q$1), 0), MATCH(table_all!Q$2, results_spb!$1:$1, 0)) = 0, "...", INDEX(results_spb!$A$1:$Y$100, MATCH(1, (results_spb!$A$1:$A$100 = table_all!$B13) * (results_spb!$C$1:$C$100 = table_all!Q$1), 0), MATCH(table_all!Q$2, results_spb!$1:$1, 0)))} -> 0.451 | S13: {=IF(INDEX(results_spb!$A$1:$Y$100, MATCH(1, (results_spb!$A$1:$A$100 = table_all!$B13) * (results_spb!$C$1:$C$100 = table_all!S$1), 0), MATCH(table_all!S$2, results_spb!$1:$1, 0)) = 0, "...", INDEX(results_spb!$A$1:$Y$100, MATCH(1, (results_spb!$A$1:$A$100 = table_all!$B13) * (results_spb!$C$1:$C$100 = table_all!S$1), 0), MATCH(table_all!S$2, results_spb!$1:$1, 0)))} -> 0.432 | T13: {=IF(INDEX(results_spb!$A$1:$Y$100, MATCH(1, (results_spb!$A$1:$A$100 = table_all!$B13) * (results_spb!$C$1:$C$100 = table_all!T$1), 0), MATCH(table_all!T$2, results_spb!$1:$1, 0)) = 0, "...", INDEX(results_spb!$A$1:$Y$100, MATCH(1, (results_spb!$A$1:$A$100 = table_all!$B13) * (results_spb!$C$1:$C$100 = table_all!T$1), 0), MATCH(table_all!T$2, results_spb!$1:$1, 0)))} -> 0.657 | V13: {=IF(INDEX(results_spb!$A$1:$Y$100, MATCH(1, (results_spb!$A$1:$A$100 = table_all!$B13) * (results_spb!$C$1:$C$100 = table_all!V$1), 0), MATCH(table_all!V$2, results_spb!$1:$1, 0)) = 0, "...", INDEX(results_spb!$A$1:$Y$100, MATCH(1, (results_spb!$A$1:$A$100 = table_all!$B13) * (results_spb!$C$1:$C$100 = table_all!V$1), 0), MATCH(table_all!V$2, results_spb!$1:$1, 0)))} -> 0.814 | W13: {=IF(INDEX(results_spb!$A$1:$Y$100, MATCH(1, (results_spb!$A$1:$A$100 = table_all!$B13) * (results_spb!$C$1:$C$100 = table_all!W$1), 0), MATCH(table_all!W$2, results_spb!$1:$1, 0)) = 0, "...", INDEX(results_spb!$A$1:$Y$100, MATCH(1, (results_spb!$A$1:$A$100 = table_all!$B13) * (results_spb!$C$1:$C$100 = table_all!W$1), 0), MATCH(table_all!W$2, results_spb!$1:$1, 0)))} -> 0.923 | Y13: {=IF(INDEX(results_spb!$A$1:$Y$100, MATCH(1, (results_spb!$A$1:$A$100 = table_all!$B13) * (results_spb!$C$1:$C$100 = table_all!Y$1), 0), MATCH(table_all!Y$2, results_spb!$1:$1, 0)) = 0, "...", INDEX(results_spb!$A$1:$Y$100, MATCH(1, (results_spb!$A$1:$A$100 = table_all!$B13) * (results_spb!$C$1:$C$100 = table_all!Y$1), 0), MATCH(table_all!Y$2, results_spb!$1:$1, 0)))} -> ... | Z13: {=IF(INDEX(results_spb!$A$1:$Y$100, MATCH(1, (results_spb!$A$1:$A$100 = table_all!$B13) * (results_spb!$C$1:$C$100 = table_all!Z$1), 0), MATCH(table_all!Z$2, results_spb!$1:$1, 0)) = 0, "...", INDEX(results_spb!$A$1:$Y$100, MATCH(1, (results_spb!$A$1:$A$100 = table_all!$B13) * (results_spb!$C$1:$C$100 = table_all!Z$1), 0), MATCH(table_all!Z$2, results_spb!$1:$1, 0)))} -> ... | AB13: {=IF(INDEX(results_spb!$A$1:$Y$100, MATCH(1, (results_spb!$A$1:$A$100 = table_all!$B13) * (results_spb!$C$1:$C$100 = table_all!AB$1), 0), MATCH(table_all!AB$2, results_spb!$1:$1, 0)) = 0, "...", INDEX(results_spb!$A$1:$Y$100, MATCH(1, (results_spb!$A$1:$A$100 = table_all!$B13) * (results_spb!$C$1:$C$100 = table_all!AB$1), 0), MATCH(table_all!AB$2, results_spb!$1:$1, 0)))} -> ... | AC13: {=IF(INDEX(results_spb!$A$1:$Y$100, MATCH(1, (results_spb!$A$1:$A$100 = table_all!$B13) * (results_spb!$C$1:$C$100 = table_all!AC$1), 0), MATCH(table_all!AC$2, results_spb!$1:$1, 0)) = 0, "...", INDEX(results_spb!$A$1:$Y$100, MATCH(1, (results_spb!$A$1:$A$100 = table_all!$B13) * (results_spb!$C$1:$C$100 = table_all!AC$1), 0), MATCH(table_all!AC$2, results_spb!$1:$1, 0)))} -> ... | AE13: =MAX(G13,J13,M13,P13,S13,V13,Y13,AB13) -> 1.092 | AF13: =MAX(H13,K13,N13,Q13,T13,W13,Z13,AC13) -> 1.135 | AH13: =(AE13-$E13)/4 -> 0.740325 | AI13: =(AF13-$E13)/7 -> 0.42918571 | AL13: Binding deficit resilience safeguard, no impact on final SPB
A14: PRT | B14: =INDEX(Table1[#All], MATCH($A14, ameco_2024_data!$A:$A, 0), MATCH(B$2, ameco_2024_data!$1:$1, 0)) -> Portugal | C14: =INDEX(Table1[#All], MATCH($A14, ameco_2024_data!$A:$A, 0), MATCH(C$2, ameco_2024_data!$1:$1, 0)) -> 95.6314 | D14: =INDEX(Table1[#All], MATCH($A14, ameco_2024_data!$A:$A, 0), MATCH(D$2, ameco_2024_data!$1:$1, 0)) -> 0.4367736 | E14: =INDEX(Table1[#All], MATCH($A14, ameco_2024_data!$A:$A, 0), MATCH(E$2, ameco_2024_data!$1:$1, 0)) -> 2.2021 | G14: {=IF(INDEX(results_spb!$A$1:$Y$100, MATCH(1, (results_spb!$A$1:$A$100 = table_all!$B14) * (results_spb!$C$1:$C$100 = table_all!G$1), 0), MATCH(table_all!G$2, results_spb!$1:$1, 0)) = 0, "...", INDEX(results_spb!$A$1:$Y$100, MATCH(1, (results_spb!$A$1:$A$100 = table_all!$B14) * (results_spb!$C$1:$C$100 = table_all!G$1), 0), MATCH(table_all!G$2, results_spb!$1:$1, 0)))} -> 2.013 | H14: {=IF(INDEX(results_spb!$A$1:$Y$100, MATCH(1, (results_spb!$A$1:$A$100 = table_all!$B14) * (results_spb!$C$1:$C$100 = table_all!H$1), 0), MATCH(table_all!H$2, results_spb!$1:$1, 0)) = 0, "...", INDEX(results_spb!$A$1:$Y$100, MATCH(1, (results_spb!$A$1:$A$100 = table_all!$B14) * (results_spb!$C$1:$C$100 = table_all!H$1), 0), MATCH(table_all!H$2, results_spb!$1:$1, 0)))} -> 1.77 | J14: {=IF(INDEX(results_spb!$A$1:$Y$100, MATCH(1, (results_spb!$A$1:$A$100 = table_all!$B14) * (results_spb!$C$1:$C$100 = table_all!J$1), 0), MATCH(table_all!J$2, results_spb!$1:$1, 0)) = 0, "...", INDEX(results_spb!$A$1:$Y$100, MATCH(1, (results_spb!$A$1:$A$100 = table_all!$B14) * (results_spb!$C$1:$C$100 = table_all!J$1), 0), MATCH(table_all!J$2, results_spb!$1:$1, 0)))} -> 2.566 | K14: {=IF(INDEX(results_spb!$A$1:$Y$100, MATCH(1, (results_spb!$A$1:$A$100 = table_all!$B14) * (results_spb!$C$1:$C$100 = table_all!K$1), 0), MATCH(table_all!K$2, results_spb!$1:$1, 0)) = 0, "...", INDEX(results_spb!$A$1:$Y$100, MATCH(1, (results_spb!$A$1:$A$100 = table_all!$B14) * (results_spb!$C$1:$C$100 = table_all!K$1), 0), MATCH(table_all!K$2, results_spb!$1:$1, 0)))} -> 2.289 | M14: {=IF(INDEX(results_spb!$A$1:$Y$100, MATCH(1, (results_spb!$A$1:$A$100 = table_all!$B14) * (results_spb!$C$1:$C$100 = table_all!M$1), 0), MATCH(table_all!M$2, results_spb!$1:$1, 0)) = 0, "...", INDEX(results_spb!$A$1:$Y$100, MATCH(1, (results_spb!$A$1:$A$100 = table_all!$B14) * (results_spb!$C$1:$C$100 = table_all!M$1), 0), MATCH(table_all!M$2, results_spb!$1:$1, 0)))} -> 2.507 | N14: {=IF(INDEX(results_spb!$A$1:$Y$100, MATCH(1, (results_spb!$A$1:$A$100 = table_all!$B14) * (results_spb!$C$1:$C$100 = table_all!N$1), 0), MATCH(table_all!N$2, results_spb!$1:$1, 0)) = 0, "...", INDEX(results_spb!$A$1:$Y$100, MATCH(1, (results_spb!$A$1:$A$100 = table_all!$B14) * (results_spb!$C$1:$C$100 = table_all!N$1), 0), MATCH(table_all!N$2, results_spb!$1:$1, 0)))} -> 2.263 | P14: {=IF(INDEX(results_spb!$A$1:$Y$100, MATCH(1, (results_spb!$A$1:$A$100 = table_all!$B14) * (results_spb!$C$1:$C$100 = table_all!P$1), 0), MATCH(table_all!P$2, results_spb!$1:$1, 0)) = 0, "...", INDEX(results_spb!$A$1:$Y$100, MATCH(1, (results_spb!$A$1:$A$100 = table_all!$B14) * (results_spb!$C$1:$C$100 = table_all!P$1), 0), MATCH(table_all!P$2, results_spb!$1:$1, 0)))} -> 2.028 | Q14: {=IF(INDEX(results_spb!$A$1:$Y$100, MATCH(1, (results_spb!$A$1:$A$100 = table_all!$B14) * (results_spb!$C$1:$C$100 = table_all!Q$1), 0), MATCH(table_all!Q$2, results_spb!$1:$1, 0)) = 0, "...", INDEX(results_spb!$A$1:$Y$100, MATCH(1, (results_spb!$A$1:$A$100 = table_all!$B14) * (results_spb!$C$1:$C$100 = table_all!Q$1), 0), MATCH(table_all!Q$2, results_spb!$1:$1, 0)))} -> 1.79 | S14: {=IF(INDEX(results_spb!$A$1:$Y$100, MATCH(1, (results_spb!$A$1:$A$100 = table_all!$B14) * (results_spb!$C$1:$C$100 = table_all!S$1), 0), MATCH(table_all!S$2, results_spb!$1:$1, 0)) = 0, "...", INDEX(results_spb!$A$1:$Y$100, MATCH(1, (results_spb!$A$1:$A$100 = table_all!$B14) * (results_spb!$C$1:$C$100 = table_all!S$1), 0), MATCH(table_all!S$2, results_spb!$1:$1, 0)))} -> 1.98 | T14: {=IF(INDEX(results_spb!$A$1:$Y$100, MATCH(1, (results_spb!$A$1:$A$100 = table_all!$B14) * (results_spb!$C$1:$C$100 = table_all!T$1), 0), MATCH(table_all!T$2, results_spb!$1:$1, 0)) = 0, "...", INDEX(results_spb!$A$1:$Y$100, MATCH(1, (results_spb!$A$1:$A$100 = table_all!$B14) * (results_spb!$C$1:$C$100 = table_all!T$1), 0), MATCH(table_all!T$2, results_spb!$1:$1, 0)))} -> 2.188 | V14: {=IF(INDEX(results_spb!$A$1:$Y$100, MATCH(1, (results_spb!$A$1:$A$100 = table_all!$B14) * (results_spb!$C$1:$C$100 = table_all!V$1), 0), MATCH(table_all!V$2, results_spb!$1:$1, 0)) = 0, "...", INDEX(results_spb!$A$1:$Y$100, MATCH(1, (results_spb!$A$1:$A$100 = table_all!$B14) * (results_spb!$C$1:$C$100 = table_all!V$1), 0), MATCH(table_all!V$2, results_spb!$1:$1, 0)))} -> 1.682 | W14: {=IF(INDEX(results_spb!$A$1:$Y$100, MATCH(1, (results_spb!$A$1:$A$100 = table_all!$B14) * (results_spb!$C$1:$C$100 = table_all!W$1), 0), MATCH(table_all!W$2, results_spb!$1:$1, 0)) = 0, "...", INDEX(results_spb!$A$1:$Y$100, MATCH(1, (results_spb!$A$1:$A$100 = table_all!$B14) * (results_spb!$C$1:$C$100 = table_all!W$1), 0), MATCH(table_all!W$2, results_spb!$1:$1, 0)))} -> 1.461 | Y14: {=IF(INDEX(results_spb!$A$1:$Y$100, MATCH(1, (results_spb!$A$1:$A$100 = table_all!$B14) * (results_spb!$C$1:$C$100 = table_all!Y$1), 0), MATCH(table_all!Y$2, results_spb!$1:$1, 0)) = 0, "...", INDEX(results_spb!$A$1:$Y$100, MATCH(1, (results_spb!$A$1:$A$100 = table_all!$B14) * (results_spb!$C$1:$C$100 = table_all!Y$1), 0), MATCH(table_all!Y$2, results_spb!$1:$1, 0)))} -> ... | Z14: {=IF(INDEX(results_spb!$A$1:$Y$100, MATCH(1, (results_spb!$A$1:$A$100 = table_all!$B14) * (results_spb!$C$1:$C$100 = table_all!Z$1), 0), MATCH(table_all!Z$2, results_spb!$1:$1, 0)) = 0, "...", INDEX(results_spb!$A$1:$Y$100, MATCH(1, (results_spb!$A$1:$A$100 = table_all!$B14) * (results_spb!$C$1:$C$100 = table_all!Z$1), 0), MATCH(table_all!Z$2, results_spb!$1:$1, 0)))} -> ... | AB14: {=IF(INDEX(results_spb!$A$1:$Y$100, MATCH(1, (results_spb!$A$1:$A$100 = table_all!$B14) * (results_spb!$C$1:$C$100 = table_all!AB$1), 0), MATCH(table_all!AB$2, results_spb!$1:$1, 0)) = 0, "...", INDEX(results_spb!$A$1:$Y$100, MATCH(1, (results_spb!$A$1:$A$100 = table_all!$B14) * (results_spb!$C$1:$C$100 = table_all!AB$1), 0), MATCH(table_all!AB$2, results_spb!$1:$1, 0)))} -> ... | AC14: {=IF(INDEX(results_spb!$A$1:$Y$100, MATCH(1, (results_spb!$A$1:$A$100 = table_all!$B14) * (results_spb!$C$1:$C$100 = table_all!AC$1), 0), MATCH(table_all!AC$2, results_spb!$1:$1, 0)) = 0, "...", INDEX(results_spb!$A$1:$Y$100, MATCH(1, (results_spb!$A$1:$A$100 = table_all!$B14) * (results_spb!$C$1:$C$100 = table_all!AC$1), 0), MATCH(table_all!AC$2, results_spb!$1:$1, 0)))} -> ... | AE14: =MAX(G14,J14,M14,P14,S14,V14,Y14,AB14) -> 2.566 | AF14: =MAX(H14,K14,N14,Q14,T14,W14,Z14,AC14) -> 2.289 | AH14: =(AE14-$E14)/4 -> 0.090975 | AI14: =(AF14-$E14)/7 -> 0.012414286 | AL14: Binding deficit resilience safeguard, impact on final SPB
A15: FIN | B15: =INDEX(Table1[#All], MATCH($A15, ameco_2024_data!$A:$A, 0), MATCH(B$2, ameco_2024_data!$1:$1, 0)) -> Finland | C15: =INDEX(Table1[#All], MATCH($A15, ameco_2024_data!$A:$A, 0), MATCH(C$2, ameco_2024_data!$1:$1, 0)) -> 80.4874 | D15: =INDEX(Table1[#All], MATCH($A15, ameco_2024_data!$A:$A, 0), MATCH(D$2, ameco_2024_data!$1:$1, 0)) -> -3.4097269 | E15: =INDEX(Table1[#All], MATCH($A15, ameco_2024_data!$A:$A, 0), MATCH(E$2, ameco_2024_data!$1:$1, 0)) -> -0.5301 | G15: {=IF(INDEX(results_spb!$A$1:$Y$100, MATCH(1, (results_spb!$A$1:$A$100 = table_all!$B15) * (results_spb!$C$1:$C$100 = table_all!G$1), 0), MATCH(table_all!G$2, results_spb!$1:$1, 0)) = 0, "...", INDEX(results_spb!$A$1:$Y$100, MATCH(1, (results_spb!$A$1:$A$100 = table_all!$B15) * (results_spb!$C$1:$C$100 = table_all!G$1), 0), MATCH(table_all!G$2, results_spb!$1:$1, 0)))} -> 0.664 | H15: {=IF(INDEX(results_spb!$A$1:$Y$100, MATCH(1, (results_spb!$A$1:$A$100 = table_all!$B15) * (results_spb!$C$1:$C$100 = table_all!H$1), 0), MATCH(table_all!H$2, results_spb!$1:$1, 0)) = 0, "...", INDEX(results_spb!$A$1:$Y$100, MATCH(1, (results_spb!$A$1:$A$100 = table_all!$B15) * (results_spb!$C$1:$C$100 = table_all!H$1), 0), MATCH(table_all!H$2, results_spb!$1:$1, 0)))} -> 0.349 | J15: {=IF(INDEX(results_spb!$A$1:$Y$100, MATCH(1, (results_spb!$A$1:$A$100 = table_all!$B15) * (results_spb!$C$1:$C$100 = table_all!J$1), 0), MATCH(table_all!J$2, results_spb!$1:$1, 0)) = 0, "...", INDEX(results_spb!$A$1:$Y$100, MATCH(1, (results_spb!$A$1:$A$100 = table_all!$B15) * (results_spb!$C$1:$C$100 = table_all!J$1), 0), MATCH(table_all!J$2, results_spb!$1:$1, 0)))} -> 1.139 | K15: {=IF(INDEX(results_spb!$A$1:$Y$100, MATCH(1, (results_spb!$A$1:$A$100 = table_all!$B15) * (results_spb!$C$1:$C$100 = table_all!K$1), 0), MATCH(table_all!K$2, results_spb!$1:$1, 0)) = 0, "...", INDEX(results_spb!$A$1:$Y$100, MATCH(1, (results_spb!$A$1:$A$100 = table_all!$B15) * (results_spb!$C$1:$C$100 = table_all!K$1), 0), MATCH(table_all!K$2, results_spb!$1:$1, 0)))} -> 0.816 | M15: {=IF(INDEX(results_spb!$A$1:$Y$100, MATCH(1, (results_spb!$A$1:$A$100 = table_all!$B15) * (results_spb!$C$1:$C$100 = table_all!M$1), 0), MATCH(table_all!M$2, results_spb!$1:$1, 0)) = 0, "...", INDEX(results_spb!$A$1:$Y$100, MATCH(1, (results_spb!$A$1:$A$100 = table_all!$B15) * (results_spb!$C$1:$C$100 = table_all!M$1), 0), MATCH(table_all!M$2, results_spb!$1:$1, 0)))} -> 1.192 | N15: {=IF(INDEX(results_spb!$A$1:$Y$100, MATCH(1, (results_spb!$A$1:$A$100 = table_all!$B15) * (results_spb!$C$1:$C$100 = table_all!N$1), 0), MATCH(table_all!N$2, results_spb!$1:$1, 0)) = 0, "...", INDEX(results_spb!$A$1:$Y$100, MATCH(1, (results_spb!$A$1:$A$100 = table_all!$B15) * (results_spb!$C$1:$C$100 = table_all!N$1), 0), MATCH(table_all!N$2, results_spb!$1:$1, 0)))} -> 0.643 | P15: {=IF(INDEX(results_spb!$A$1:$Y$100, MATCH(1, (results_spb!$A$1:$A$100 = table_all!$B15) * (results_spb!$C$1:$C$100 = table_all!P$1), 0), MATCH(table_all!P$2, results_spb!$1:$1, 0)) = 0, "...", INDEX(results_spb!$A$1:$Y$100, MATCH(1, (results_spb!$A$1:$A$100 = table_all!$B15) * (results_spb!$C$1:$C$100 = table_all!P$1), 0), MATCH(table_all!P$2, results_spb!$1:$1, 0)))} -> 0.797 | Q15: {=IF(INDEX(results_spb!$A$1:$Y$100, MATCH(1, (results_spb!$A$1:$A$100 = table_all!$B15) * (results_spb!$C$1:$C$100 = table_all!Q$1), 0), MATCH(table_all!Q$2, results_spb!$1:$1, 0)) = 0, "...", INDEX(results_spb!$A$1:$Y$100, MATCH(1, (results_spb!$A$1:$A$100 = table_all!$B15) * (results_spb!$C$1:$C$100 = table_all!Q$1), 0), MATCH(table_all!Q$2, results_spb!$1:$1, 0)))} -> 0.491 | S15: {=IF(INDEX(results_spb!$A$1:$Y$100, MATCH(1, (results_spb!$A$1:$A$100 = table_all!$B15) * (results_spb!$C$1:$C$100 = table_all!S$1), 0), MATCH(table_all!S$2, results_spb!$1:$1, 0)) = 0, "...", INDEX(results_spb!$A$1:$Y$100, MATCH(1, (results_spb!$A$1:$A$100 = table_all!$B15) * (results_spb!$C$1:$C$100 = table_all!S$1), 0), MATCH(table_all!S$2, results_spb!$1:$1, 0)))} -> 1.381 | T15: {=IF(INDEX(results_spb!$A$1:$Y$100, MATCH(1, (results_spb!$A$1:$A$100 = table_all!$B15) * (results_spb!$C$1:$C$100 = table_all!T$1), 0), MATCH(table_all!T$2, results_spb!$1:$1, 0)) = 0, "...", INDEX(results_spb!$A$1:$Y$100, MATCH(1, (results_spb!$A$1:$A$100 = table_all!$B15) * (results_spb!$C$1:$C$100 = table_all!T$1), 0), MATCH(table_all!T$2, results_spb!$1:$1, 0)))} -> 0.98 | V15: {=IF(INDEX(results_spb!$A$1:$Y$100, MATCH(1, (results_spb!$A$1:$A$100 = table_all!$B15) * (results_spb!$C$1:$C$100 = table_all!V$1), 0), MATCH(table_all!V$2, results_spb!$1:$1, 0)) = 0, "...", INDEX(results_spb!$A$1:$Y$100, MATCH(1, (results_spb!$A$1:$A$100 = table_all!$B15) * (results_spb!$C$1:$C$100 = table_all!V$1), 0), MATCH(table_all!V$2, results_spb!$1:$1, 0)))} -> -0.384 | W15: {=IF(INDEX(results_spb!$A$1:$Y$100, MATCH(1, (results_spb!$A$1:$A$100 = table_all!$B15) * (results_spb!$C$1:$C$100 = table_all!W$1), 0), MATCH(table_all!W$2, results_spb!$1:$1, 0)) = 0, "...", INDEX(results_spb!$A$1:$Y$100, MATCH(1, (results_spb!$A$1:$A$100 = table_all!$B15) * (results_spb!$C$1:$C$100 = table_all!W$1), 0), MATCH(table_all!W$2, results_spb!$1:$1, 0)))} -> -0.615 | Y15: {=IF(INDEX(results_spb!$A$1:$Y$100, MATCH(1, (results_spb!$A$1:$A$100 = table_all!$B15) * (results_spb!$C$1:$C$100 = table_all!Y$1), 0), MATCH(table_all!Y$2, results_spb!$1:$1, 0)) = 0, "...", INDEX(results_spb!$A$1:$Y$100, MATCH(1, (results_spb!$A$1:$A$100 = table_all!$B15) * (results_spb!$C$1:$C$100 = table_all!Y$1), 0), MATCH(table_all!Y$2, results_spb!$1:$1, 0)))} -> 4.31 | Z15: {=IF(INDEX(results_spb!$A$1:$Y$100, MATCH(1, (results_spb!$A$1:$A$100 = table_all!$B15) * (results_spb!$C$1:$C$100 = table_all!Z$1), 0), MATCH(table_all!Z$2, results_spb!$1:$1, 0)) = 0, "...", INDEX(results_spb!$A$1:$Y$100, MATCH(1, (results_spb!$A$1:$A$100 = table_all!$B15) * (results_spb!$C$1:$C$100 = table_all!Z$1), 0), MATCH(table_all!Z$2, results_spb!$1:$1, 0)))} -> 3.321 | AB15: {=IF(INDEX(results_spb!$A$1:$Y$100, MATCH(1, (results_spb!$A$1:$A$100 = table_all!$B15) * (results_spb!$C$1:$C$100 = table_all!AB$1), 0), MATCH(table_all!AB$2, results_spb!$1:$1, 0)) = 0, "...", INDEX(results_spb!$A$1:$Y$100, MATCH(1, (results_spb!$A$1:$A$100 = table_all!$B15) * (results_spb!$C$1:$C$100 = table_all!AB$1), 0), MATCH(table_all!AB$2, results_spb!$1:$1, 0)))} -> ... | AC15: {=IF(INDEX(results_spb!$A$1:$Y$100, MATCH(1, (results_spb!$A$1:$A$100 = table_all!$B15) * (results_spb!$C$1:$C$100 = table_all!AC$1), 0), MATCH(table_all!AC$2, results_spb!$1:$1, 0)) = 0, "...", INDEX(results_spb!$A$1:$Y$100, MATCH(1, (results_spb!$A$1:$A$100 = table_all!$B15) * (results_spb!$C$1:$C$100 = table_all!AC$1), 0), MATCH(table_all!AC$2, results_spb!$1:$1, 0)))} -> ... | AE15: =MAX(G15,J15,M15,P15,S15,V15,Y15,AB15) -> 4.31 | AF15: =MAX(H15,K15,N15,Q15,T15,W15,Z15,AC15) -> 3.321 | AH15: =(AE15-$E15)/4 -> 1.210025 | AI15: =(AF15-$E15)/7 -> 0.55015714
A16: AUT | B16: =INDEX(Table1[#All], MATCH($A16, ameco_2024_data!$A:$A, 0), MATCH(B$2, ameco_2024_data!$1:$1, 0)) -> Austria | C16: =INDEX(Table1[#All], MATCH($A16, ameco_2024_data!$A:$A, 0), MATCH(C$2, ameco_2024_data!$1:$1, 0)) -> 77.6939 | D16: =INDEX(Table1[#All], MATCH($A16, ameco_2024_data!$A:$A, 0), MATCH(D$2, ameco_2024_data!$1:$1, 0)) -> -3.0652172 | E16: =INDEX(Table1[#All], MATCH($A16, ameco_2024_data!$A:$A, 0), MATCH(E$2, ameco_2024_data!$1:$1, 0)) -> -1.1266 | G16: {=IF(INDEX(results_spb!$A$1:$Y$100, MATCH(1, (results_spb!$A$1:$A$100 = table_all!$B16) * (results_spb!$C$1:$C$100 = table_all!G$1), 0), MATCH(table_all!G$2, results_spb!$1:$1, 0)) = 0, "...", INDEX(results_spb!$A$1:$Y$100, MATCH(1, (results_spb!$A$1:$A$100 = table_all!$B16) * (results_spb!$C$1:$C$100 = table_all!G$1), 0), MATCH(table_all!G$2, results_spb!$1:$1, 0)))} -> 0.185 | H16: {=IF(INDEX(results_spb!$A$1:$Y$100, MATCH(1, (results_spb!$A$1:$A$100 = table_all!$B16) * (results_spb!$C$1:$C$100 = table_all!H$1), 0), MATCH(table_all!H$2, results_spb!$1:$1, 0)) = 0, "...", INDEX(results_spb!$A$1:$Y$100, MATCH(1, (results_spb!$A$1:$A$100 = table_all!$B16) * (results_spb!$C$1:$C$100 = table_all!H$1), 0), MATCH(table_all!H$2, results_spb!$1:$1, 0)))} -> -0.06 | J16: {=IF(INDEX(results_spb!$A$1:$Y$100, MATCH(1, (results_spb!$A$1:$A$100 = table_all!$B16) * (results_spb!$C$1:$C$100 = table_all!J$1), 0), MATCH(table_all!J$2, results_spb!$1:$1, 0)) = 0, "...", INDEX(results_spb!$A$1:$Y$100, MATCH(1, (results_spb!$A$1:$A$100 = table_all!$B16) * (results_spb!$C$1:$C$100 = table_all!J$1), 0), MATCH(table_all!J$2, results_spb!$1:$1, 0)))} -> 0.781 | K16: {=IF(INDEX(results_spb!$A$1:$Y$100, MATCH(1, (results_spb!$A$1:$A$100 = table_all!$B16) * (results_spb!$C$1:$C$100 = table_all!K$1), 0), MATCH(table_all!K$2, results_spb!$1:$1, 0)) = 0, "...", INDEX(results_spb!$A$1:$Y$100, MATCH(1, (results_spb!$A$1:$A$100 = table_all!$B16) * (results_spb!$C$1:$C$100 = table_all!K$1), 0), MATCH(table_all!K$2, results_spb!$1:$1, 0)))} -> 0.55 | M16: {=IF(INDEX(results_spb!$A$1:$Y$100, MATCH(1, (results_spb!$A$1:$A$100 = table_all!$B16) * (results_spb!$C$1:$C$100 = table_all!M$1), 0), MATCH(table_all!M$2, results_spb!$1:$1, 0)) = 0, "...", INDEX(results_spb!$A$1:$Y$100, MATCH(1, (results_spb!$A$1:$A$100 = table_all!$B16) * (results_spb!$C$1:$C$100 = table_all!M$1), 0), MATCH(table_all!M$2, results_spb!$1:$1, 0)))} -> 0.691 | N16: {=IF(INDEX(results_spb!$A$1:$Y$100, MATCH(1, (results_spb!$A$1:$A$100 = table_all!$B16) * (results_spb!$C$1:$C$100 = table_all!N$1), 0), MATCH(table_all!N$2, results_spb!$1:$1, 0)) = 0, "...", INDEX(results_spb!$A$1:$Y$100, MATCH(1, (results_spb!$A$1:$A$100 = table_all!$B16) * (results_spb!$C$1:$C$100 = table_all!N$1), 0), MATCH(table_all!N$2, results_spb!$1:$1, 0)))} -> 0.449 | P16: {=IF(INDEX(results_spb!$A$1:$Y$100, MATCH(1, (results_spb!$A$1:$A$100 = table_all!$B16) * (results_spb!$C$1:$C$100 = table_all!P$1), 0), MATCH(table_all!P$2, results_spb!$1:$1, 0)) = 0, "...", INDEX(results_spb!$A$1:$Y$100, MATCH(1, (results_spb!$A$1:$A$100 = table_all!$B16) * (results_spb!$C$1:$C$100 = table_all!P$1), 0), MATCH(table_all!P$2, results_spb!$1:$1, 0)))} -> 0.208 | Q16: {=IF(INDEX(results_spb!$A$1:$Y$100, MATCH(1, (results_spb!$A$1:$A$100 = table_all!$B16) * (results_spb!$C$1:$C$100 = table_all!Q$1), 0), MATCH(table_all!Q$2, results_spb!$1:$1, 0)) = 0, "...", INDEX(results_spb!$A$1:$Y$100, MATCH(1, (results_spb!$A$1:$A$100 = table_all!$B16) * (results_spb!$C$1:$C$100 = table_all!Q$1), 0), MATCH(table_all!Q$2, results_spb!$1:$1, 0)))} -> -0.037 | S16: {=IF(INDEX(results_spb!$A$1:$Y$100, MATCH(1, (results_spb!$A$1:$A$100 = table_all!$B16) * (results_spb!$C$1:$C$100 = table_all!S$1), 0), MATCH(table_all!S$2, results_spb!$1:$1, 0)) = 0, "...", INDEX(results_spb!$A$1:$Y$100, MATCH(1, (results_spb!$A$1:$A$100 = table_all!$B16) * (results_spb!$C$1:$C$100 = table_all!S$1), 0), MATCH(table_all!S$2, results_spb!$1:$1, 0)))} -> 0.629 | T16: {=IF(INDEX(results_spb!$A$1:$Y$100, MATCH(1, (results_spb!$A$1:$A$100 = table_all!$B16) * (results_spb!$C$1:$C$100 = table_all!T$1), 0), MATCH(table_all!T$2, results_spb!$1:$1, 0)) = 0, "...", INDEX(results_spb!$A$1:$Y$100, MATCH(1, (results_spb!$A$1:$A$100 = table_all!$B16) * (results_spb!$C$1:$C$100 = table_all!T$1), 0), MATCH(table_all!T$2, results_spb!$1:$1, 0)))} -> 0.713 | V16: {=IF(INDEX(results_spb!$A$1:$Y$100, MATCH(1, (results_spb!$A$1:$A$100 = table_all!$B16) * (results_spb!$C$1:$C$100 = table_all!V$1), 0), MATCH(table_all!V$2, results_spb!$1:$1, 0)) = 0, "...", INDEX(results_spb!$A$1:$Y$100, MATCH(1, (results_spb!$A$1:$A$100 = table_all!$B16) * (results_spb!$C$1:$C$100 = table_all!V$1), 0), MATCH(table_all!V$2, results_spb!$1:$1, 0)))} -> -0.082 | W16: {=IF(INDEX(results_spb!$A$1:$Y$100, MATCH(1, (results_spb!$A$1:$A$100 = table_all!$B16) * (results_spb!$C$1:$C$100 = table_all!W$1), 0), MATCH(table_all!W$2, results_spb!$1:$1, 0)) = 0, "...", INDEX(results_spb!$A$1:$Y$100, MATCH(1, (results_spb!$A$1:$A$100 = table_all!$B16) * (results_spb!$C$1:$C$100 = table_all!W$1), 0), MATCH(table_all!W$2, results_spb!$1:$1, 0)))} -> -0.239 | Y16: {=IF(INDEX(results_spb!$A$1:$Y$100, MATCH(1, (results_spb!$A$1:$A$100 = table_all!$B16) * (results_spb!$C$1:$C$100 = table_all!Y$1), 0), MATCH(table_all!Y$2, results_spb!$1:$1, 0)) = 0, "...", INDEX(results_spb!$A$1:$Y$100, MATCH(1, (results_spb!$A$1:$A$100 = table_all!$B16) * (results_spb!$C$1:$C$100 = table_all!Y$1), 0), MATCH(table_all!Y$2, results_spb!$1:$1, 0)))} -> ... | Z16: {=IF(INDEX(results_spb!$A$1:$Y$100, MATCH(1, (results_spb!$A$1:$A$100 = table_all!$B16) * (results_spb!$C$1:$C$100 = table_all!Z$1), 0), MATCH(table_all!Z$2, results_spb!$1:$1, 0)) = 0, "...", INDEX(results_spb!$A$1:$Y$100, MATCH(1, (results_spb!$A$1:$A$100 = table_all!$B16) * (results_spb!$C$1:$C$100 = table_all!Z$1), 0), MATCH(table_all!Z$2, results_spb!$1:$1, 0)))} -> ... | AB16: {=IF(INDEX(results_spb!$A$1:$Y$100, MATCH(1, (results_spb!$A$1:$A$100 = table_all!$B16) * (results_spb!$C$1:$C$100 = table_all!AB$1), 0), MATCH(table_all!AB$2, results_spb!$1:$1, 0)) = 0, "...", INDEX(results_spb!$A$1:$Y$100, MATCH(1, (results_spb!$A$1:$A$100 = table_all!$B16) * (results_spb!$C$1:$C$100 = table_all!AB$1), 0), MATCH(table_all!AB$2, results_spb!$1:$1, 0)))} -> ... | AC16: {=IF(INDEX(results_spb!$A$1:$Y$100, MATCH(1, (results_spb!$A$1:$A$100 = table_all!$B16) * (results_spb!$C$1:$C$100 = table_all!AC$1), 0), MATCH(table_all!AC$2, results_spb!$1:$1, 0)) = 0, "...", INDEX(results_spb!$A$1:$Y$100, MATCH(1, (results_spb!$A$1:$A$100 = table_all!$B16) * (results_spb!$C$1:$C$100 = table_all!AC$1), 0), MATCH(table_all!AC$2, results_spb!$1:$1, 0)))} -> ... | AE16: =MAX(G16,J16,M16,P16,S16,V16,Y16,AB16) -> 0.781 | AF16: =MAX(H16,K16,N16,Q16,T16,W16,Z16,AC16) -> 0.713 | AH16: =(AE16-$E16)/4 -> 0.4769 | AI16: =(AF16-$E16)/7 -> 0.2628
