Workbook
Name Macrobond_Object1: Sheet1!$B$4:$CY$72
Name Macrobond_Object1: Sheet3!$A$3:$B$53

Sheet Sheet1
C1: =_xlfn.TEXTBEFORE(C5,",") -> Austria | D1: =_xlfn.TEXTBEFORE(D5,",") -> Austria | E1: =_xlfn.TEXTBEFORE(E5,",") -> France | F1: =_xlfn.TEXTBEFORE(F5,",") -> France | G1: =_xlfn.TEXTBEFORE(G5,",") -> Italy | H1: =_xlfn.TEXTBEFORE(H5,",") -> Italy | I1: =_xlfn.TEXTBEFORE(I5,",") -> Netherlands | J1: =_xlfn.TEXTBEFORE(J5,",") -> Netherlands | ... CY1: =_xlfn.TEXTBEFORE(CY5,",") -> Netherlands
C2: =_xlfn.TEXTAFTER(C5,", ") -> Capital Formation & Saving, Gross Fixed Capital Formation, Private Sector, Current Prices, EUR | D2: =_xlfn.TEXTAFTER(D5,", ") -> Capital Formation & Saving, Gross Fixed Capital Formation, General Government, Current Prices, EUR | E2: =_xlfn.TEXTAFTER(E5,", ") -> Capital Formation & Saving, Gross Fixed Capital Formation, Private Sector, Current Prices, EUR | F2: =_xlfn.TEXTAFTER(F5,", ") -> Capital Formation & Saving, Gross Fixed Capital Formation, General Government, Current Prices, EUR | G2: =_xlfn.TEXTAFTER(G5,", ") -> Capital Formation & Saving, Gross Fixed Capital Formation, Private Sector, Current Prices, EUR | H2: =_xlfn.TEXTAFTER(H5,", ") -> Capital Formation & Saving, Gross Fixed Capital Formation, General Government, Current Prices, EUR | I2: =_xlfn.TEXTAFTER(I5,", ") -> Capital Formation & Saving, Gross Fixed Capital Formation, Private Sector, Current Prices, EUR | J2: =_xlfn.TEXTAFTER(J5,", ") -> Capital Formation & Saving, Gross Fixed Capital Formation, General Government, Current Prices, EUR | ... CY2: =_xlfn.TEXTAFTER(CY5,", ") -> Monetary Variables, Interest Rates, Nominal, Short-Term, Current Prices
C3: =_xlfn.XLOOKUP(C2,Sheet2!$D:$D,Sheet2!$E:$E) -> I_M_NOM | D3: =_xlfn.XLOOKUP(D2,Sheet2!$D:$D,Sheet2!$E:$E) -> I_G | E3: =_xlfn.XLOOKUP(E2,Sheet2!$D:$D,Sheet2!$E:$E) -> I_M_NOM | F3: =_xlfn.XLOOKUP(F2,Sheet2!$D:$D,Sheet2!$E:$E) -> I_G | G3: =_xlfn.XLOOKUP(G2,Sheet2!$D:$D,Sheet2!$E:$E) -> I_M_NOM | H3: =_xlfn.XLOOKUP(H2,Sheet2!$D:$D,Sheet2!$E:$E) -> I_G | I3: =_xlfn.XLOOKUP(I2,Sheet2!$D:$D,Sheet2!$E:$E) -> I_M_NOM | J3: =_xlfn.XLOOKUP(J2,Sheet2!$D:$D,Sheet2!$E:$E) -> I_G | ... CY3: =_xlfn.XLOOKUP(CY2,Sheet2!$D:$D,Sheet2!$E:$E) -> I_RATE
B4: DG ECFIN AMECO, Estimate
C5: Austria, Capital Formation & Saving, Gross Fixed Capital Formation, Private Sector, Current Prices, EUR | D5: Austria, Capital Formation & Saving, Gross Fixed Capital Formation, General Government, Current Prices, EUR | E5: France, Capital Formation & Saving, Gross Fixed Capital Formation, Private Sector, Current Prices, EUR | F5: France, Capital Formation & Saving, Gross Fixed Capital Formation, General Government, Current Prices, EUR | G5: Italy, Capital Formation & Saving, Gross Fixed Capital Formation, Private Sector, Current Prices, EUR | H5: Italy, Capital Formation & Saving, Gross Fixed Capital Formation, General Government, Current Prices, EUR | I5: Netherlands, Capital Formation & Saving, Gross Fixed Capital Formation, Private Sector, Current Prices, EUR | J5: Netherlands, Capital Formation & Saving, Gross Fixed Capital Formation, General Government, Current Prices, EUR | K5: Finland, Capital Formation & Saving, Gross Fixed Capital Formation, Private Sector, Current Prices, EUR | L5: Finland, Capital Formation & Saving, Gross Fixed Capital Formation, General Government, Current Prices, EUR | M5: Austria, Capital Formation & Saving, Consumption of Fixed Capital, Total, Current Prices, EUR | N5: Austria, Capital Formation & Saving, Consumption of Fixed Capital, General Government, Current Prices, EUR | O5: France, Capital Formation & Saving, Consumption of Fixed Capital, Total, Current Prices, EUR | P5: France, Capital Formation & Saving, Consumption of Fixed Capital, General Government, Current Prices, EUR | Q5: Italy, Capital Formation & Saving, Consumption of Fixed Capital, General Government, Current Prices, EUR | R5: Italy, Capital Formation & Saving, Consumption of Fixed Capital, Total, Current Prices, EUR | S5: Netherlands, Capital Formation & Saving, Consumption of Fixed Capital, Total, Current Prices, EUR | T5: Netherlands, Capital Formation & Saving, Consumption of Fixed Capital, General Government, Current Prices, EUR | U5: Finland, Capital Formation & Saving, Consumption of Fixed Capital, General Government, Current Prices, EUR | V5: Finland, Capital Formation & Saving, Consumption of Fixed Capital, Total, Current Prices, EUR | W5: Austria, General Government, Net Lending(ESA2010), Net Lending (+) or Net Borrowing (-) Excluding Interest, Percent of GDP (Excessive Deficit Procedure), Market Prices | X5: Finland, General Government, Net Lending(ESA2010), Net Lending (+) or Net Borrowing (-) Excluding Interest, Percent of GDP (Excessive Deficit Procedure), Market Prices | Y5: France, General Government, Net Lending(ESA2010), Net Lending (+) or Net Borrowing (-) Excluding Interest, Percent of GDP (Excessive Deficit Procedure), Market Prices | Z5: Italy, General Government, Net Lending(ESA2010), Net Lending (+) or Net Borrowing (-) Excluding Interest, Percent of GDP (Excessive Deficit Procedure), Market Prices | AA5: Netherlands, General Government, Net Lending(ESA2010), Net Lending (+) or Net Borrowing (-) Excluding Interest, Percent of GDP (Excessive Deficit Procedure), Market Prices | AB5: Austria, General Government, Revenue(ESA2010), Total Revenue, EUR | AC5: Finland, General Government, Revenue(ESA2010), Total Revenue, EUR | AD5: France, General Government, Revenue(ESA2010), Total Revenue, EUR | AE5: Italy, General Government, Revenue(ESA2010), Total Revenue, EUR | AF5: Netherlands, General Government, Revenue(ESA2010), Total Revenue, EUR | AG5: Austria, General Government, Revenue(ESA2010), Current Taxes on Income & Wealth, Direct Taxes, EUR | AH5: Finland, General Government, Revenue(ESA2010), Current Taxes on Income & Wealth, Direct Taxes, EUR | AI5: France, General Government, Revenue(ESA2010), Current Taxes on Income & Wealth, Direct Taxes, EUR | AJ5: Italy, General Government, Revenue(ESA2010), Current Taxes on Income & Wealth, Direct Taxes, EUR | AK5: Netherlands, General Government, Revenue(ESA2010), Current Taxes on Income & Wealth, Direct Taxes, EUR | AL5: Austria, General Government, Revenue(ESA2010), Taxes Linked to Imports & Production, Indirect Taxes, EUR | AM5: Finland, General Government, Revenue(ESA2010), Taxes Linked to Imports & Production, Indirect Taxes, EUR | AN5: France, General Government, Revenue(ESA2010), Taxes Linked to Imports & Production, Indirect Taxes, EUR | AO5: Italy, General Government, Revenue(ESA2010), Taxes Linked to Imports & Production, Indirect Taxes, EUR | AP5: Netherlands, General Government, Revenue(ESA2010), Taxes Linked to Imports & Production, Indirect Taxes, EUR | AQ5: Austria, General Government, Revenue(ESA2010), Actual Social Contributions Received, EUR | AR5: Finland, General Government, Revenue(ESA2010), Actual Social Contributions Received, EUR | AS5: France, General Government, Revenue(ESA2010), Actual Social Contributions Received, EUR | AT5: Italy, General Government, Revenue(ESA2010), Actual Social Contributions Received, EUR | AU5: Netherlands, General Government, Revenue(ESA2010), Actual Social Contributions Received, EUR | AV5: Austria, General Government, Revenue(ESA2010), Imputed Social Contributions, EUR | AW5: France, General Government, Revenue(ESA2010), Imputed Social Contributions, EUR | AX5: Finland, General Government, Revenue(ESA2010), Imputed Social Contributions, EUR | AY5: Italy, General Government, Revenue(ESA2010), Imputed Social Contributions, EUR | AZ5: Netherlands, General Government, Revenue(ESA2010), Imputed Social Contributions, EUR | BA5: Austria, General Government, Expenditure(ESA2010), Total Expenditure, EUR | BB5: Finland, General Government, Expenditure(ESA2010), Total Expenditure, EUR | BC5: France, General Government, Expenditure(ESA2010), Total Expenditure, EUR | BD5: Netherlands, General Government, Expenditure(ESA2010), Total Expenditure, EUR | BE5: Italy, General Government, Expenditure(ESA2010), Total Expenditure, EUR | BF5: Austria, General Government, Expenditure(ESA2010), Final Consumption Expenditure, EUR | BG5: Finland, General Government, Expenditure(ESA2010), Final Consumption Expenditure, EUR | BH5: France, General Government, Expenditure(ESA2010), Final Consumption Expenditure, EUR | BI5: Italy, General Government, Expenditure(ESA2010), Final Consumption Expenditure, EUR | BJ5: Netherlands, General Government, Expenditure(ESA2010), Final Consumption Expenditure, EUR | BK5: Austria, General Government, Expenditure(ESA2010), Subsidies, EUR | BL5: Finland, General Government, Expenditure(ESA2010), Subsidies, EUR | BM5: France, General Government, Expenditure(ESA2010), Subsidies, EUR | BN5: Italy, General Government, Expenditure(ESA2010), Subsidies, EUR | BO5: Netherlands, General Government, Expenditure(ESA2010), Subsidies, EUR | BP5: Austria, General Government, Expenditure(ESA2010), Social Benefits Other than Social Transfers in Kind, EUR | BQ5: France, General Government, Expenditure(ESA2010), Social Benefits Other than Social Transfers in Kind, EUR | BR5: Finland, General Government, Expenditure(ESA2010), Social Benefits Other than Social Transfers in Kind, EUR | BS5: Italy, General Government, Expenditure(ESA2010), Social Benefits Other than Social Transfers in Kind, EUR | BT5: Netherlands, General Government, Expenditure(ESA2010), Social Benefits Other than Social Transfers in Kind, EUR | BU5: Austria, General Government, Expenditure(ESA2010), Interest, EUR | BV5: Finland, General Government, Expenditure(ESA2010), Interest, EUR | BW5: France, General Government, Expenditure(ESA2010), Interest, EUR | BX5: Italy, General Government, Expenditure(ESA2010), Interest, EUR | BY5: Netherlands, General Government, Expenditure(ESA2010), Interest, EUR | BZ5: Austria, Gross Public Debt, Based on ESA2010, Total, Percent of GDP (Excessive Deficit Procedure), Market Prices | CA5: Finland, Gross Public Debt, Based on ESA2010, Total, Percent of GDP (Excessive Deficit Procedure), Market Prices | CB5: France, Gross Public Debt, Based on ESA2010, Total, Percent of GDP (Excessive Deficit Procedure), Market Prices | CC5: Italy, Gross Public Debt, Based on ESA2010, Total, Percent of GDP (Excessive Deficit Procedure), Market Prices | CD5: Netherlands, Gross Public Debt, Based on ESA2010, Total, Percent of GDP (Excessive Deficit Procedure), Market Prices | CE5: United States, Monetary Variables, Exchange Rates & Purchasing Power Parities, National Currency per ECU/EUR (Annual Averages), Average of Period | CF5: Austria, Gross Public Debt, Based on ESA2010, Stock-Flow Adjustment on Gross Public Debt, EUR | CG5: Finland, Gross Public Debt, Based on ESA2010, Stock-Flow Adjustment on Gross Public Debt, EUR | CH5: France, Gross Public Debt, Based on ESA2010, Stock-Flow Adjustment on Gross Public Debt, EUR | CI5: Italy, Gross Public Debt, Based on ESA2010, Stock-Flow Adjustment on Gross Public Debt, EUR | CJ5: Netherlands, Gross Public Debt, Based on ESA2010, Stock-Flow Adjustment on Gross Public Debt, EUR | CK5: Austria, General Government, Expenditure(ESA2010), Implicit Interest Rate, Percentage of Gross Public Debt | CL5: Finland, General Government, Expenditure(ESA2010), Implicit Interest Rate, Percentage of Gross Public Debt | CM5: France, General Government, Expenditure(ESA2010), Implicit Interest Rate, Percentage of Gross Public Debt | CN5: Italy, General Government, Expenditure(ESA2010), Implicit Interest Rate, Percentage of Gross Public Debt | CO5: Netherlands, General Government, Expenditure(ESA2010), Implicit Interest Rate, Percentage of Gross Public Debt | CP5: Austria, Monetary Variables, Interest Rates, Nominal, Long-Term, Current Prices | CQ5: Finland, Monetary Variables, Interest Rates, Nominal, Long-Term, Current Prices | CR5: France, Monetary Variables, Interest Rates, Nominal, Long-Term, Current Prices | CS5: Italy, Monetary Variables, Interest Rates, Nominal, Long-Term, Current Prices | CT5: Netherlands, Monetary Variables, Interest Rates, Nominal, Long-Term, Current Prices | CU5: Austria, Monetary Variables, Interest Rates, Nominal, Short-Term, Current Prices | CV5: Finland, Monetary Variables, Interest Rates, Nominal, Short-Term, Current Prices | CW5: Finland, Monetary Variables, Interest Rates, Nominal, Short-Term, Current Prices | CX5: Italy, Monetary Variables, Interest Rates, Nominal, Short-Term, Current Prices | CY5: Netherlands, Monetary Variables, Interest Rates, Nominal, Short-Term, Current Prices
A6: 1960 | B6: 21916 | C6: 1342600000 | D6: 351380000 | E6: 10962500000 | F6: 2417600000 | K6: 1229120000 | L6: 244770000 | M6: 1002100000 | N6: 217340000 | O6: 7292700000 | R6: 5185000000 | S6: 1687600000 | U6: 66100000 | V6: 568970000 | CC6: 31.7222 | CE6: 1.05621 | CR6: 5.7 | CS6: 5.26 | CT6: 4.2 | CX6: 3.5 | CY6: 2.1
A7: =A6+1 -> 1961 | B7: 22282 | C7: 1557500000 | D7: 391750000 | E7: 12425400000 | F7: 2783500000 | K7: 1386240000 | L7: 243560000 | M7: 1088700000 | N7: 233560000 | O7: 7863300000 | R7: 5620500000 | S7: 1869400000 | U7: 73860000 | V7: 642730000 | CC7: 29.8648 | CE7: 1.06734 | CQ7: 6.58 | CR7: 5.52 | CS7: 4.97 | CT7: 3.91 | CX7: 3.5 | CY7: 1.14
A8: =A7+1 -> 1962 | B8: 22647 | C8: 1619400000 | D8: 418620000 | E8: 13563800000 | F8: 3286400000 | K8: 1451490000 | L8: 2.6569e+08 | M8: 1181000000 | N8: 248100000 | O8: 8596400000 | R8: 6274100000 | S8: 2.0336e+09 | U8: 79320000 | V8: 705830000 | CC8: 28.7243 | CE8: 1.06981 | CQ8: 7.09 | CR8: 5.43 | CS8: 5.05 | CT8: 4.21 | CX8: 3.5 | CY8: 1.88
A9: =A8+1 -> 1963 | B9: 23012 | C9: 1758600000 | D9: 458510000 | E9: 15700400000 | F9: 3858000000 | K9: 1431710000 | L9: 300740000 | M9: 1307400000 | N9: 268220000 | O9: 9711600000 | R9: 7256400000 | S9: 2210300000 | U9: 86630000 | V9: 774670000 | CC9: 26.7858 | CE9: 1.06981 | CQ9: 7.95 | CR9: 5.34 | CS9: 5.19 | CT9: 4.22 | CX9: 3.5 | CY9: 1.98
A10: =A9+1 -> 1964 | B10: 23377 | C10: 1938300000 | D10: 5.3072e+08 | E10: 17883000000 | F10: 4616000000 | K10: 1547250000 | L10: 380510000 | M10: 1410600000 | N10: 283310000 | O10: 10614600000 | R10: 8.2548e+09 | S10: 2442500000 | U10: 95070000 | V10: 850220000 | CC10: 26.6171 | CE10: 1.06981 | CQ10: 8.41 | CR10: 5.45 | CS10: 5.74 | CT10: 4.92 | CX10: 3.5 | CY10: 3.45
A11: =A10+1 -> 1965 | B11: 23743 | C11: 2187000000 | D11: 588290000 | E11: 19441100000 | F11: 5216600000 | K11: 1785440000 | L11: 443980000 | M11: 1566900000 | N11: 316840000 | O11: 11521200000 | R11: 8867400000 | S11: 2689000000 | U11: 106330000 | V11: 930440000 | CC11: 27.6472 | CE11: 1.06981 | CP11: 6.51 | CQ11: 8.62 | CR11: 6.2 | CS11: 5.39 | CT11: 5.21 | CX11: 3.5 | CY11: 3.96
A12: =A11+1 -> 1966 | B12: 24108 | C12: 2440800000 | D12: 633230000 | E12: 21532000000 | F12: 5519300000 | K12: 1940650000 | L12: 459950000 | M12: 1703300000 | N12: 336950000 | O12: 12540800000 | R12: 9336900000 | S12: 2950800000 | U12: 114200000 | V12: 1025690000 | CC12: 32.2993 | CE12: 1.06981 | CP12: 6.91 | CQ12: 8.41 | CR12: 6.58 | CS12: 5.49 | CT12: 6.24 | CX12: 3.5 | CY12: 4.87
A13: =A12+1 -> 1967 | B13: 24473 | C13: 2428600000 | D13: 731070000 | E13: 23701800000 | F13: 6149200000 | K13: 1868740000 | L13: 458790000 | M13: 1853100000 | N13: 378950000 | O13: 13710500000 | R13: 10026000000 | S13: 3221300000 | U13: 121100000 | V13: 1.05916e+09 | CC13: 31.8738 | CE13: 1.064817 | CP13: 7.22 | CQ13: 8.19 | CR13: 6.71 | CS13: 5.59 | CT13: 6 | CU13: 4.75 | CX13: 3.5 | CY13: 4.69
A14: =A13+1 -> 1968 | B14: 24838 | C14: 2604400000 | D14: 788100000 | E14: 26671700000 | F14: 6658500000 | K14: 1660270000 | L14: 427050000 | M14: 2028400000 | N14: 409620000 | O14: 14867900000 | R14: 11130800000 | S14: 3605000000 | U14: 121660000 | V14: 1052200000 | CC14: 34.2302 | CE14: 1.02889 | CP14: 7.74 | CQ14: 8.15 | CR14: 6.95 | CS14: 5.61 | CT14: 6.22 | CU14: 4.14 | CX14: 3.5 | CY14: 4.55
A15: =A14+1 -> 1969 | B15: 25204 | C15: 2808300000 | D15: 821810000 | E15: 29496500000 | F15: 6936900000 | K15: 2031170000 | L15: 440490000 | M15: 2172300000 | N15: 408790000 | O15: 15884500000 | R15: 12429500000 | S15: 4012100000 | U15: 134570000 | V15: 1156990000 | CC15: 34.8413 | CE15: 1.022187 | CP15: 7.52 | CQ15: 7.91 | CR15: 7.87 | CS15: 5.8 | CT15: 7.04 | CU15: 4.49 | CX15: 3.71 | CY15: 5.71
A16: =A15+1 -> 1970 | B16: 25569 | C16: 3270100000 | D16: 926410000 | E16: 30363000000 | F16: 7144300000 | G16: 25621100000 | H16: 3748410000 | I16: 8.1766e+09 | J16: 2414530000 | K16: 2605400000 | L16: 426640000 | M16: 2416300000 | N16: 456150000 | O16: 16419600000 | P16: 2670700000 | Q16: 3497000000 | R16: 14482100000 | S16: 4630400000 | T16: 893110000 | U16: 156550000 | V16: 1338640000 | CC16: 35.7766 | CE16: 1.022227 | CP16: 7.82 | CQ16: 7.83 | CR16: 8.04 | CS16: 7.73 | CT16: 7.83 | CU16: 5.62 | CV16: 10.61 | CW16: 10.61 | CX16: 5.25 | CY16: 6.15
A17: =A16+1 -> 1971 | B17: 25934 | C17: 3996800000 | D17: 1127250000 | E17: 33939600000 | F17: 7556500000 | G17: 27188100000 | H17: 3882060000 | I17: 9422700000 | J17: 2808950000 | K17: 2944820000 | L17: 470440000 | M17: 2770300000 | N17: 537910000 | O17: 18520800000 | P17: 3101100000 | Q17: 3576760000 | R17: 15468700000 | S17: 5464700000 | T17: 1.06632e+09 | U17: 173950000 | V17: 1532160000 | CC17: 40.416 | CE17: 1.04776 | CP17: 7.71 | CQ17: 8.1 | CR17: 7.75 | CS17: 7 | CT17: 7.05 | CU17: 4.39 | CV17: 8.09 | CW17: 8.09 | CX17: 5.69 | CY17: 4.45
A18: =A17+1 -> 1972 | B18: 26299 | C18: 5040000000 | D18: 1361760000 | E18: 39231900000 | F18: 8.2451e+09 | G18: 28674600000 | H18: 4378990000 | I18: 10048100000 | J18: 2806310000 | K18: 3249130000 | L18: 568970000 | M18: 3174200000 | N18: 609600000 | O18: 21783800000 | P18: 3706700000 | Q18: 3648220000 | R18: 16829500000 | S18: 6257900000 | T18: 1246280000 | U18: 189220000 | V18: 1692000000 | CC18: 45.9063 | CE18: 1.12178 | CP18: 7.38 | CQ18: 7.97 | CR18: 7.35 | CS18: 6.59 | CT18: 6.67 | CU18: 5.17 | CV18: 7.77 | CW18: 7.77 | CX18: 5.18 | CY18: 2.74
A19: =A18+1 -> 1973 | B19: 26665 | C19: 5809800000 | D19: 1546830000 | E19: 47375500000 | F19: 9508500000 | G19: 34125600000 | H19: 4353380000 | I19: 11642300000 | J19: 3034010000 | K19: 4101960000 | L19: 631220000 | M19: 3787400000 | N19: 732760000 | O19: 26177600000 | P19: 4605600000 | Q19: 4006330000 | R19: 18949300000 | S19: 7280300000 | T19: 1501540000 | U19: 236090000 | V19: 2.06436e+09 | CC19: 48.8105 | CE19: 1.23173 | CP19: 8.25 | CQ19: 8.26 | CR19: 8.29 | CS19: 6.92 | CT19: 7.31 | CU19: 6.94 | CV19: 9.34 | CW19: 9.34 | CX19: 6.98 | CY19: 7.54
A20: =A19+1 -> 1974 | B20: 27030 | C20: 7184000000 | D20: 2022910000 | E20: 54618100000 | F20: 10781300000 | G20: 40741900000 | H20: 5339450000 | I20: 13059400000 | J20: 3672870000 | K20: 5593020000 | L20: 820640000 | M20: 4779600000 | N20: 958160000 | O20: 31408400000 | P20: 5599900000 | Q20: 4691960000 | R20: 23174600000 | S20: 9166300000 | T20: 1896770000 | U20: 330280000 | V20: 2822060000 | CC20: 48.5119 | CE20: 1.1927 | CP20: 9.74 | CQ20: 8.79 | CR20: 10.45 | CS20: 9.61 | CT20: 10.69 | CU20: 7.26 | CV20: 10.41 | CW20: 10.41 | CX20: 14.88 | CY20: 10.36
A21: =A20+1 -> 1975 | B21: 27395 | C21: 7124700000 | D21: 2231340000 | E21: 60523900000 | F21: 13887000000 | G21: 43125800000 | H21: 6740150000 | I21: 13866500000 | J21: 4519270000 | K21: 6750070000 | L21: 1087290000 | M21: 5262200000 | N21: 1.0712e+09 | O21: 39623800000 | P21: 7388600000 | Q21: 5745980000 | R21: 28792900000 | S21: 10704100000 | T21: 2206170000 | U21: 434390000 | V21: 3447650000 | X21: 5.533027 | AC21: 10333800000 | AH21: 3791760000 | AM21: 2848400000 | AR21: 2.11831e+09 | AX21: 346728000 | BB21: 9157500000 | BG21: 4010270000 | BL21: 779811000 | BR21: 2194200000 | BV21: 136074000 | CA21: 6.5094 | CC21: 54.7423 | CE21: 1.24077 | CP21: 9.61 | CQ21: 9.63 | CR21: 9.52 | CS21: 10.04 | CT21: 9.15 | CU21: 5.49 | CV21: 11.72 | CW21: 11.72 | CX21: 10.44 | CY21: 5.35
A22: =A21+1 -> 1976 | B22: 27760 | C22: 8441400000 | D22: 2364020000 | E22: 68415300000 | F22: 15711700000 | G22: 44755300000 | H22: 7106940000 | I22: 15969000000 | J22: 5273290000 | K22: 7204620000 | L22: 1201230000 | M22: 6031500000 | N22: 1238180000 | O22: 46426000000 | P22: 8917400000 | Q22: 6128090000 | R22: 30634200000 | S22: 12744700000 | T22: 2674690000 | U22: 553030000 | V22: 4284980000 | X22: 8.24907 | AC22: 13482500000 | AH22: 5312440000 | AM22: 3428540000 | AR22: 2730700000 | AX22: 427533000 | BB22: 11310300000 | BG22: 5105570000 | BL22: 906094000 | BR22: 2894810000 | BV22: 169634000 | CA22: 6.1066 | CC22: 54.4349 | CE22: 1.11805 | CG22: 2370000000 | CL22: 10.423729 | CP22: 8.75 | CQ22: 10.17 | CR22: 9.33 | CS22: 12.66 | CT22: 9.2 | CU22: 4.67 | CV22: 12.37 | CW22: 12.37 | CX22: 15.97 | CY22: 7.37
A23: =A22+1 -> 1977 | B23: 28126 | C23: 10345100000 | D23: 2726180000 | E23: 71892800000 | F23: 15154100000 | G23: 50099700000 | H23: 7761990000 | I23: 20021000000 | J23: 5371570000 | K23: 7220140000 | L23: 1263330000 | M23: 7244100000 | N23: 1462370000 | O23: 51049600000 | P23: 9947500000 | Q23: 7248900000 | R23: 34840500000 | S23: 14742000000 | T23: 3157070000 | U23: 616130000 | V23: 4707720000 | X23: 7.006843 | AC23: 14033800000 | AH23: 5084390000 | AM23: 3834000000 | AR23: 2943460000 | AX23: 462099000 | BB23: 12195800000 | BG23: 5422220000 | BL23: 941026000 | BR23: 3353780000 | BV23: 210987000 | CA23: 7.7726 | CC23: 53.4769 | CE23: 1.14112 | CG23: 2190000000 | CL23: 12.967383 | CP23: 8.73 | CQ23: 10.75 | CR23: 9.87 | CS23: 14.71 | CT23: 8.49 | CU23: 7.49 | CV23: 11.76 | CW23: 11.76 | CX23: 13.95 | CY23: 4.75
A24: =A23+1 -> 1978 | B24: 28491 | C24: 10123000000 | D24: 3066920000 | E24: 78951000000 | F24: 15878300000 | G24: 54015600000 | H24: 7904750000 | I24: 22028000000 | J24: 5980610000 | K24: 6149450000 | L24: 1215590000 | M24: 8005900000 | N24: 1637250000 | O24: 56792400000 | P24: 11222500000 | Q24: 7787920000 | R24: 37353100000 | S24: 16369000000 | T24: 3564370000 | U24: 606090000 | V24: 4592230000 | X24: 4.611048 | Y24: -0.772626 | AC24: 12830100000 | AD24: 172906000000 | AH24: 4.25513e+09 | AI24: 26524800000 | AM24: 3787510000 | AN24: 58053900000 | AR24: 2570780000 | AS24: 62802300000 | AW24: 6658050000 | AX24: 442652000 | BB24: 11739300000 | BC24: 180064000000 | BG24: 5149510000 | BH24: 81863300000 | BL24: 862603000 | BM24: 7804290000 | BQ24: 58729300000 | BR24: 3353940000 | BV24: 219056000 | BW24: 4110710000 | CA24: 10.9762 | CC24: 57.5131 | CE24: 1.2741 | CG24: 1990000000 | CL24: 10.990888 | CP24: 8.21 | CQ24: 9.78 | CR24: 9.5 | CS24: 13.05 | CT24: 8.05 | CU24: 6.44 | CV24: 8.58 | CW24: 8.58 | CX24: 11.5 | CY24: 6.97
A25: =A24+1 -> 1979 | B25: 28856 | C25: 11539900000 | D25: 3146990000 | E25: 88235200000 | F25: 18006200000 | G25: 63287400000 | H25: 8962690000 | I25: 22854800000 | J25: 6173950000 | K25: 6871860000 | L25: 1331700000 | M25: 8732900000 | N25: 1805310000 | O25: 64021800000 | P25: 12818000000 | Q25: 10519030000 | R25: 41893500000 | S25: 18059300000 | T25: 3968560000 | U25: 680370000 | V25: 5050840000 | X25: 4.299299 | Y25: 0.657303 | AC25: 14199500000 | AD25: 201579000000 | AH25: 4534690000 | AI25: 30985100000 | AM25: 4.25874e+09 | AN25: 68118200000 | AR25: 2881240000 | AS25: 75096600000 | AW25: 7230390000 | AX25: 506089000 | BB25: 13093500000 | BC25: 203739000000 | BG25: 5737910000 | BH25: 91669300000 | BL25: 1.057983e+09 | BM25: 8841640000 | BQ25: 6.62639e+10 | BR25: 3606300000 | BV25: 288236000 | BW25: 5077930000 | CA25: 11.1341 | CC25: 56.3298 | CE25: 1.37047 | CG25: 1700000000 | CL25: 9.392064 | CP25: 7.96 | CQ25: 9.5 | CR25: 9.89 | CS25: 13.02 | CT25: 9.2 | CU25: 5.6 | CV25: 8.52 | CW25: 8.52 | CX25: 11.95 | CY25: 9.58
A26: =A25+1 -> 1980 | B26: 29221 | C26: 13220800000 | D26: 3231730000 | E26: 103085200000 | F26: 20853500000 | G26: 78572000000 | H26: 12608650000 | I26: 25092500000 | J26: 6851420000 | K26: 8899790000 | L26: 1670290000 | M26: 9812200000 | N26: 2.08083e+09 | O26: 75462600000 | P26: 15169000000 | Q26: 6667620000 | R26: 49597400000 | S26: 19921900000 | T26: 4414600000 | U26: 846070000 | V26: 6142030000 | X26: 4.663259 | Y26: 0.798363 | AC26: 16945500000 | AD26: 232147000000 | AH26: 5412060000 | AI26: 37191600000 | AM26: 5014320000 | AN26: 75403700000 | AR26: 3517610000 | AS26: 86615100000 | AW26: 8.31548e+09 | AX26: 596615000 | BB26: 15513100000 | BC26: 234311000000 | BG26: 6858190000 | BH26: 106268200000 | BL26: 1184033000 | BM26: 9760630000 | BQ26: 76293400000 | BR26: 4.15216e+09 | BV26: 370154000 | BW26: 6156140000 | CA26: 11.221 | CC26: 54.2665 | CE26: 1.39233 | CG26: 2290000000 | CL26: 9.962871 | CP26: 9.32 | CQ26: 11.6 | CR26: 13.13 | CS26: 15.25 | CT26: 10.74 | CU26: 10.28 | CV26: 13.8 | CW26: 13.8 | CX26: 16.93 | CY26: 10.55
A27: =A26+1 -> 1981 | B27: 29587 | C27: 14308300000 | D27: 3399870000 | E27: 109209300000 | F27: 23751600000 | G27: 87468800000 | H27: 16699310000 | I27: 23869300000 | J27: 6956760000 | K27: 10824670000 | L27: 1983570000 | M27: 10935500000 | N27: 2332710000 | O27: 84653100000 | P27: 17269000000 | Q27: 8214710000 | R27: 59476500000 | S27: 21762600000 | T27: 4801170000 | U27: 1056910000 | V27: 7601830000 | X27: 6.1451 | Y27: -0.715065 | AC27: 21789500000 | AD27: 2.57821e+11 | AH27: 7302870000 | AI27: 41629900000 | AM27: 6254640000 | AN27: 83293400000 | AR27: 4385200000 | AS27: 94432800000 | AW27: 9318170000 | AX27: 743064000 | BB27: 19378000000 | BC27: 271156000000 | BG27: 8659990000 | BH27: 120481400000 | BL27: 1458837000 | BM27: 11576040000 | BQ27: 88410800000 | BR27: 5179120000 | BV27: 487520000 | BW27: 9414830000 | CA27: 11.5092 | CC27: 56.5292 | CE27: 1.11645 | CG27: 3460000000 | CL27: 10.416115 | CP27: 10.61 | CQ27: 12.4 | CR27: 15.85 | CS27: 19.36 | CT27: 12.24 | CU27: 11.37 | CV27: 12.7 | CW27: 12.7 | CX27: 19.31 | CY27: 11.77
A28: =A27+1 -> 1982 | B28: 29952 | C28: 14665400000 | D28: 3559160000 | E28: 113063700000 | F28: 26476300000 | G28: 92568300000 | H28: 18664380000 | I28: 25513000000 | J28: 7255830000 | K28: 12439120000 | L28: 2383490000 | M28: 12583100000 | N28: 2655420000 | O28: 92205500000 | P28: 19273300000 | Q28: 9463680000 | R28: 68002100000 | S28: 24502200000 | T28: 5377980000 | U28: 1221430000 | V28: 8686420000 | X28: 4.232756 | Y28: -1.099869 | AC28: 24749400000 | AD28: 283308000000 | AH28: 8249380000 | AI28: 45882100000 | AM28: 7132790000 | AN28: 91442900000 | AR28: 4732880000 | AS28: 104905500000 | AW28: 10271050000 | AX28: 862705000 | BB28: 23098500000 | BC28: 300263000000 | BG28: 9968470000 | BH28: 132695400000 | BL28: 1588994000 | BM28: 12728150000 | BQ28: 99003900000 | BR28: 6450710000 | BV28: 635345000 | BW28: 10457700000 | CA28: 13.8067 | CC28: 61.0334 | CE28: 0.979715 | CG28: 3010000000 | CL28: 11.491889 | CP28: 9.92 | CQ28: 12.38 | CR28: 15.65 | CS28: 20.22 | CT28: 10.45 | CU28: 8.77 | CV28: 13.67 | CW28: 13.67 | CX28: 19.88 | CY28: 8.21
A29: =A28+1 -> 1983 | B29: 30317 | C29: 15785300000 | D29: 3800630000 | E29: 111882200000 | F29: 26509400000 | G29: 100268200000 | H29: 20858270000 | I29: 27568500000 | J29: 7064540000 | K29: 13311290000 | L29: 2636300000 | M29: 13836300000 | N29: 2890950000 | O29: 96781400000 | P29: 20460200000 | Q29: 10871770000 | R29: 76989600000 | S29: 26056800000 | T29: 5661270000 | U29: 1334970000 | V29: 9364050000 | X29: 2.943028 | Y29: -0.337976 | AC29: 26327000000 | AD29: 303788000000 | AH29: 8772860000 | AI29: 48881100000 | AM29: 7565250000 | AN29: 96264400000 | AR29: 4791970000 | AS29: 113093500000 | AW29: 10565790000 | AX29: 936044000 | BB29: 25455800000 | BC29: 319801000000 | BG29: 10765110000 | BH29: 140886600000 | BL29: 1750727000 | BM29: 13497400000 | BQ29: 105269500000 | BR29: 7303310000 | BV29: 815884000 | BW29: 13907210000 | CA29: 15.3063 | CC29: 67.0259 | CE29: 0.89022 | CG29: 3040000000 | CL29: 11.500678 | CP29: 8.17 | CQ29: 13.06 | CR29: 13.59 | CS29: 18.3 | CT29: 8.81 | CU29: 5.38 | CV29: 14.22 | CW29: 14.22 | CX29: 18.31 | CY29: 5.67
A30: =A29+1 -> 1984 | B30: 30682 | C30: 1.64745e+10 | D30: 3957510000 | E30: 115250000000 | F30: 28159200000 | G30: 111056600000 | H30: 22742110000 | I30: 29775300000 | J30: 7916710000 | K30: 14886730000 | L30: 2824300000 | M30: 14730800000 | N30: 3044720000 | O30: 103155900000 | P30: 22276100000 | Q30: 12140720000 | R30: 85404200000 | S30: 27276100000 | T30: 5890410000 | U30: 1587100000 | V30: 10981290000 | X30: 4.808227 | Y30: -0.408719 | AC30: 32016300000 | AD30: 330290000000 | AH30: 10549590000 | AI30: 53907200000 | AM30: 9348890000 | AN30: 105223700000 | AR30: 5780750000 | AS30: 123615600000 | AW30: 11371950000 | AX30: 1098758000 | BB30: 29843900000 | BC30: 348755000000 | BG30: 12729490000 | BH30: 152063200000 | BL30: 2035157000 | BM30: 1.709849e+10 | BQ30: 114005900000 | BR30: 8652880000 | BV30: 1059742000 | BW30: 15736300000 | CA30: 15.1324 | CC30: 72.2966 | CE30: 0.789034 | CG30: 3520000000 | CL30: 11.531087 | CP30: 8.02 | CQ30: 14.01 | CR30: 12.49 | CS30: 15.6 | CT30: 8.56 | CU30: 6.57 | CV30: 15.8 | CW30: 15.8 | CX30: 17.27 | CY30: 6.08
A31: =A30+1 -> 1985 | B31: 31048 | C31: 18164500000 | D31: 4.06549e+09 | E31: 122424600000 | F31: 31600700000 | G31: 115925500000 | H31: 25139170000 | I31: 3.26953e+10 | J31: 7781680000 | K31: 16411390000 | L31: 3251370000 | M31: 15494600000 | N31: 3179630000 | O31: 110776700000 | P31: 24184900000 | Q31: 13264340000 | R31: 92229800000 | S31: 28576800000 | T31: 6109190000 | U31: 1789710000 | V31: 12112530000 | X31: 5.067981 | Y31: -0.45065 | AC31: 36587100000 | AD31: 360884000000 | AH31: 11980810000 | AI31: 57532800000 | AM31: 10353220000 | AN31: 114693000000 | AR31: 6970120000 | AS31: 133630300000 | AW31: 12404720000 | AX31: 1231139000 | BB31: 34126100000 | BC31: 382625000000 | BG31: 14516550000 | BH31: 165187500000 | BL31: 2179825000 | BM31: 17408120000 | BQ31: 125086900000 | BR31: 10030240000 | BV31: 1274204000 | BW31: 18480630000 | CA31: 15.79 | CC31: 78.0334 | CE31: 0.763088 | CG31: 3430000000 | CL31: 12.447414 | CP31: 7.77 | CQ31: 12.7 | CR31: 11.12 | CS31: 13.71 | CT31: 7.34 | CU31: 6.2 | CV31: 12.81 | CW31: 12.81 | CX31: 15.04 | CY31: 6.26
A32: =A31+1 -> 1986 | B32: 31413 | C32: 19628700000 | D32: 4678180000 | E32: 1.321349e+11 | F32: 33630600000 | G32: 123617600000 | H32: 26652290000 | I32: 36904000000 | J32: 7712900000 | K32: 1.630505e+10 | L32: 3257190000 | M32: 17058000000 | N32: 3468500000 | O32: 117222400000 | P32: 25644000000 | Q32: 14182190000 | R32: 98533300000 | S32: 31012200000 | T32: 6466380000 | U32: 1861420000 | V32: 12352960000 | X32: 5.462015 | Y32: -0.648131 | AC32: 37986600000 | AD32: 382727000000 | AH32: 12787570000 | AI32: 61743200000 | AM32: 10743470000 | AN32: 121482700000 | AR32: 7015850000 | AS32: 139939900000 | AW32: 13497760000 | AX32: 1271593000 | BB32: 35119800000 | BC32: 407853000000 | BG32: 14903310000 | BH32: 175285600000 | BL32: 2213646000 | BM32: 19196100000 | BQ32: 132947900000 | BR32: 10443780000 | BV32: 1217864000 | BW32: 20075890000 | CA32: 16.402 | CC32: 81.951 | CE32: 0.984167 | CG32: 3430000000 | CL32: 11.101437 | CP32: 7.44 | CQ32: 11.66 | CR32: 8.54 | CS32: 11.47 | CT32: 6.19 | CU32: 5.32 | CV32: 11.67 | CW32: 11.67 | CX32: 12.83 | CY32: 5.66
A33: =A32+1 -> 1987 | B33: 31778 | C33: 21872700000 | D33: 4561050000 | E33: 140544500000 | F33: 35439500000 | G33: 1.322667e+11 | H33: 28339350000 | I33: 38705900000 | J33: 8261120000 | K33: 17679260000 | L33: 3717560000 | M33: 18311800000 | N33: 3712840000 | O33: 121509400000 | P33: 26511500000 | Q33: 15111600000 | R33: 104617200000 | S33: 3.36566e+10 | T33: 6846770000 | U33: 2062440000 | V33: 13401770000 | X33: 3.226869 | Y33: 0.45241 | AC33: 39227500000 | AD33: 399531000000 | AH33: 12222060000 | AI33: 6.42562e+10 | AM33: 11572930000 | AN33: 126801700000 | AR33: 7465650000 | AS33: 146540700000 | AW33: 13592290000 | AX33: 1366354000 | BB33: 37933900000 | BC33: 415853000000 | BG33: 1.612627e+10 | BH33: 179456400000 | BL33: 2264345000 | BM33: 18747850000 | BQ33: 134981900000 | BR33: 11263030000 | BV33: 1268925000 | BW33: 19957690000 | CA33: 17.6184 | CC33: 85.6825 | CE33: 1.15444 | CG33: 3170000000 | CL33: 10.52273 | CP33: 7.01 | CQ33: 10.41 | CR33: 9.5 | CS33: 10.64 | CT33: 6.41 | CU33: 4.35 | CV33: 10.03 | CW33: 10.03 | CX33: 11.39 | CY33: 5.36
A34: =A33+1 -> 1988 | B34: 32143 | C34: 23946700000 | D34: 4522770000 | E34: 154084300000 | F34: 39623400000 | G34: 146497600000 | H34: 30019010000 | I34: 43405100000 | J34: 8704010000 | K34: 21707670000 | L34: 4.29006e+09 | M34: 19017800000 | N34: 3536540000 | O34: 127498300000 | P34: 27677900000 | Q34: 16327060000 | R34: 111824400000 | S34: 35674400000 | T34: 7117190000 | U34: 2384970000 | V34: 15401880000 | X34: 6.655008 | Y34: -0.195984 | AC34: 47529800000 | AD34: 414690000000 | AH34: 15393460000 | AI34: 6.53679e+10 | AM34: 14430090000 | AN34: 132652400000 | AR34: 9507400000 | AS34: 154134700000 | AW34: 13996480000 | AX34: 698773000 | BB34: 42829600000 | BC34: 436808000000 | BG34: 18082710000 | BH34: 187141100000 | BL34: 2552146000 | BM34: 1.665892e+10 | BQ34: 141224200000 | BR34: 12431190000 | BV34: 1434830000 | BW34: 20440970000 | CA34: 16.5129 | CC34: 87.2344 | CE34: 1.18248 | CG34: 6360000000 | CL34: 10.009229 | CP34: 6.86 | CQ34: 10.56 | CR34: 9.08 | CS34: 10.9 | CT34: 6.42 | CU34: 4.59 | CV34: 9.97 | CW34: 9.97 | CX34: 11.29 | CY34: 4.82
A35: =A34+1 -> 1989 | B35: 32509 | C35: 25941800000 | D35: 4849990000 | E35: 171291100000 | F35: 42625900000 | G35: 163631700000 | H35: 3.291389e+10 | I35: 45388600000 | J35: 8863610000 | K35: 28751690000 | L35: 4289020000 | M35: 20402500000 | N35: 3734630000 | O35: 136981800000 | P35: 29440200000 | Q35: 18322160000 | R35: 124906800000 | S35: 37901700000 | T35: 7473280000 | U35: 2809830000 | V35: 18464080000 | X35: 8.141413 | Y35: 0.676015 | AC35: 55268900000 | AD35: 444100000000 | AH35: 17697420000 | AI35: 70914500000 | AM35: 1.667394e+10 | AN35: 138987200000 | AR35: 11244370000 | AS35: 168059400000 | AW35: 14152270000 | AX35: 785545000 | BB35: 47990000000 | BC35: 460696000000 | BG35: 20984370000 | BH35: 196830900000 | BL35: 2821163000 | BM35: 1.629743e+10 | BQ35: 149741000000 | BR35: 14191420000 | BV35: 1515698000 | BW35: 22839380000 | CA35: 14.2457 | CC35: 89.5424 | CE35: 1.10175 | CG35: 6850000000 | CL35: 9.512523 | CP35: 7.15 | CQ35: 12.09 | CR35: 8.79 | CS35: 12.79 | CT35: 7.21 | CU35: 7.46 | CV35: 12.56 | CW35: 12.56 | CX35: 12.68 | CY35: 7.39
... A40: =A39+1 -> 1994 | B40: 34335 | C40: 38255100000 | D40: 7220180000 | E40: 182767800000 | F40: 52581200000 | G40: 155967700000 | H40: 24839320000 | I40: 54017700000 | J40: 12209310000 | K40: 12618940000 | L40: 3638070000 | M40: 29954400000 | N40: 5317520000 | O40: 179243300000 | P40: 39331600000 | Q40: 22046710000 | R40: 143375800000 | S40: 52047800000 | T40: 9921270000 | U40: 2908150000 | V40: 1.693218e+10 | X40: -2.36484 | Y40: -2.115587 | AC40: 48889100000 | AD40: 578490000000 | AH40: 14548420000 | AI40: 94245800000 | AM40: 12372110000 | AN40: 181072700000 | AR40: 13170220000 | AS40: 214627800000 | AW40: 19864200000 | AX40: 206490000 | BB40: 54451900000 | BC40: 642249000000 | BG40: 19426380000 | BH40: 272609100000 | BL40: 2557594000 | BM40: 17867220000 | BQ40: 208518300000 | BR40: 20026650000 | BV40: 3503607000 | BW40: 39030850000 | CA40: 56.198 | CC40: 116.6175 | CE40: 1.18952 | CG40: 3700000000 | CL40: 7.861391 | CP40: 7.03 | CQ40: 9.04 | CR40: 7.22 | CS40: 10.52 | CT40: 6.86 | CU40: 5.04 | CV40: 5.34 | CW40: 5.34 | CX40: 8.45 | CY40: 5.18
A41: =A40+1 -> 1995 | B41: 34700 | C41: 39947500000 | D41: 7211090000 | E41: 184381600000 | F41: 56574300000 | G41: 156057300000 | H41: 22847390000 | I41: 59346300000 | J41: 13099990000 | K41: 15985680000 | L41: 3802690000 | M41: 31688000000 | N41: 5756000000 | O41: 183772500000 | P41: 44897600000 | Q41: 20982150000 | R41: 137322800000 | S41: 55469900000 | T41: 10982270000 | U41: 3340250000 | V41: 18535390000 | W41: -2.152362 | X41: -1.99484 | Y41: -1.652337 | Z41: 3.884118 | AA41: -3.380884 | AB41: 91559100000 | AC41: 56589400000 | AD41: 621602000000 | AE41: 398399000000 | AF41: 159611500000 | AG41: 22029370000 | AH41: 17266790000 | AI41: 98329500000 | AJ41: 124564000000 | AK41: 39345100000 | AL41: 26897520000 | AM41: 13975490000 | AN41: 192183700000 | AO41: 105195300000 | AP41: 36057800000 | AQ41: 27526260000 | AR41: 14463980000 | AS41: 222810400000 | AT41: 111590900000 | AU41: 52204700000 | AV41: 2258084000 | AW41: 20950320000 | AX41: 234348000 | AY41: 14412900000 | AZ41: 4339363000 | BA41: 102891400000 | BB41: 62570000000 | BC41: 683969000000 | BD41: 189840100000 | BE41: 463213000000 | BF41: 36567300000 | BG41: 22378700000 | BH41: 286309400000 | BI41: 157442000000 | BJ41: 77257000000 | BK41: 4726430000 | BL41: 2740313000 | BM41: 18468660000 | BN41: 15778200000 | BO41: 2847410000 | BP41: 36683000000 | BQ41: 216215800000 | BR41: 21864180000 | BS41: 140078600000 | BT41: 50626600000 | BU41: 7379940000 | BV41: 3934969000 | BW41: 42204640000 | BX41: 99785000000 | BY41: 18513430000 | BZ41: 68.5835 | CA41: 55.2045 | CB41: 57.805 | CC41: 119.0877 | CD41: 73.1623 | CE41: 1.30801 | CG41: -1420000000 | CI41: -4820000000 | CL41: 7.415113 | CN41: 10.265051 | CP41: 7.14 | CQ41: 8.79 | CR41: 7.54 | CS41: 12.21 | CT41: 6.9 | CU41: 4.52 | CV41: 5.75 | CW41: 5.75 | CX41: 10.33 | CY41: 4.37
A42: =A41+1 -> 1996 | B42: 35065 | C42: 41408700000 | D42: 6898250000 | E42: 187564000000 | F42: 57601600000 | G42: 176445300000 | H42: 27238800000 | I42: 62337800000 | J42: 14218810000 | K42: 17181720000 | L42: 4.17046e+09 | M42: 3.22582e+10 | N42: 5831840000 | O42: 189175300000 | P42: 46419200000 | Q42: 23355310000 | R42: 156680100000 | S42: 56271700000 | T42: 11100270000 | U42: 3399210000 | V42: 18682390000 | W42: -0.615015 | X42: 0.918835 | Y42: -0.28153 | Z42: 4.422067 | AA42: 3.088908 | AB42: 95557400000 | AC42: 58586400000 | AD42: 656603000000 | AE42: 463342000000 | AF42: 164351600000 | AG42: 24167680000 | AH42: 19144530000 | AI42: 108196100000 | AJ42: 149571300000 | AK42: 41829400000 | AL42: 27895500000 | AM42: 14285450000 | AN42: 205247100000 | AO42: 119370200000 | AP42: 37926100000 | AQ42: 28049650000 | AR42: 14112030000 | AS42: 230756500000 | AT42: 144181400000 | AU42: 51346700000 | AV42: 2385819000 | AW42: 22778870000 | AX42: 228518000 | AY42: 4.13257e+09 | AZ42: 4445053000 | BA42: 104061900000 | BB42: 61857000000 | BC42: 705685000000 | BD42: 171130400000 | BE42: 531778000000 | BF42: 37040100000 | BG42: 22973230000 | BH42: 299086100000 | BI42: 183063800000 | BJ42: 75625600000 | BK42: 4302200000 | BL42: 2013818000 | BM42: 19311280000 | BN42: 17046250000 | BO42: 3330700000 | BP42: 37054400000 | BQ42: 224349500000 | BR42: 21534790000 | BS42: 163832100000 | BT42: 49785400000 | BU42: 7360851000 | BV42: 4.226568e+09 | BW42: 45535520000 | BX42: 114231400000 | BY42: 17763730000 | BZ42: 68.6324 | CA42: 55.3635 | CB42: 60.5935 | CC42: 118.8963 | CD42: 71.3724 | CE42: 1.26975 | CF42: -8570000000 | CG42: -2080000000 | CH42: -8.46e+09 | CI42: 95320000000 | CJ42: -10540000000 | CK42: 5.956544 | CL42: 7.622675 | CM42: 6.424022 | CN42: 9.79748 | CO42: 7.143242 | CP42: 6.32 | CQ42: 7.08 | CR42: 6.31 | CS42: 9.4 | CT42: 6.15 | CU42: 3.34 | CV42: 3.63 | CW42: 3.63 | CX42: 8.69 | CY42: 2.99
A43: =A42+1 -> 1997 | B43: 35431 | C43: 42147100000 | D43: 5592550000 | E43: 188910000000 | F43: 53678700000 | G43: 186828100000 | H43: 29057600000 | I43: 66094100000 | J43: 13684910000 | K43: 19016180000 | L43: 4915820000 | M43: 32596700000 | N43: 4914780000 | O43: 189803900000 | P43: 46784300000 | Q43: 24469080000 | R43: 166272400000 | S43: 56839900000 | T43: 11138110000 | U43: 3570080000 | V43: 19384210000 | W43: 0.987146 | X43: 2.882706 | Y43: -0.160429 | Z43: 6.139121 | AA43: 3.047395 | AB43: 93563700000 | AC43: 61456800000 | AD43: 663418000000 | AE43: 509346000000 | AF43: 165268500000 | AG43: 25389520000 | AH43: 20003990000 | AI43: 116778300000 | AJ43: 166369900000 | AK43: 41335800000 | AL43: 28522830000 | AM43: 1.601027e+10 | AN43: 208371400000 | AO43: 131685000000 | AP43: 39315300000 | AQ43: 28009980000 | AR43: 14265170000 | AS43: 228006900000 | AT43: 154040500000 | AU43: 52491900000 | AV43: 2334354000 | AW43: 23195880000 | AX43: 227490000 | AY43: 3956240000 | AZ43: 4341014000 | BA43: 98465300000 | BB43: 62774200000 | BC43: 710900000000 | BD43: 171169500000 | BE43: 542101000000 | BF43: 37209800000 | BG43: 23838970000 | BH43: 303192300000 | BI43: 194915600000 | BJ43: 76952100000 | BK43: 4048990000 | BL43: 2000905000 | BM43: 18463040000 | BN43: 14864510000 | BO43: 3869530000 | BP43: 36042600000 | BQ43: 228450700000 | BR43: 21377020000 | BS43: 178410200000 | BT43: 47755100000 | BU43: 6746748000 | BV43: 4545764000 | BW43: 45429030000 | BX43: 100226800000 | BY43: 17129810000 | BZ43: 63.9039 | CA43: 52.2354 | CB43: 61.9832 | CC43: 116.4905 | CD43: 65.8091 | CE43: 1.13404 | CF43: -11300000000 | CG43: -1570000000 | CH43: -9770000000 | CI43: -21270000000 | CJ43: -13810000000 | CK43: 5.43994 | CL43: 7.963442 | CM43: 6.06104 | CN43: 8.016659 | CO43: 6.973045 | CP43: 5.68 | CQ43: 5.96 | CR43: 5.58 | CS43: 6.86 | CT43: 5.58 | CU43: 3.51 | CV43: 3.23 | CW43: 3.23 | CX43: 6.78 | CY43: 3.32
A44: =A43+1 -> 1998 | B44: 35796 | C44: 43905800000 | D44: 5711320000 | E44: 204483300000 | F44: 54305200000 | G44: 195869300000 | H44: 31106600000 | I44: 71426000000 | J44: 14055270000 | K44: 21662990000 | L44: 4929510000 | M44: 33807100000 | N44: 5046740000 | O44: 195250000000 | P44: 47695000000 | Q44: 25230960000 | R44: 172660300000 | S44: 59413000000 | T44: 11448140000 | U44: 3725950000 | V44: 20113580000 | W44: 0.842629 | X44: 5.089221 | Y44: 0.994646 | Z44: 4.846061 | AA44: 3.022751 | AB44: 96767400000 | AC44: 6.46163e+10 | AD44: 690119000000 | AE44: 511826000000 | AF44: 172643400000 | AG44: 26662500000 | AH44: 21853810000 | AI44: 150697300000 | AJ44: 155160400000 | AK44: 42760500000 | AL44: 29414720000 | AM44: 1.672256e+10 | AN44: 216594300000 | AO44: 167913900000 | AP44: 42110200000 | AQ44: 28902660000 | AR44: 14972380000 | AS44: 211371900000 | AT44: 1.338993e+11 | AU44: 55734600000 | AV44: 2382172000 | AW44: 23899360000 | AX44: 121250000 | AY44: 3995790000 | AZ44: 4350512000 | BA44: 102108300000 | BB44: 62610700000 | BC44: 722110000000 | BD44: 177877600000 | BE44: 545774000000 | BF44: 38557800000 | BG44: 24597840000 | BH44: 306121800000 | BI44: 199981800000 | BJ44: 81216200000 | BK44: 4656670000 | BL44: 1961864000 | BM44: 18977650000 | BN44: 15304750000 | BO44: 4651330000 | BP44: 36655800000 | BQ44: 234113000000 | BR44: 21104450000 | BS44: 181261100000 | BT44: 48201100000 | BU44: 6975189000 | BV44: 4085726000 | BW44: 45296880000 | BX44: 89044100000 | BY44: 17083350000 | BZ44: 64.3454 | CA44: 46.8434 | CB44: 62.0997 | CC44: 113.8868 | CD44: 62.7788 | CE44: 1.12109 | CF44: 1530000000 | CG44: 960000000 | CH44: 11050000000 | CI44: -6100000000 | CJ44: 1960000000 | CK44: 5.852548 | CL44: 7.105327 | CM44: 5.702653 | CN44: 7.006706 | CO44: 7.073211 | CP44: 4.71 | CQ44: 4.79 | CR44: 4.64 | CS44: 4.88 | CT44: 4.63 | CU44: 3.58 | CV44: 3.57 | CW44: 3.57 | CX44: 4.91 | CY44: 3.42
...

Sheet Sheet3
B4: France, DG ECFIN AMECO, General Government, Expenditure(ESA2010), Total Expenditure, Estimate, EUR
A5: 28491 | B5: 180064000000
A6: 28856 | B6: 203739000000
A7: 29221 | B7: 234311000000
A8: 29587 | B8: 271156000000
A9: 29952 | B9: 300263000000
A10: 30317 | B10: 319801000000
A11: 30682 | B11: 348755000000
A12: 31048 | B12: 382625000000
A13: 31413 | B13: 407853000000
A14: 31778 | B14: 415853000000
A15: 32143 | B15: 436808000000
A16: 32509 | B16: 460696000000
... A53: 46023 | B53: 1771500000000

Sheet Sheet2
B2: {=TRANSPOSE(Sheet1!C2:CY2)} -> Capital Formation & Saving, Gross Fixed Capital Formation, Private Sector, Current Prices, EUR | D2: {=_xlfn.UNIQUE(_xlfn.ANCHORARRAY(B2))} -> Capital Formation & Saving, Gross Fixed Capital Formation, Private Sector, Current Prices, EUR | E2: I_M_NOM
B3: Capital Formation & Saving, Gross Fixed Capital Formation, General Government, Current Prices, EUR | D3: Capital Formation & Saving, Gross Fixed Capital Formation, General Government, Current Prices, EUR | E3: I_G
B4: Capital Formation & Saving, Gross Fixed Capital Formation, Private Sector, Current Prices, EUR | D4: Capital Formation & Saving, Consumption of Fixed Capital, Total, Current Prices, EUR | E4: DEPR_TOTAL_NOM
B5: Capital Formation & Saving, Gross Fixed Capital Formation, General Government, Current Prices, EUR | D5: Capital Formation & Saving, Consumption of Fixed Capital, General Government, Current Prices, EUR | E5: DEPR_G_NOM
B6: Capital Formation & Saving, Gross Fixed Capital Formation, Private Sector, Current Prices, EUR | D6: General Government, Net Lending(ESA2010), Net Lending (+) or Net Borrowing (-) Excluding Interest, Percent of GDP (Excessive Deficit Procedure), Market Prices | E6: PB_RATIO
B7: Capital Formation & Saving, Gross Fixed Capital Formation, General Government, Current Prices, EUR | D7: General Government, Revenue(ESA2010), Total Revenue, EUR | E7: GR
B8: Capital Formation & Saving, Gross Fixed Capital Formation, Private Sector, Current Prices, EUR | D8: General Government, Revenue(ESA2010), Current Taxes on Income & Wealth, Direct Taxes, EUR | E8: taxes_income_wealth
B9: Capital Formation & Saving, Gross Fixed Capital Formation, General Government, Current Prices, EUR | D9: General Government, Revenue(ESA2010), Taxes Linked to Imports & Production, Indirect Taxes, EUR | E9: T_C
B10: Capital Formation & Saving, Gross Fixed Capital Formation, Private Sector, Current Prices, EUR | D10: General Government, Revenue(ESA2010), Actual Social Contributions Received, EUR | E10: SC_actual
B11: Capital Formation & Saving, Gross Fixed Capital Formation, General Government, Current Prices, EUR | D11: General Government, Revenue(ESA2010), Imputed Social Contributions, EUR | E11: SC_IMP
B12: Capital Formation & Saving, Consumption of Fixed Capital, Total, Current Prices, EUR | D12: General Government, Expenditure(ESA2010), Total Expenditure, EUR | E12: GE
B13: Capital Formation & Saving, Consumption of Fixed Capital, General Government, Current Prices, EUR | D13: General Government, Expenditure(ESA2010), Final Consumption Expenditure, EUR | E13: G
B14: Capital Formation & Saving, Consumption of Fixed Capital, Total, Current Prices, EUR | D14: General Government, Expenditure(ESA2010), Subsidies, EUR | E14: SUB
... B22: General Government, Net Lending(ESA2010), Net Lending (+) or Net Borrowing (-) Excluding Interest, Percent of GDP (Excessive Deficit Procedure), Market Prices | D22: Monetary Variables, Interest Rates, Nominal, Short-Term, Current Prices | E22: I_RATE
B23: General Government, Net Lending(ESA2010), Net Lending (+) or Net Borrowing (-) Excluding Interest, Percent of GDP (Excessive Deficit Procedure), Market Prices
B24: General Government, Net Lending(ESA2010), Net Lending (+) or Net Borrowing (-) Excluding Interest, Percent of GDP (Excessive Deficit Procedure), Market Prices
B25: General Government, Net Lending(ESA2010), Net Lending (+) or Net Borrowing (-) Excluding Interest, Percent of GDP (Excessive Deficit Procedure), Market Prices
B26: General Government, Net Lending(ESA2010), Net Lending (+) or Net Borrowing (-) Excluding Interest, Percent of GDP (Excessive Deficit Procedure), Market Prices
B27: General Government, Revenue(ESA2010), Total Revenue, EUR
B28: General Government, Revenue(ESA2010), Total Revenue, EUR
B29: General Government, Revenue(ESA2010), Total Revenue, EUR
B30: General Government, Revenue(ESA2010), Total Revenue, EUR
B31: General Government, Revenue(ESA2010), Total Revenue, EUR
B32: General Government, Revenue(ESA2010), Current Taxes on Income & Wealth, Direct Taxes, EUR
B33: General Government, Revenue(ESA2010), Current Taxes on Income & Wealth, Direct Taxes, EUR
B34: General Government, Revenue(ESA2010), Current Taxes on Income & Wealth, Direct Taxes, EUR
... B102: Monetary Variables, Interest Rates, Nominal, Short-Term, Current Prices
