Workbook

Sheet Sources
A1: Block | B1: Decription | C1: Variable / Parameter | D1: In Model? | E1: Source | F1: Notes | G1: Link
A2: Supply | B2: potential output, real | C2: Y_STAR | D2: 1 | E2: EUCAM | G2: https://circabc.europa.eu/ui/group/671d465b-0752-4a2e-906c-a3effd2340ba/library/b9482682-d5a0-47a1-9281-bc7d8a214629
B3: log TFP | C3: SR | D3: 0 | E3: calculated
B4: log trend TFP | C4: SR_TREND | D4: 1 | E4: estimated | F4: UCM, bayesian Kalman filter
B5: log trend TFP growth | C5: SR_SLOPE | D5: 1 | E5: estimated | F5: UCM, bayesian Kalman filter
B6: inertia / persistence in TFP growth | C6: RHO_SR | D6: 1 | E6: estimated | F6: UCM, bayesian Kalman filter
B7: long-term TFP growth | C7: OMEGA_SR | D7: 1 | E7: estimated | F7: UCM, bayesian Kalman filter
B8: capacity utilisation indicator | C8: CUBS | D8: 0 | E8: EUCAM | F8: relevant for TFP trend estimation | G8: https://circabc.europa.eu/ui/group/671d465b-0752-4a2e-906c-a3effd2340ba/library/b9482682-d5a0-47a1-9281-bc7d8a214626
B9: working age population EUCAM | C9: WP_EUCAM | D9: 0 | E9: EUCAM | G9: https://circabc.europa.eu/ui/group/671d465b-0752-4a2e-906c-a3effd2340ba/library/b9482682-d5a0-47a1-9281-bc7d8a214627
B10: working age population EU projections | C10: WP_PROJ | D10: 0 | E10: EUCAM | G10: https://circabc.europa.eu/ui/group/671d465b-0752-4a2e-906c-a3effd2340ba/library/b9482682-d5a0-47a1-9281-bc7d8a214628
B11: working age population (merged) | C11: WP | D11: 1 | E11: calculated | F11: starting 2029 forecasted based on EU projections | G11: https://circabc.europa.eu/ui/group/671d465b-0752-4a2e-906c-a3effd2340ba/library/b9482682-d5a0-47a1-9281-bc7d8a214629
B12: labour force participation rate | C12: LP | D12: 0 | E12: EUCAM | G12: https://circabc.europa.eu/ui/group/671d465b-0752-4a2e-906c-a3effd2340ba/library/b9482682-d5a0-47a1-9281-bc7d8a214630
B13: trend labour force participation rate | C13: LP_TREND | D13: 1 | E13: estimated | F13: UCM, MLE Kalman filter
B14: trend labour force participation rate growth | C14: LP_SLOPE | D14: 1 | E14: estimated | F14: UCM, MLE Kalman filter
B15: trend labour force participation rate; EUCAM values | C15: LP_TREND_EUCAM | D15: 0 | E15: EUCAM | G15: https://circabc.europa.eu/ui/group/671d465b-0752-4a2e-906c-a3effd2340ba/library/b9482682-d5a0-47a1-9281-bc7d8a214631
B16: AWG participation rate projections | C16: LP_AWG | D16: 1 | E16: AWG EU projections
B17: unemployment rate | C17: U | D17: 0 | E17: EUCAM | G17: https://circabc.europa.eu/ui/group/671d465b-0752-4a2e-906c-a3effd2340ba/library/b9482682-d5a0-47a1-9281-bc7d8a214632
B18: trend unemployment rate (NAWRU) | C18: U_TREND | D18: 1 | E18: estimated | F18: UCM, MLE Kalman filter
B19: trend unemployment rate growth | C19: U_SLOPE | D19: 1 | E19: estimated | F19: UCM, MLE Kalman filter
B20: NAWRU; EUCAM values | C20: U_TREND_EUCAM | D20: 0 | E20: EUCAM | G20: https://circabc.europa.eu/ui/group/671d465b-0752-4a2e-906c-a3effd2340ba/library/b9482682-d5a0-47a1-9281-bc7d8a214633
B21: Anchored NAWRU EUCAM estimates | C21: STRUCT_U_EUCAM | D21: 0 | E21: EUCAM
B22: productivity indicator? | C22: dlprod | D22: 0 | E22: EUCAM | F22: relevant for Germany NAWRU estimation | G22: https://circabc.europa.eu/ui/group/671d465b-0752-4a2e-906c-a3effd2340ba/library/b9482682-d5a0-47a1-9281-bc7d8a214634
B23: Terms of trade indicator? | C23: dpcegdp | D23: 0 | E23: EUCAM | F23: relevant for Germany NAWRU estimation | G23: https://circabc.europa.eu/ui/group/671d465b-0752-4a2e-906c-a3effd2340ba/library/b9482682-d5a0-47a1-9281-bc7d8a214635
B24: wage level/inflation indicator? | C24: endo_dwinf | D24: 0 | E24: EUCAM | F24: relevant for Germany NAWRU estimation | G24: https://circabc.europa.eu/ui/group/671d465b-0752-4a2e-906c-a3effd2340ba/library/b9482682-d5a0-47a1-9281-bc7d8a214636
B25: average hours worked | C25: H | D25: 0 | E25: EUCAM | F25: relevant for Germany NAWRU estimation | G25: https://circabc.europa.eu/ui/group/671d465b-0752-4a2e-906c-a3effd2340ba/library/b9482682-d5a0-47a1-9281-bc7d8a214634
B26: trend average hours worked | C26: H_TREND | D26: 1 | E26: estimated | F26: UCM, MLE Kalman filter
B27: trend average hours worked growth | C27: H_SLOPE | D27: 1 | E27: estimated | F27: UCM, MLE Kalman filter
B28: trend average hours worked; EUCAM values | C28: H_TREND_EUCAM | D28: 0 | E28: EUCAM | G28: https://circabc.europa.eu/ui/group/671d465b-0752-4a2e-906c-a3effd2340ba/library/b9482682-d5a0-47a1-9281-bc7d8a214635
B29: capital stock (total) | C29: K | D29: 0 | E29: EUCAM | G29: https://circabc.europa.eu/ui/group/671d465b-0752-4a2e-906c-a3effd2340ba/library/b9482682-d5a0-47a1-9281-bc7d8a214636
B30: total capital stock Eurostat | C30: K_EUROSTAT | D30: 0 | E30: Eurostat | G30: Saskia Link
B31: public capital stock eurostat | C31: K_G_EUROSTAT | D31: 0 | E31: Eurostat | G31: Saskia Link
B32: eurostat private/public capital split | C32: K_SPLIT | D32: 0 | E32: calculated | F32: K_G_EUROSTAT/K_EUROSTAT | G32: https://ec.europa.eu/eurostat/databrowser/view/nama_10_nfa_bs/default/table?lang=en
B33: public capital stock, real | C33: K_G | D33: 1 | E33: calculated (based on Eurostat, AMECO) | F33: initial values based on Eurostat private/public split; then calculated based on AMECO investment and depreciation data | G33: Macrobond, https://ec.europa.eu/eurostat/databrowser/view/nama_10_nfa_bs/default/table?lang=en
B34: public investment, real | C34: I_G_REAL | D34: 1 | E34: calculated (based on AMECO) | F34: nominal expenditure and GDP deflator
B35: public capital depreciation, nominal | C35: DEPR_G_NOM | D35: 0 | E35: AMECO | F35: AMECO Capital Formation & Saving, Consumption of Fixes Capital, General Government, Current Prices, EUR | G35: Macrobond
B36: public capital depreciation, real | C36: DEPR_G | D36: 0 | E36: calculated (based on AMECO) | F36: DEPR_G_NOM / P
B37: public capital depreciation rate | C37: DEPR_G_RATIO | D37: 1 | E37: calculated (based on AMECO) | F37: DEPR_G / K_G; projected based on historical average
B38: public capital depreciation rate | C38: DELTA_G | D38: 1 | E38: calibrated / calculated | F38: Historical average of DEPR_G_RATIO
B39: private capital stock, real | C39: K_M | D39: 1 | E39: calculated (based on Eurostat, AMECO) | F39: initial values based on Eurostat private/public split; then calculated based on AMECO investment and depreciation data | G39: Macrobond, https://ec.europa.eu/eurostat/databrowser/view/nama_10_nfa_bs/default/table?lang=en
B40: private investment, nominal | C40: I_M_NOM | D40: 0 | E40: AMECO | F40: AMECO Capital Formation & Saving, Gross Fixed Capital Formation, Private Sector, Current Prices, EUR | G40: Macrobond
...

Sheet Python Calculations
A1: Block | B1: Decription | C1: Variable / Parameter | D1: Calculation
A2: Supply | B2: log trend potential output, real | C2: Y_TREND | D2: log(Y_STAR)
B3: potential output, nominal | C3: Y_STAR_NOM | D3: Y_STAR * P
B4: PO growth, real | C4: G_Y_STAR | D4: (Y_STAR - Y_STAR(-1))/Y_STAR(-1) * 100
B5: pulbic investment lags | C5: THETA_KG_x | D5: add all thetas
B6: AWG participation rate growth | C6: LP_SLOPE_AWG | D6: LP_AWG(+1) - LP_AWG
A7: Demand | B7: log demand, real | C7: Y_D_LOG | D7: log(Y_D)
B8: GDP growth, real | C8: G_Y_D | D8: (Y_D - Y_D(-1))/Y_D * 100
B9: output gap closure mechanism | C9: BETA_D | D9: = 0
A10: Prices | B10: nominal potential output growth | C10: G_Y_STAR_NOM | D10: (Y_STAR_NOM - Y_STAR_NOM(-1)) / Y_STAR_NOM(-1) * 100
B11: nominal GDP growth | C11: G_Y_D_NOM | D11: (Y_D_NOM - Y_D_NOM(-1)) / Y_D_NOM(-1) * 100
A12: Financial | B12: short-term interest rate | C12: I_ST | D12: = I_RATE
B13: share of country GDP in euro area gdp | C13: OMEGA_DE | D13: Y_D / GDP_EA; kept constant
B14: neutral interest rate | C14: I_STAR | D14: kept constant; (I_RATE - THETA_I * I_RATE(-1)) / (1 - THETA_I) - OMEGA_DE * (SIGMA_I_1 * (PI - PI_T) + SIGMA_I_2 * Y_GAP) - (1 - OMEGA_DE) * (SIGMA_I_1 * (PI_EA - PI_T) + SIGMA_I_2 * Y_GAP_EA)
B15: term premium on long-term interest rate | C15: TERM | D15: I_LT - I_ST
B16: historical average / long-term term premium | C16: TERM_STAR | D16: average of term between 1999 and 2014
B17: risk premium | C17: RISK | D17: PHI_RISK * D_RATIO(-1) / D_RATIO_STAR
B18: short-term real interest rate | C18: R_ST | D18: I_ST - PI
B19: long-term real interest rate | C19: R_LT | D19: I_LT - PI
A20: Fiscal | B20: share of short term debt | C20: ALPHA_ST | D20: D_ST / D
B21: implicit long-term interest rate | C21: IIR_LT | D21: (IIR - ALPHA_ST(-1) * I_ST) / (1 - ALPHA_ST(-1))
B22: parameter: share of new debt issued as short-term debt | C22: D_SHARE_ST | D22: 3 year historical average of ALPHA_ST
B23: repayments, short-term | C23: REP_ST | D23: = D_ST(-1)
B24: repayments, long-term | C24: REP_LT | D24: D_residual_maturity_ST(-1) - D_ST(-1)
B25: repayments | C25: REP | D25: REP_ST + REP_LT
B26: new short-term debt | C26: D_STN | D26: = D_ST
B27: new long-term debt | C27: D_LTN | D27: D_LT - D_LT(-1) + REP_LT
B28: share of new debt in long-term debt | C28: BETA_LT | D28: D_LTN / D_LT
B29: parameter: long-term debt maturing share | C29: PHI_LT | D29: converges over 10 years from BETA_LT to 6 year historical average of BETA_LT
B30: gross financing needs | C30: GFN | D30: INT + REP - PB + SF
B31: parameter: share of stock flow adjustments | C31: SF_RATIO | D31: SF / GDP nominal * 100, 0 after 2025

Sheet Austria
A1: YEAR | B1: Y_STAR | C1: SR | D1: SR_TREND | E1: SR_SLOPE | F1: RHO_SR | G1: OMEGA_SR | H1: CUBS | I1: WP_EUCAM | J1: WP_PROJ | K1: WP | L1: LP | M1: LP_TREND | N1: LP_SLOPE | O1: LP_TREND_EUCAM | P1: LP_AWG_GROWTH_EUCAM | Q1: LP_AWG | R1: U | S1: U_TREND | T1: U_SLOPE | U1: U_TREND_EUCAM | V1: STRUCT_U_EUCAM | W1: dlprod | X1: dpcegdp | Y1: endo_dwinf | Z1: H | AA1: H_TREND | AB1: H_SLOPE | AC1: H_TREND_EUCAM | AD1: K | AE1: K_EUROSTAT | AF1: K_G_EUROSTAT | AG1: K_SPLIT | AH1: K_G | AI1: I_G_REAL | AJ1: DEPR_G_NOM | AK1: DEPR_G | AL1: DEPR_G_RATIO | AM1: DELTA_G | AN1: K_M | AO1: I_M_NOM | AP1: I_M | AQ1: DEPR_TOTAL_NOM | AR1: DEPR_M | AS1: DELTA_M | AT1: IQ_M | AU1: PHI_IQ_M_0 | AV1: PHI_IQ_M_1 | AW1: PHI_IQ_M_2 | AX1: LAMBDA_IQ_M_1 | AY1: LAMBDA_IQ_M_2 | AZ1: LAMBDA_IQ_M_3 | BA1: LAMBDA_IQ_M_4 | BB1: Y_D | BC1: Y_D_NOM | BD1: Y_GAP | BE1: BETA_D | BF1: LAMBDA_R | BG1: LAMBDA_I_G | BH1: LAMBDA_G | BI1: LAMBDA_S | BJ1: LAMBDA_TR | BK1: LAMBDA_T_HH | BL1: LAMBDA_T_F | BM1: LAMBDA_T_C | BN1: PB | BO1: PB_RATIO | BP1: GR | BQ1: taxes_income_wealth | BR1: T_HH_ECB | BS1: T_non-finan_corp | BT1: T_finan_corp | BU1: T_HH | BV1: T_F | BW1: T_C | BX1: SC_actual | BY1: SC_HH_ECB | BZ1: SC_F_ECB | CA1: SC_HH | CB1: SC_F | CC1: SC_IMP | CD1: NonT | CE1: GE | CF1: PE | CG1: G | CH1: I_G | CI1: SUB | CJ1: TR | CK1: INT | CL1: OTHER_PE | CM1: TAU_HH_STAR | CN1: TAU_F_STAR | CO1: TAU_C_STAR | CP1: TAU_SC_HH_STAR | CQ1: TAU_SC_F_STAR | CR1: TAU_SC_IMP_STAR | CS1: TAU_NON_T_STAR | CT1: S_G_STAR | CU1: S_IG_STAR | CV1: S_SUB_STAR | CW1: S_TR_STAR | CX1: S_OTHER_PE_STAR | CY1: ALPHA_HH | CZ1: ALPHA_F | DA1: ALPHA_C | DB1: ALPHA_SC_HH | DC1: ALPHA_SC_F | DD1: ALPHA_SC_IMP | DE1: ALPHA_NON_T | DF1: ALPHA_G | DG1: ALPHA_IG | DH1: ALPHA_SUB | DI1: ALPHA_TR | DJ1: ALPHA_OTHER_PE | DK1: D | DL1: D_RATIO | DM1: D_ST | DN1: D_LT | DO1: ALPHA_EUR | DP1: ALPHA_USD | DQ1: EXR_USD | DR1: SF | DS1: IIR | DT1: D_residual_maturity_ST | DU1: I_RATE | DV1: THETA_I | DW1: GDP_EA | DX1: SIGMA_I_1 | DY1: SIGMA_I_2 | DZ1: I_LT | EA1: PI_T | EB1: P_EA | EC1: PI_EA | ED1: Y_GAP_EA | EE1: I_LB | EF1: I_ST_10F | EG1: I_LT_10F | EH1: THETA_TERM | EI1: PHI_RISK | EJ1: D_RATIO_STAR | EK1: PI | EL1: BETA_PI_1 | EM1: BETA_PI_2 | EN1: P
A2: 1962 | W2: 0.020145346 | X2: 0.04762852 | AJ2: 248100000 | AM2: =AVERAGE($AL$35:$AL$63) -> 0.065166448 | AO2: 1619400000 | AQ2: 1002100000 | CH2: {=INDEX([1]Sheet1!$C$6:$CY$72,MATCH($A2,[1]Sheet1!$A$6:$A$72,0),MATCH(MID(CELL("filename",O1),FIND("]",CELL("filename",O1))+1,255) & CH$1,[1]Sheet1!$C$1:$CY$1 & [1]Sheet1!$C$3:$CY$3,0))} -> 418620000 | DQ2: 1.06981 | DR2: {=INDEX([1]Sheet1!$C$6:$CY$72,MATCH($A2,[1]Sheet1!$A$6:$A$72,0),MATCH(MID(CELL("filename",AZ1),FIND("]",CELL("filename",AZ1))+1,255) & DR$1,[1]Sheet1!$C$1:$CY$1 & [1]Sheet1!$C$3:$CY$3,0))} -> 0 | DS2: {=INDEX([1]Sheet1!$C$6:$CY$72,MATCH($A2,[1]Sheet1!$A$6:$A$72,0),MATCH(MID(CELL("filename",BA1),FIND("]",CELL("filename",BA1))+1,255) & DS$1,[1]Sheet1!$C$1:$CY$1 & [1]Sheet1!$C$3:$CY$3,0))} -> 0 | DU2: {=INDEX([1]Sheet1!$C$6:$CY$72,MATCH($A2,[1]Sheet1!$A$6:$A$72,0),MATCH(MID(CELL("filename",BC1),FIND("]",CELL("filename",BC1))+1,255) & DU$1,[1]Sheet1!$C$1:$CY$1 & [1]Sheet1!$C$3:$CY$3,0))} -> 0 | DV2: 0.5 | DX2: 1 | DY2: 0.5 | DZ2: {=INDEX([1]Sheet1!$C$6:$CY$72,MATCH($A2,[1]Sheet1!$A$6:$A$72,0),MATCH(MID(CELL("filename",BH1),FIND("]",CELL("filename",BH1))+1,255) & DZ$1,[1]Sheet1!$C$1:$CY$1 & [1]Sheet1!$C$3:$CY$3,0))} -> 0 | EA2: 2 | EH2: 0.75 | EI2: 0.05 | EJ2: 75
A3: 1963 | W3: 0.046661457 | X3: 0.038727325 | AJ3: 268220000 | AM3: =AVERAGE($AL$35:$AL$63) -> 0.065166448 | AO3: 1758600000 | AQ3: 1088700000 | CH3: {=INDEX([1]Sheet1!$C$6:$CY$72,MATCH($A3,[1]Sheet1!$A$6:$A$72,0),MATCH(MID(CELL("filename",O2),FIND("]",CELL("filename",O2))+1,255) & CH$1,[1]Sheet1!$C$1:$CY$1 & [1]Sheet1!$C$3:$CY$3,0))} -> 458510000 | DQ3: 1.06981 | DR3: {=INDEX([1]Sheet1!$C$6:$CY$72,MATCH($A3,[1]Sheet1!$A$6:$A$72,0),MATCH(MID(CELL("filename",AZ2),FIND("]",CELL("filename",AZ2))+1,255) & DR$1,[1]Sheet1!$C$1:$CY$1 & [1]Sheet1!$C$3:$CY$3,0))} -> 0 | DS3: {=INDEX([1]Sheet1!$C$6:$CY$72,MATCH($A3,[1]Sheet1!$A$6:$A$72,0),MATCH(MID(CELL("filename",BA2),FIND("]",CELL("filename",BA2))+1,255) & DS$1,[1]Sheet1!$C$1:$CY$1 & [1]Sheet1!$C$3:$CY$3,0))} -> 0 | DU3: {=INDEX([1]Sheet1!$C$6:$CY$72,MATCH($A3,[1]Sheet1!$A$6:$A$72,0),MATCH(MID(CELL("filename",BC2),FIND("]",CELL("filename",BC2))+1,255) & DU$1,[1]Sheet1!$C$1:$CY$1 & [1]Sheet1!$C$3:$CY$3,0))} -> 0 | DV3: 0.5 | DX3: 1 | DY3: 0.5 | DZ3: {=INDEX([1]Sheet1!$C$6:$CY$72,MATCH($A3,[1]Sheet1!$A$6:$A$72,0),MATCH(MID(CELL("filename",BH2),FIND("]",CELL("filename",BH2))+1,255) & DZ$1,[1]Sheet1!$C$1:$CY$1 & [1]Sheet1!$C$3:$CY$3,0))} -> 0 | EA3: 2 | EH3: 0.75 | EI3: 0.05 | EJ3: 75
A4: 1964 | W4: 0.061708767 | X4: 0.04327294 | AJ4: 283310000 | AM4: =AVERAGE($AL$35:$AL$63) -> 0.065166448 | AO4: 1938300000 | AQ4: 1181000000 | CH4: {=INDEX([1]Sheet1!$C$6:$CY$72,MATCH($A4,[1]Sheet1!$A$6:$A$72,0),MATCH(MID(CELL("filename",O3),FIND("]",CELL("filename",O3))+1,255) & CH$1,[1]Sheet1!$C$1:$CY$1 & [1]Sheet1!$C$3:$CY$3,0))} -> 5.3072e+08 | DQ4: 1.06981 | DR4: {=INDEX([1]Sheet1!$C$6:$CY$72,MATCH($A4,[1]Sheet1!$A$6:$A$72,0),MATCH(MID(CELL("filename",AZ3),FIND("]",CELL("filename",AZ3))+1,255) & DR$1,[1]Sheet1!$C$1:$CY$1 & [1]Sheet1!$C$3:$CY$3,0))} -> 0 | DS4: {=INDEX([1]Sheet1!$C$6:$CY$72,MATCH($A4,[1]Sheet1!$A$6:$A$72,0),MATCH(MID(CELL("filename",BA3),FIND("]",CELL("filename",BA3))+1,255) & DS$1,[1]Sheet1!$C$1:$CY$1 & [1]Sheet1!$C$3:$CY$3,0))} -> 0 | DU4: {=INDEX([1]Sheet1!$C$6:$CY$72,MATCH($A4,[1]Sheet1!$A$6:$A$72,0),MATCH(MID(CELL("filename",BC3),FIND("]",CELL("filename",BC3))+1,255) & DU$1,[1]Sheet1!$C$1:$CY$1 & [1]Sheet1!$C$3:$CY$3,0))} -> 0 | DV4: 0.5 | DX4: 1 | DY4: 0.5 | DZ4: {=INDEX([1]Sheet1!$C$6:$CY$72,MATCH($A4,[1]Sheet1!$A$6:$A$72,0),MATCH(MID(CELL("filename",BH3),FIND("]",CELL("filename",BH3))+1,255) & DZ$1,[1]Sheet1!$C$1:$CY$1 & [1]Sheet1!$C$3:$CY$3,0))} -> 0 | EA4: 2 | EH4: 0.75 | EI4: 0.05 | EJ4: 75
A5: 1965 | B5: =[2]EUCAM_output!$E2*10^9 -> 1.0364351e+11 | I5: =[2]EUCAM_output!$W2*10^3 -> 5250163 | K5: =IF(A5<2030,I5,K4*J5/J4) -> 5250163 | L5: =[2]EUCAM_output!$G2 -> 65.05291 | O5: =[2]EUCAM_output!$H2 -> 64.545558 | R5: =[2]EUCAM_output!$L2 -> 1.6 | U5: =[2]EUCAM_output!$K2 -> 1.3885506 | V5: 1.3885506 | W5: 0.035075862 | X5: 0.031476534 | Y5: =[2]EUCAM_output!$AI2 -> -0.0017574738 | Z5: =[2]EUCAM_output!$M2 -> 2005.2571 | AC5: =[2]EUCAM_output!$AL2 -> 2009.1425 | AD5: =[2]EUCAM_output!$T2*10^9 -> 2.992678e+11 | AJ5: 316840000 | AM5: =AVERAGE($AL$35:$AL$63) -> 0.065166448 | AO5: 2187000000 | AP5: =AO5/EN5 -> 2.3766215e+10 | AQ5: 1307400000 | AR5: =(AQ5-AJ5)/EN5 -> 1.0764455e+10 | BB5: 1.0200195e+11 | BC5: =[2]EUCAM_output!$AG2*10^9 -> 1.897354e+10 | BD5: =(BB5-B5)/B5*100 -> -1.5838576 | CH5: {=INDEX([1]Sheet1!$C$6:$CY$72,MATCH($A5,[1]Sheet1!$A$6:$A$72,0),MATCH(MID(CELL("filename",O4),FIND("]",CELL("filename",O4))+1,255) & CH$1,[1]Sheet1!$C$1:$CY$1 & [1]Sheet1!$C$3:$CY$3,0))} -> 588290000 | DQ5: 1.06981 | DR5: {=INDEX([1]Sheet1!$C$6:$CY$72,MATCH($A5,[1]Sheet1!$A$6:$A$72,0),MATCH(MID(CELL("filename",AZ4),FIND("]",CELL("filename",AZ4))+1,255) & DR$1,[1]Sheet1!$C$1:$CY$1 & [1]Sheet1!$C$3:$CY$3,0))} -> 0 | DS5: {=INDEX([1]Sheet1!$C$6:$CY$72,MATCH($A5,[1]Sheet1!$A$6:$A$72,0),MATCH(MID(CELL("filename",BA4),FIND("]",CELL("filename",BA4))+1,255) & DS$1,[1]Sheet1!$C$1:$CY$1 & [1]Sheet1!$C$3:$CY$3,0))} -> 0 | DU5: {=INDEX([1]Sheet1!$C$6:$CY$72,MATCH($A5,[1]Sheet1!$A$6:$A$72,0),MATCH(MID(CELL("filename",BC4),FIND("]",CELL("filename",BC4))+1,255) & DU$1,[1]Sheet1!$C$1:$CY$1 & [1]Sheet1!$C$3:$CY$3,0))} -> 0 | DV5: 0.5 | DW5: =Euro_Area_Data!V2*10^9 -> #N/A | DX5: 1 | DY5: 0.5 | DZ5: {=INDEX([1]Sheet1!$C$6:$CY$72,MATCH($A5,[1]Sheet1!$A$6:$A$72,0),MATCH(MID(CELL("filename",BH4),FIND("]",CELL("filename",BH4))+1,255) & DZ$1,[1]Sheet1!$C$1:$CY$1 & [1]Sheet1!$C$3:$CY$3,0))} -> 6.51 | EA5: 2 | EE5: -5 | EH5: 0.75 | EI5: 0.05 | EJ5: 75 | EN5: =[2]EUCAM_output!$AE2 -> 0.092021383
A6: 1966 | B6: =[2]EUCAM_output!$E3*10^9 -> 1.0826854e+11 | I6: =[2]EUCAM_output!$W3*10^3 -> 5265008.5 | K6: =IF(A6<2030,I6,K5*J6/J5) -> 5265008.5 | L6: =[2]EUCAM_output!$G3 -> 64.169299 | O6: =[2]EUCAM_output!$H3 -> 63.820409 | R6: =[2]EUCAM_output!$L3 -> 1.5 | U6: =[2]EUCAM_output!$K3 -> 1.3347745 | V6: 1.3347745 | W6: 0.066872852 | X6: 0.023475123 | Y6: =[2]EUCAM_output!$AI3 -> 0.0019316627 | Z6: =[2]EUCAM_output!$M3 -> 1995.9261 | AC6: =[2]EUCAM_output!$AL3 -> 1993.3413 | AD6: =[2]EUCAM_output!$T3*10^9 -> 3.1180181e+11 | AI6: =CH6/EN6 -> 6.6730047e+09 | AJ6: 336950000 | AK6: =AJ6/EN6 -> 3.5507935e+09 | AM6: =AVERAGE($AL$35:$AL$63) -> 0.065166448 | AO6: 2440800000 | AP6: =AO6/EN6 -> 2.5721254e+10 | AQ6: 1410600000 | AR6: =(AQ6-AJ6)/EN6 -> 1.1314169e+10 | BB6: 1.077579e+11 | BC6: =[2]EUCAM_output!$AG3*10^9 -> 2.0670067e+10 | BD6: =(BB6-B6)/B6*100 -> -0.47164484 | CH6: {=INDEX([1]Sheet1!$C$6:$CY$72,MATCH($A6,[1]Sheet1!$A$6:$A$72,0),MATCH(MID(CELL("filename",O5),FIND("]",CELL("filename",O5))+1,255) & CH$1,[1]Sheet1!$C$1:$CY$1 & [1]Sheet1!$C$3:$CY$3,0))} -> 633230000 | DQ6: 1.06981 | DR6: {=INDEX([1]Sheet1!$C$6:$CY$72,MATCH($A6,[1]Sheet1!$A$6:$A$72,0),MATCH(MID(CELL("filename",AZ5),FIND("]",CELL("filename",AZ5))+1,255) & DR$1,[1]Sheet1!$C$1:$CY$1 & [1]Sheet1!$C$3:$CY$3,0))} -> 0 | DS6: {=INDEX([1]Sheet1!$C$6:$CY$72,MATCH($A6,[1]Sheet1!$A$6:$A$72,0),MATCH(MID(CELL("filename",BA5),FIND("]",CELL("filename",BA5))+1,255) & DS$1,[1]Sheet1!$C$1:$CY$1 & [1]Sheet1!$C$3:$CY$3,0))} -> 0 | DU6: {=INDEX([1]Sheet1!$C$6:$CY$72,MATCH($A6,[1]Sheet1!$A$6:$A$72,0),MATCH(MID(CELL("filename",BC5),FIND("]",CELL("filename",BC5))+1,255) & DU$1,[1]Sheet1!$C$1:$CY$1 & [1]Sheet1!$C$3:$CY$3,0))} -> 0 | DV6: 0.5 | DW6: =Euro_Area_Data!V3*10^9 -> #N/A | DX6: 1 | DY6: 0.5 | DZ6: {=INDEX([1]Sheet1!$C$6:$CY$72,MATCH($A6,[1]Sheet1!$A$6:$A$72,0),MATCH(MID(CELL("filename",BH5),FIND("]",CELL("filename",BH5))+1,255) & DZ$1,[1]Sheet1!$C$1:$CY$1 & [1]Sheet1!$C$3:$CY$3,0))} -> 6.91 | EA6: 2 | EE6: -5 | EH6: 0.75 | EI6: 0.05 | EJ6: 75 | EK6: =(EN6-EN5)/EN5*100 -> 3.1219914 | EN6: =[2]EUCAM_output!$AE3 -> 0.094894283
A7: 1967 | B7: =[2]EUCAM_output!$E4*10^9 -> 1.129524e+11 | I7: =[2]EUCAM_output!$W4*10^3 -> 5282658.5 | K7: =IF(A7<2030,I7,K6*J7/J6) -> 5282658.5 | L7: =[2]EUCAM_output!$G4 -> 62.833244 | O7: =[2]EUCAM_output!$H4 -> 63.145994 | R7: =[2]EUCAM_output!$L4 -> 1.5 | U7: =[2]EUCAM_output!$K4 -> 1.280036 | V7: 1.280036 | W7: 0.048464971 | X7: 0.029641486 | Y7: =[2]EUCAM_output!$AI4 -> 0.0019664909 | Z7: =[2]EUCAM_output!$M4 -> 1986.1608 | AC7: =[2]EUCAM_output!$AL4 -> 1977.1517 | AD7: =[2]EUCAM_output!$T4*10^9 -> 3.2331192e+11 | AI7: =CH7/EN7 -> 7.426873e+09 | AJ7: 378950000 | AK7: =AJ7/EN7 -> 3.8497182e+09 | AM7: =AVERAGE($AL$35:$AL$63) -> 0.065166448 | AO7: 2428600000 | AP7: =AO7/EN7 -> 2.4671924e+10 | AQ7: 1566900000 | AR7: =(AQ7-AJ7)/EN7 -> 1.2068275e+10 | BB7: 1.109989e+11 | BC7: =[2]EUCAM_output!$AG4*10^9 -> 2.1983259e+10 | BD7: =(BB7-B7)/B7*100 -> -1.7294904 | CH7: {=INDEX([1]Sheet1!$C$6:$CY$72,MATCH($A7,[1]Sheet1!$A$6:$A$72,0),MATCH(MID(CELL("filename",O6),FIND("]",CELL("filename",O6))+1,255) & CH$1,[1]Sheet1!$C$1:$CY$1 & [1]Sheet1!$C$3:$CY$3,0))} -> 731070000 | DQ7: 1.064817 | DR7: {=INDEX([1]Sheet1!$C$6:$CY$72,MATCH($A7,[1]Sheet1!$A$6:$A$72,0),MATCH(MID(CELL("filename",AZ6),FIND("]",CELL("filename",AZ6))+1,255) & DR$1,[1]Sheet1!$C$1:$CY$1 & [1]Sheet1!$C$3:$CY$3,0))} -> 0 | DS7: {=INDEX([1]Sheet1!$C$6:$CY$72,MATCH($A7,[1]Sheet1!$A$6:$A$72,0),MATCH(MID(CELL("filename",BA6),FIND("]",CELL("filename",BA6))+1,255) & DS$1,[1]Sheet1!$C$1:$CY$1 & [1]Sheet1!$C$3:$CY$3,0))} -> 0 | DU7: {=INDEX([1]Sheet1!$C$6:$CY$72,MATCH($A7,[1]Sheet1!$A$6:$A$72,0),MATCH(MID(CELL("filename",BC6),FIND("]",CELL("filename",BC6))+1,255) & DU$1,[1]Sheet1!$C$1:$CY$1 & [1]Sheet1!$C$3:$CY$3,0))} -> 4.75 | DV7: 0.5 | DW7: =Euro_Area_Data!V4*10^9 -> #N/A | DX7: 1 | DY7: 0.5 | DZ7: {=INDEX([1]Sheet1!$C$6:$CY$72,MATCH($A7,[1]Sheet1!$A$6:$A$72,0),MATCH(MID(CELL("filename",BH6),FIND("]",CELL("filename",BH6))+1,255) & DZ$1,[1]Sheet1!$C$1:$CY$1 & [1]Sheet1!$C$3:$CY$3,0))} -> 7.22 | EA7: 2 | EE7: -5 | EH7: 0.75 | EI7: 0.05 | EJ7: 75 | EK7: =(EN7-EN6)/EN6*100 -> 3.7320395 | EN7: =[2]EUCAM_output!$AE4 -> 0.098435775
A8: 1968 | B8: =[2]EUCAM_output!$E5*10^9 -> 1.1768782e+11 | I8: =[2]EUCAM_output!$W5*10^3 -> 5289687 | K8: =IF(A8<2030,I8,K7*J8/J7) -> 5289687 | L8: =[2]EUCAM_output!$G5 -> 62.101917 | O8: =[2]EUCAM_output!$H5 -> 62.607938 | R8: =[2]EUCAM_output!$L5 -> 1.7 | U8: =[2]EUCAM_output!$K5 -> 1.22466 | V8: 1.22466 | W8: 0.057769949 | X8: 0.0260883 | Y8: =[2]EUCAM_output!$AI5 -> -0.022069905 | Z8: =[2]EUCAM_output!$M5 -> 1972.3733 | AC8: =[2]EUCAM_output!$AL5 -> 1960.4434 | AD8: =[2]EUCAM_output!$T5*10^9 -> 3.3480634e+11 | AI8: =CH8/EN8 -> 7.5226176e+09 | AJ8: 409620000 | AK8: =AJ8/EN8 -> 3.9099285e+09 | AM8: =AVERAGE($AL$35:$AL$63) -> 0.065166448 | AO8: 2604400000 | AP8: =AO8/EN8 -> 2.4859669e+10 | AQ8: 1703300000 | AR8: =(AQ8-AJ8)/EN8 -> 1.2348509e+10 | BB8: 1.1596319e+11 | BC8: =[2]EUCAM_output!$AG5*10^9 -> 2.3618205e+10 | BD8: =(BB8-B8)/B8*100 -> -1.4654245 | CH8: {=INDEX([1]Sheet1!$C$6:$CY$72,MATCH($A8,[1]Sheet1!$A$6:$A$72,0),MATCH(MID(CELL("filename",O7),FIND("]",CELL("filename",O7))+1,255) & CH$1,[1]Sheet1!$C$1:$CY$1 & [1]Sheet1!$C$3:$CY$3,0))} -> 788100000 | DQ8: 1.02889 | DR8: {=INDEX([1]Sheet1!$C$6:$CY$72,MATCH($A8,[1]Sheet1!$A$6:$A$72,0),MATCH(MID(CELL("filename",AZ7),FIND("]",CELL("filename",AZ7))+1,255) & DR$1,[1]Sheet1!$C$1:$CY$1 & [1]Sheet1!$C$3:$CY$3,0))} -> 0 | DS8: {=INDEX([1]Sheet1!$C$6:$CY$72,MATCH($A8,[1]Sheet1!$A$6:$A$72,0),MATCH(MID(CELL("filename",BA7),FIND("]",CELL("filename",BA7))+1,255) & DS$1,[1]Sheet1!$C$1:$CY$1 & [1]Sheet1!$C$3:$CY$3,0))} -> 0 | DU8: {=INDEX([1]Sheet1!$C$6:$CY$72,MATCH($A8,[1]Sheet1!$A$6:$A$72,0),MATCH(MID(CELL("filename",BC7),FIND("]",CELL("filename",BC7))+1,255) & DU$1,[1]Sheet1!$C$1:$CY$1 & [1]Sheet1!$C$3:$CY$3,0))} -> 4.14 | DV8: 0.5 | DW8: =Euro_Area_Data!V5*10^9 -> #N/A | DX8: 1 | DY8: 0.5 | DZ8: {=INDEX([1]Sheet1!$C$6:$CY$72,MATCH($A8,[1]Sheet1!$A$6:$A$72,0),MATCH(MID(CELL("filename",BH7),FIND("]",CELL("filename",BH7))+1,255) & DZ$1,[1]Sheet1!$C$1:$CY$1 & [1]Sheet1!$C$3:$CY$3,0))} -> 7.74 | EA8: 2 | EE8: -5 | EH8: 0.75 | EI8: 0.05 | EJ8: 75 | EK8: =(EN8-EN7)/EN7*100 -> 6.4288513 | EN8: =[2]EUCAM_output!$AE5 -> 0.10476406
A9: 1969 | B9: =[2]EUCAM_output!$E6*10^9 -> 1.2262414e+11 | I9: =[2]EUCAM_output!$W6*10^3 -> 5289343.5 | K9: =IF(A9<2030,I9,K8*J9/J8) -> 5289343.5 | L9: =[2]EUCAM_output!$G6 -> 62.044722 | O9: =[2]EUCAM_output!$H6 -> 62.260591 | R9: =[2]EUCAM_output!$L6 -> 1.7 | U9: =[2]EUCAM_output!$K6 -> 1.164066 | V9: 1.164066 | W9: 0.063810442 | X9: 0.031915588 | Y9: =[2]EUCAM_output!$AI6 -> 0.0098573205 | Z9: =[2]EUCAM_output!$M6 -> 1958.5649 | AC9: =[2]EUCAM_output!$AL6 -> 1943.9874 | AD9: =[2]EUCAM_output!$T6*10^9 -> 3.4687575e+11 | AI9: =CH9/EN9 -> 7.5859396e+09 | AJ9: 408790000 | AK9: =AJ9/EN9 -> 3.7734467e+09 | AM9: =AVERAGE($AL$35:$AL$63) -> 0.065166448 | AO9: 2808300000 | AP9: =AO9/EN9 -> 2.5922773e+10 | AQ9: 1853100000 | AR9: =(AQ9-AJ9)/EN9 -> 1.3332094e+10 | BB9: 1.2324123e+11 | BC9: =[2]EUCAM_output!$AG6*10^9 -> 2.5786588e+10 | BD9: =(BB9-B9)/B9*100 -> 0.50324034 | CH9: {=INDEX([1]Sheet1!$C$6:$CY$72,MATCH($A9,[1]Sheet1!$A$6:$A$72,0),MATCH(MID(CELL("filename",O8),FIND("]",CELL("filename",O8))+1,255) & CH$1,[1]Sheet1!$C$1:$CY$1 & [1]Sheet1!$C$3:$CY$3,0))} -> 821810000 | DQ9: 1.022187 | DR9: {=INDEX([1]Sheet1!$C$6:$CY$72,MATCH($A9,[1]Sheet1!$A$6:$A$72,0),MATCH(MID(CELL("filename",AZ8),FIND("]",CELL("filename",AZ8))+1,255) & DR$1,[1]Sheet1!$C$1:$CY$1 & [1]Sheet1!$C$3:$CY$3,0))} -> 0 | DS9: {=INDEX([1]Sheet1!$C$6:$CY$72,MATCH($A9,[1]Sheet1!$A$6:$A$72,0),MATCH(MID(CELL("filename",BA8),FIND("]",CELL("filename",BA8))+1,255) & DS$1,[1]Sheet1!$C$1:$CY$1 & [1]Sheet1!$C$3:$CY$3,0))} -> 0 | DU9: {=INDEX([1]Sheet1!$C$6:$CY$72,MATCH($A9,[1]Sheet1!$A$6:$A$72,0),MATCH(MID(CELL("filename",BC8),FIND("]",CELL("filename",BC8))+1,255) & DU$1,[1]Sheet1!$C$1:$CY$1 & [1]Sheet1!$C$3:$CY$3,0))} -> 4.49 | DV9: 0.5 | DW9: =Euro_Area_Data!V6*10^9 -> #N/A | DX9: 1 | DY9: 0.5 | DZ9: {=INDEX([1]Sheet1!$C$6:$CY$72,MATCH($A9,[1]Sheet1!$A$6:$A$72,0),MATCH(MID(CELL("filename",BH8),FIND("]",CELL("filename",BH8))+1,255) & DZ$1,[1]Sheet1!$C$1:$CY$1 & [1]Sheet1!$C$3:$CY$3,0))} -> 7.52 | EA9: 2 | EE9: -5 | EH9: 0.75 | EI9: 0.05 | EJ9: 75 | EK9: =(EN9-EN8)/EN8*100 -> 3.4069431 | EN9: =[2]EUCAM_output!$AE6 -> 0.10833332
A10: 1970 | B10: =[2]EUCAM_output!$E7*10^9 -> 1.281897e+11 | I10: =[2]EUCAM_output!$W7*10^3 -> 5297592 | K10: =IF(A10<2030,I10,K9*J10/J9) -> 5297592 | L10: =[2]EUCAM_output!$G7 -> 61.795088 | O10: =[2]EUCAM_output!$H7 -> 62.1077 | R10: =[2]EUCAM_output!$L7 -> 1.1 | U10: =[2]EUCAM_output!$K7 -> 1.093997 | V10: 1.093997 | W10: 0.067366127 | X10: 0.023764645 | Y10: =[2]EUCAM_output!$AI7 -> -0.0029240582 | Z10: =[2]EUCAM_output!$M7 -> 1897.1867 | AC10: =[2]EUCAM_output!$AL7 -> 1929.7474 | AD10: =[2]EUCAM_output!$T7*10^9 -> 3.6093085e+11 | AI10: =CH10/EN10 -> 8.1646164e+09 | AJ10: 456150000 | AK10: =AJ10/EN10 -> 4.0201312e+09 | AM10: =AVERAGE($AL$35:$AL$63) -> 0.065166448 | AO10: 3270100000 | AP10: =AO10/EN10 -> 2.8819974e+10 | AQ10: 2028400000 | AR10: =(AQ10-AJ10)/EN10 -> 1.3856519e+10 | BB10: 1.320195e+11 | BC10: =[2]EUCAM_output!$AG7*10^9 -> 2.8933321e+10 | BD10: =(BB10-B10)/B10*100 -> 2.9876053 | CH10: {=INDEX([1]Sheet1!$C$6:$CY$72,MATCH($A10,[1]Sheet1!$A$6:$A$72,0),MATCH(MID(CELL("filename",O9),FIND("]",CELL("filename",O9))+1,255) & CH$1,[1]Sheet1!$C$1:$CY$1 & [1]Sheet1!$C$3:$CY$3,0))} -> 926410000 | DQ10: 1.022227 | DR10: {=INDEX([1]Sheet1!$C$6:$CY$72,MATCH($A10,[1]Sheet1!$A$6:$A$72,0),MATCH(MID(CELL("filename",AZ9),FIND("]",CELL("filename",AZ9))+1,255) & DR$1,[1]Sheet1!$C$1:$CY$1 & [1]Sheet1!$C$3:$CY$3,0))} -> 0 | DS10: {=INDEX([1]Sheet1!$C$6:$CY$72,MATCH($A10,[1]Sheet1!$A$6:$A$72,0),MATCH(MID(CELL("filename",BA9),FIND("]",CELL("filename",BA9))+1,255) & DS$1,[1]Sheet1!$C$1:$CY$1 & [1]Sheet1!$C$3:$CY$3,0))} -> 0 | DU10: {=INDEX([1]Sheet1!$C$6:$CY$72,MATCH($A10,[1]Sheet1!$A$6:$A$72,0),MATCH(MID(CELL("filename",BC9),FIND("]",CELL("filename",BC9))+1,255) & DU$1,[1]Sheet1!$C$1:$CY$1 & [1]Sheet1!$C$3:$CY$3,0))} -> 5.62 | DV10: 0.5 | DW10: =Euro_Area_Data!V7*10^9 -> #N/A | DX10: 1 | DY10: 0.5 | DZ10: {=INDEX([1]Sheet1!$C$6:$CY$72,MATCH($A10,[1]Sheet1!$A$6:$A$72,0),MATCH(MID(CELL("filename",BH9),FIND("]",CELL("filename",BH9))+1,255) & DZ$1,[1]Sheet1!$C$1:$CY$1 & [1]Sheet1!$C$3:$CY$3,0))} -> 7.82 | EA10: 2 | EE10: -5 | EH10: 0.75 | EI10: 0.05 | EJ10: 75 | EK10: =(EN10-EN9)/EN9*100 -> 4.7382731 | EN10: =[2]EUCAM_output!$AE7 -> 0.11346645
A11: 1971 | B11: =[2]EUCAM_output!$E8*10^9 -> 1.3469051e+11 | I11: =[2]EUCAM_output!$W8*10^3 -> 5319969.5 | K11: =IF(A11<2030,I11,K10*J11/J10) -> 5319969.5 | L11: =[2]EUCAM_output!$G8 -> 62.178198 | O11: =[2]EUCAM_output!$H8 -> 62.131424 | R11: =[2]EUCAM_output!$L8 -> 1 | U11: =[2]EUCAM_output!$K8 -> 1.036013 | V11: 1.036013 | W11: 0.039209843 | X11: 0.012186416 | Y11: =[2]EUCAM_output!$AI8 -> 0.045715548 | Z11: =[2]EUCAM_output!$M8 -> 1891.4112 | AC11: =[2]EUCAM_output!$AL8 -> 1921.1451 | AD11: =[2]EUCAM_output!$T8*10^9 -> 3.7829696e+11 | AI11: =CH11/EN11 -> 9.2136534e+09 | AJ11: 537910000 | AK11: =AJ11/EN11 -> 4.3966434e+09 | AM11: =AVERAGE($AL$35:$AL$63) -> 0.065166448 | AO11: 3996800000 | AP11: =AO11/EN11 -> 3.2668113e+10 | AQ11: 2172300000 | AR11: =(AQ11-AJ11)/EN11 -> 1.3358796e+10 | BB11: 1.3876983e+11 | BC11: =[2]EUCAM_output!$AG8*10^9 -> 3.2300203e+10 | BD11: =(BB11-B11)/B11*100 -> 3.0286553 | CH11: {=INDEX([1]Sheet1!$C$6:$CY$72,MATCH($A11,[1]Sheet1!$A$6:$A$72,0),MATCH(MID(CELL("filename",O10),FIND("]",CELL("filename",O10))+1,255) & CH$1,[1]Sheet1!$C$1:$CY$1 & [1]Sheet1!$C$3:$CY$3,0))} -> 1127250000 | DQ11: 1.04776 | DR11: {=INDEX([1]Sheet1!$C$6:$CY$72,MATCH($A11,[1]Sheet1!$A$6:$A$72,0),MATCH(MID(CELL("filename",AZ10),FIND("]",CELL("filename",AZ10))+1,255) & DR$1,[1]Sheet1!$C$1:$CY$1 & [1]Sheet1!$C$3:$CY$3,0))} -> 0 | DS11: {=INDEX([1]Sheet1!$C$6:$CY$72,MATCH($A11,[1]Sheet1!$A$6:$A$72,0),MATCH(MID(CELL("filename",BA10),FIND("]",CELL("filename",BA10))+1,255) & DS$1,[1]Sheet1!$C$1:$CY$1 & [1]Sheet1!$C$3:$CY$3,0))} -> 0 | DU11: {=INDEX([1]Sheet1!$C$6:$CY$72,MATCH($A11,[1]Sheet1!$A$6:$A$72,0),MATCH(MID(CELL("filename",BC10),FIND("]",CELL("filename",BC10))+1,255) & DU$1,[1]Sheet1!$C$1:$CY$1 & [1]Sheet1!$C$3:$CY$3,0))} -> 4.39 | DV11: 0.5 | DW11: =Euro_Area_Data!V8*10^9 -> #N/A | DX11: 1 | DY11: 0.5 | DZ11: {=INDEX([1]Sheet1!$C$6:$CY$72,MATCH($A11,[1]Sheet1!$A$6:$A$72,0),MATCH(MID(CELL("filename",BH10),FIND("]",CELL("filename",BH10))+1,255) & DZ$1,[1]Sheet1!$C$1:$CY$1 & [1]Sheet1!$C$3:$CY$3,0))} -> 7.71 | EA11: 2 | EE11: -5 | EH11: 0.75 | EI11: 0.05 | EJ11: 75 | EK11: =(EN11-EN10)/EN10*100 -> 7.8253617 | EN11: =[2]EUCAM_output!$AE8 -> 0.12234561
A12: 1972 | B12: =[2]EUCAM_output!$E9*10^9 -> 1.4217231e+11 | I12: =[2]EUCAM_output!$W9*10^3 -> 5356960.5 | K12: =IF(A12<2030,I12,K11*J12/J11) -> 5356960.5 | L12: =[2]EUCAM_output!$G9 -> 62.126296 | O12: =[2]EUCAM_output!$H9 -> 62.282662 | R12: =[2]EUCAM_output!$L9 -> 0.9 | U12: =[2]EUCAM_output!$K9 -> 0.990719 | V12: 0.990719 | W12: 0.054560679 | X12: 0.0017830222 | Y12: =[2]EUCAM_output!$AI9 -> -0.015973066 | Z12: =[2]EUCAM_output!$M9 -> 1912.4208 | AC12: =[2]EUCAM_output!$AL9 -> 1918.346 | AD12: =[2]EUCAM_output!$T9*10^9 -> 3.9976557e+11 | AI12: =CH12/EN12 -> 1.0246063e+10 | AJ12: 609600000 | AK12: =AJ12/EN12 -> 4.5867111e+09 | AM12: =AVERAGE($AL$35:$AL$63) -> 0.065166448 | AO12: 5040000000 | AP12: =AO12/EN12 -> 3.7921627e+10 | AQ12: 2416300000 | AR12: =(AQ12-AJ12)/EN12 -> 1.359385e+10 | BB12: 1.4738446e+11 | BC12: =[2]EUCAM_output!$AG9*10^9 -> 3.6912538e+10 | BD12: =(BB12-B12)/B12*100 -> 3.6660849 | CH12: {=INDEX([1]Sheet1!$C$6:$CY$72,MATCH($A12,[1]Sheet1!$A$6:$A$72,0),MATCH(MID(CELL("filename",O11),FIND("]",CELL("filename",O11))+1,255) & CH$1,[1]Sheet1!$C$1:$CY$1 & [1]Sheet1!$C$3:$CY$3,0))} -> 1361760000 | DQ12: 1.12178 | DR12: {=INDEX([1]Sheet1!$C$6:$CY$72,MATCH($A12,[1]Sheet1!$A$6:$A$72,0),MATCH(MID(CELL("filename",AZ11),FIND("]",CELL("filename",AZ11))+1,255) & DR$1,[1]Sheet1!$C$1:$CY$1 & [1]Sheet1!$C$3:$CY$3,0))} -> 0 | DS12: {=INDEX([1]Sheet1!$C$6:$CY$72,MATCH($A12,[1]Sheet1!$A$6:$A$72,0),MATCH(MID(CELL("filename",BA11),FIND("]",CELL("filename",BA11))+1,255) & DS$1,[1]Sheet1!$C$1:$CY$1 & [1]Sheet1!$C$3:$CY$3,0))} -> 0 | DU12: {=INDEX([1]Sheet1!$C$6:$CY$72,MATCH($A12,[1]Sheet1!$A$6:$A$72,0),MATCH(MID(CELL("filename",BC11),FIND("]",CELL("filename",BC11))+1,255) & DU$1,[1]Sheet1!$C$1:$CY$1 & [1]Sheet1!$C$3:$CY$3,0))} -> 5.17 | DV12: 0.5 | DW12: =Euro_Area_Data!V9*10^9 -> #N/A | DX12: 1 | DY12: 0.5 | DZ12: {=INDEX([1]Sheet1!$C$6:$CY$72,MATCH($A12,[1]Sheet1!$A$6:$A$72,0),MATCH(MID(CELL("filename",BH11),FIND("]",CELL("filename",BH11))+1,255) & DZ$1,[1]Sheet1!$C$1:$CY$1 & [1]Sheet1!$C$3:$CY$3,0))} -> 7.38 | EA12: 2 | EE12: -5 | EH12: 0.75 | EI12: 0.05 | EJ12: 75 | EK12: =(EN12-EN11)/EN11*100 -> 8.6313549 | EN12: =[2]EUCAM_output!$AE9 -> 0.13290569
A13: 1973 | B13: =[2]EUCAM_output!$E10*10^9 -> 1.4967003e+11 | I13: =[2]EUCAM_output!$W10*10^3 -> 5399117 | K13: =IF(A13<2030,I13,K12*J13/J12) -> 5399117 | L13: =[2]EUCAM_output!$G10 -> 62.672532 | O13: =[2]EUCAM_output!$H10 -> 62.516991 | R13: =[2]EUCAM_output!$L10 -> 0.9 | U13: =[2]EUCAM_output!$K10 -> 0.970604 | V13: 0.970604 | W13: 0.03161307 | X13: -0.011905162 | Y13: =[2]EUCAM_output!$AI10 -> 0.022597137 | Z13: =[2]EUCAM_output!$M10 -> 1902.2121 | AC13: =[2]EUCAM_output!$AL10 -> 1918.5422 | AD13: =[2]EUCAM_output!$T10*10^9 -> 4.204903e+11 | AI13: =CH13/EN13 -> 1.0018456e+10 | AJ13: 732760000 | AK13: =AJ13/EN13 -> 4.745915e+09 | AM13: =AVERAGE($AL$35:$AL$63) -> 0.065166448 | AO13: 5809800000 | AP13: =AO13/EN13 -> 3.7628715e+10 | AQ13: 2770300000 | AR13: =(AQ13-AJ13)/EN13 -> 1.319667e+10 | BB13: 1.5458759e+11 | BC13: =[2]EUCAM_output!$AG10*10^9 -> 4.1832773e+10 | BD13: =(BB13-B13)/B13*100 -> 3.2856015 | CH13: {=INDEX([1]Sheet1!$C$6:$CY$72,MATCH($A13,[1]Sheet1!$A$6:$A$72,0),MATCH(MID(CELL("filename",O12),FIND("]",CELL("filename",O12))+1,255) & CH$1,[1]Sheet1!$C$1:$CY$1 & [1]Sheet1!$C$3:$CY$3,0))} -> 1546830000 | DQ13: 1.23173 | DR13: {=INDEX([1]Sheet1!$C$6:$CY$72,MATCH($A13,[1]Sheet1!$A$6:$A$72,0),MATCH(MID(CELL("filename",AZ12),FIND("]",CELL("filename",AZ12))+1,255) & DR$1,[1]Sheet1!$C$1:$CY$1 & [1]Sheet1!$C$3:$CY$3,0))} -> 0 | DS13: {=INDEX([1]Sheet1!$C$6:$CY$72,MATCH($A13,[1]Sheet1!$A$6:$A$72,0),MATCH(MID(CELL("filename",BA12),FIND("]",CELL("filename",BA12))+1,255) & DS$1,[1]Sheet1!$C$1:$CY$1 & [1]Sheet1!$C$3:$CY$3,0))} -> 0 | DU13: {=INDEX([1]Sheet1!$C$6:$CY$72,MATCH($A13,[1]Sheet1!$A$6:$A$72,0),MATCH(MID(CELL("filename",BC12),FIND("]",CELL("filename",BC12))+1,255) & DU$1,[1]Sheet1!$C$1:$CY$1 & [1]Sheet1!$C$3:$CY$3,0))} -> 6.94 | DV13: 0.5 | DW13: =Euro_Area_Data!V10*10^9 -> #N/A | DX13: 1 | DY13: 0.5 | DZ13: {=INDEX([1]Sheet1!$C$6:$CY$72,MATCH($A13,[1]Sheet1!$A$6:$A$72,0),MATCH(MID(CELL("filename",BH12),FIND("]",CELL("filename",BH12))+1,255) & DZ$1,[1]Sheet1!$C$1:$CY$1 & [1]Sheet1!$C$3:$CY$3,0))} -> 8.25 | EA13: 2 | EE13: -5 | EH13: 0.75 | EI13: 0.05 | EJ13: 75 | EK13: =(EN13-EN12)/EN12*100 -> 16.171134 | EN13: =[2]EUCAM_output!$AE10 -> 0.15439805
A14: 1974 | B14: =[2]EUCAM_output!$E11*10^9 -> 1.5662384e+11 | I14: =[2]EUCAM_output!$W11*10^3 -> 5422011.5 | K14: =IF(A14<2030,I14,K13*J14/J13) -> 5422011.5 | L14: =[2]EUCAM_output!$G11 -> 63.127778 | O14: =[2]EUCAM_output!$H11 -> 62.774351 | R14: =[2]EUCAM_output!$L11 -> 1.1 | U14: =[2]EUCAM_output!$K11 -> 0.985529 | V14: 0.985529 | W14: 0.029662229 | X14: -0.0072064351 | Y14: =[2]EUCAM_output!$AI11 -> 0.0063791865 | Z14: =[2]EUCAM_output!$M11 -> 1987.0916 | AC14: =[2]EUCAM_output!$AL11 -> 1918.3332 | AD14: =[2]EUCAM_output!$T11*10^9 -> 4.4178968e+11 | AI14: =CH14/EN14 -> 1.0864732e+10 | AJ14: 958160000 | AK14: =AJ14/EN14 -> 5.1461267e+09 | AM14: =AVERAGE($AL$35:$AL$63) -> 0.065166448 | AO14: 7184000000 | AP14: =AO14/EN14 -> 3.8584135e+10 | AQ14: 3174200000 | AR14: =(AQ14-AJ14)/EN14 -> 1.1902002e+10 | BB14: 1.6068413e+11 | BC14: =[2]EUCAM_output!$AG11*10^9 -> 4.7613587e+10 | BD14: =(BB14-B14)/B14*100 -> 2.5923869 | CH14: {=INDEX([1]Sheet1!$C$6:$CY$72,MATCH($A14,[1]Sheet1!$A$6:$A$72,0),MATCH(MID(CELL("filename",O13),FIND("]",CELL("filename",O13))+1,255) & CH$1,[1]Sheet1!$C$1:$CY$1 & [1]Sheet1!$C$3:$CY$3,0))} -> 2022910000 | DQ14: 1.1927 | DR14: {=INDEX([1]Sheet1!$C$6:$CY$72,MATCH($A14,[1]Sheet1!$A$6:$A$72,0),MATCH(MID(CELL("filename",AZ13),FIND("]",CELL("filename",AZ13))+1,255) & DR$1,[1]Sheet1!$C$1:$CY$1 & [1]Sheet1!$C$3:$CY$3,0))} -> 0 | DS14: {=INDEX([1]Sheet1!$C$6:$CY$72,MATCH($A14,[1]Sheet1!$A$6:$A$72,0),MATCH(MID(CELL("filename",BA13),FIND("]",CELL("filename",BA13))+1,255) & DS$1,[1]Sheet1!$C$1:$CY$1 & [1]Sheet1!$C$3:$CY$3,0))} -> 0 | DU14: {=INDEX([1]Sheet1!$C$6:$CY$72,MATCH($A14,[1]Sheet1!$A$6:$A$72,0),MATCH(MID(CELL("filename",BC13),FIND("]",CELL("filename",BC13))+1,255) & DU$1,[1]Sheet1!$C$1:$CY$1 & [1]Sheet1!$C$3:$CY$3,0))} -> 7.26 | DV14: 0.5 | DW14: =Euro_Area_Data!V11*10^9 -> #N/A | DX14: 1 | DY14: 0.5 | DZ14: {=INDEX([1]Sheet1!$C$6:$CY$72,MATCH($A14,[1]Sheet1!$A$6:$A$72,0),MATCH(MID(CELL("filename",BH13),FIND("]",CELL("filename",BH13))+1,255) & DZ$1,[1]Sheet1!$C$1:$CY$1 & [1]Sheet1!$C$3:$CY$3,0))} -> 9.74 | EA14: 2 | EE14: -5 | EH14: 0.75 | EI14: 0.05 | EJ14: 75 | EK14: =(EN14-EN13)/EN13*100 -> 20.59124 | EN14: =[2]EUCAM_output!$AE11 -> 0.18619052
A15: 1975 | B15: =[2]EUCAM_output!$E12*10^9 -> 1.6218392e+11 | I15: =[2]EUCAM_output!$W12*10^3 -> 5424049.5 | K15: =IF(A15<2030,I15,K14*J15/J14) -> 5424049.5 | L15: =[2]EUCAM_output!$G12 -> 62.998429 | O15: =[2]EUCAM_output!$H12 -> 63.010234 | R15: =[2]EUCAM_output!$L12 -> 1.4 | U15: =[2]EUCAM_output!$K12 -> 1.039544 | V15: 1.039544 | W15: 0.0010842606 | X15: 0.006122739 | Y15: =[2]EUCAM_output!$AI12 -> -0.01208226 | Z15: =[2]EUCAM_output!$M12 -> 1906.9313 | AC15: =[2]EUCAM_output!$AL12 -> 1912.6858 | AD15: =[2]EUCAM_output!$T12*10^9 -> 4.6005117e+11 | AI15: =CH15/EN15 -> 1.1076272e+10 | AJ15: 1.0712e+09 | AK15: =AJ15/EN15 -> 5.3173887e+09 | AM15: =AVERAGE($AL$35:$AL$63) -> 0.065166448 | AO15: 7124700000 | AP15: =AO15/EN15 -> 3.5366691e+10 | AQ15: 3787400000 | AR15: =(AQ15-AJ15)/EN15 -> 1.3483095e+10 | BB15: 1.6010197e+11 | BC15: =[2]EUCAM_output!$AG12*10^9 -> 5.0503994e+10 | BD15: =(BB15-B15)/B15*100 -> -1.2836977 | CH15: {=INDEX([1]Sheet1!$C$6:$CY$72,MATCH($A15,[1]Sheet1!$A$6:$A$72,0),MATCH(MID(CELL("filename",O14),FIND("]",CELL("filename",O14))+1,255) & CH$1,[1]Sheet1!$C$1:$CY$1 & [1]Sheet1!$C$3:$CY$3,0))} -> 2231340000 | DQ15: 1.24077 | DR15: {=INDEX([1]Sheet1!$C$6:$CY$72,MATCH($A15,[1]Sheet1!$A$6:$A$72,0),MATCH(MID(CELL("filename",AZ14),FIND("]",CELL("filename",AZ14))+1,255) & DR$1,[1]Sheet1!$C$1:$CY$1 & [1]Sheet1!$C$3:$CY$3,0))} -> 0 | DS15: {=INDEX([1]Sheet1!$C$6:$CY$72,MATCH($A15,[1]Sheet1!$A$6:$A$72,0),MATCH(MID(CELL("filename",BA14),FIND("]",CELL("filename",BA14))+1,255) & DS$1,[1]Sheet1!$C$1:$CY$1 & [1]Sheet1!$C$3:$CY$3,0))} -> 0 | DU15: {=INDEX([1]Sheet1!$C$6:$CY$72,MATCH($A15,[1]Sheet1!$A$6:$A$72,0),MATCH(MID(CELL("filename",BC14),FIND("]",CELL("filename",BC14))+1,255) & DU$1,[1]Sheet1!$C$1:$CY$1 & [1]Sheet1!$C$3:$CY$3,0))} -> 5.49 | DV15: 0.5 | DW15: =Euro_Area_Data!V12*10^9 -> #N/A | DX15: 1 | DY15: 0.5 | DZ15: {=INDEX([1]Sheet1!$C$6:$CY$72,MATCH($A15,[1]Sheet1!$A$6:$A$72,0),MATCH(MID(CELL("filename",BH14),FIND("]",CELL("filename",BH14))+1,255) & DZ$1,[1]Sheet1!$C$1:$CY$1 & [1]Sheet1!$C$3:$CY$3,0))} -> 9.61 | EA15: 2 | EE15: -5 | EH15: 0.75 | EI15: 0.05 | EJ15: 75 | EK15: =(EN15-EN14)/EN14*100 -> 8.1968454 | EN15: =[2]EUCAM_output!$AE12 -> 0.20145227
A16: 1976 | B16: =[2]EUCAM_output!$E13*10^9 -> 1.6759215e+11 | I16: =[2]EUCAM_output!$W13*10^3 -> 5440280.5 | K16: =IF(A16<2030,I16,K15*J16/J15) -> 5440280.5 | L16: =[2]EUCAM_output!$G13 -> 63.07227 | O16: =[2]EUCAM_output!$H13 -> 63.215479 | R16: =[2]EUCAM_output!$L13 -> 1.5 | U16: =[2]EUCAM_output!$K13 -> 1.138892 | V16: 1.138892 | W16: 0.042486602 | X16: 0.014742997 | Y16: =[2]EUCAM_output!$AI13 -> -0.03451953 | Z16: =[2]EUCAM_output!$M13 -> 1901.3918 | AC16: =[2]EUCAM_output!$AL13 -> 1903.4422 | AD16: =[2]EUCAM_output!$T13*10^9 -> 4.793181e+11 | AI16: =CH16/EN16 -> 1.0329929e+10 | AJ16: 1238180000 | AK16: =AJ16/EN16 -> 5.4104073e+09 | AM16: =AVERAGE($AL$35:$AL$63) -> 0.065166448 | AO16: 8441400000 | AP16: =AO16/EN16 -> 3.6885923e+10 | AQ16: 4779600000 | AR16: =(AQ16-AJ16)/EN16 -> 1.5474749e+10 | BB16: 1.6742984e+11 | BC16: =[2]EUCAM_output!$AG13*10^9 -> 5.5787551e+10 | BD16: =(BB16-B16)/B16*100 -> -0.096849894 | CH16: {=INDEX([1]Sheet1!$C$6:$CY$72,MATCH($A16,[1]Sheet1!$A$6:$A$72,0),MATCH(MID(CELL("filename",O15),FIND("]",CELL("filename",O15))+1,255) & CH$1,[1]Sheet1!$C$1:$CY$1 & [1]Sheet1!$C$3:$CY$3,0))} -> 2364020000 | DQ16: 1.11805 | DR16: {=INDEX([1]Sheet1!$C$6:$CY$72,MATCH($A16,[1]Sheet1!$A$6:$A$72,0),MATCH(MID(CELL("filename",AZ15),FIND("]",CELL("filename",AZ15))+1,255) & DR$1,[1]Sheet1!$C$1:$CY$1 & [1]Sheet1!$C$3:$CY$3,0))} -> 0 | DS16: {=INDEX([1]Sheet1!$C$6:$CY$72,MATCH($A16,[1]Sheet1!$A$6:$A$72,0),MATCH(MID(CELL("filename",BA15),FIND("]",CELL("filename",BA15))+1,255) & DS$1,[1]Sheet1!$C$1:$CY$1 & [1]Sheet1!$C$3:$CY$3,0))} -> 0 | DU16: {=INDEX([1]Sheet1!$C$6:$CY$72,MATCH($A16,[1]Sheet1!$A$6:$A$72,0),MATCH(MID(CELL("filename",BC15),FIND("]",CELL("filename",BC15))+1,255) & DU$1,[1]Sheet1!$C$1:$CY$1 & [1]Sheet1!$C$3:$CY$3,0))} -> 4.67 | DV16: 0.5 | DW16: =Euro_Area_Data!V13*10^9 -> #N/A | DX16: 1 | DY16: 0.5 | DZ16: {=INDEX([1]Sheet1!$C$6:$CY$72,MATCH($A16,[1]Sheet1!$A$6:$A$72,0),MATCH(MID(CELL("filename",BH15),FIND("]",CELL("filename",BH15))+1,255) & DZ$1,[1]Sheet1!$C$1:$CY$1 & [1]Sheet1!$C$3:$CY$3,0))} -> 8.75 | EA16: 2 | EE16: -5 | EH16: 0.75 | EI16: 0.05 | EJ16: 75 | EK16: =(EN16-EN15)/EN15*100 -> 13.600872 | EN16: =[2]EUCAM_output!$AE13 -> 0.22885153
A17: 1977 | B17: =[2]EUCAM_output!$E14*10^9 -> 1.7309417e+11 | I17: =[2]EUCAM_output!$W14*10^3 -> 5473782.5 | K17: =IF(A17<2030,I17,K16*J17/J16) -> 5473782.5 | L17: =[2]EUCAM_output!$G14 -> 63.51301 | O17: =[2]EUCAM_output!$H14 -> 63.37974 | R17: =[2]EUCAM_output!$L14 -> 1.6 | U17: =[2]EUCAM_output!$K14 -> 1.287983 | V17: 1.287983 | W17: 0.038175132 | X17: 0.017259586 | Y17: =[2]EUCAM_output!$AI14 -> -0.012670404 | Z17: =[2]EUCAM_output!$M14 -> 1906.5261 | AC17: =[2]EUCAM_output!$AL14 -> 1891.8695 | AD17: =[2]EUCAM_output!$T14*10^9 -> 5.0055777e+11 | AI17: =CH17/EN17 -> 1.0649621e+10 | AJ17: 1462370000 | AK17: =AJ17/EN17 -> 5.7126407e+09 | AM17: =AVERAGE($AL$35:$AL$63) -> 0.065166448 | AO17: 10345100000 | AP17: =AO17/EN17 -> 4.0412371e+10 | AQ17: 5262200000 | AR17: =(AQ17-AJ17)/EN17 -> 1.4843756e+10 | BB17: 1.7593524e+11 | BC17: =[2]EUCAM_output!$AG14*10^9 -> 6.1669109e+10 | BD17: =(BB17-B17)/B17*100 -> 1.6413398 | CH17: {=INDEX([1]Sheet1!$C$6:$CY$72,MATCH($A17,[1]Sheet1!$A$6:$A$72,0),MATCH(MID(CELL("filename",O16),FIND("]",CELL("filename",O16))+1,255) & CH$1,[1]Sheet1!$C$1:$CY$1 & [1]Sheet1!$C$3:$CY$3,0))} -> 2726180000 | DQ17: 1.14112 | DR17: {=INDEX([1]Sheet1!$C$6:$CY$72,MATCH($A17,[1]Sheet1!$A$6:$A$72,0),MATCH(MID(CELL("filename",AZ16),FIND("]",CELL("filename",AZ16))+1,255) & DR$1,[1]Sheet1!$C$1:$CY$1 & [1]Sheet1!$C$3:$CY$3,0))} -> 0 | DS17: {=INDEX([1]Sheet1!$C$6:$CY$72,MATCH($A17,[1]Sheet1!$A$6:$A$72,0),MATCH(MID(CELL("filename",BA16),FIND("]",CELL("filename",BA16))+1,255) & DS$1,[1]Sheet1!$C$1:$CY$1 & [1]Sheet1!$C$3:$CY$3,0))} -> 0 | DU17: {=INDEX([1]Sheet1!$C$6:$CY$72,MATCH($A17,[1]Sheet1!$A$6:$A$72,0),MATCH(MID(CELL("filename",BC16),FIND("]",CELL("filename",BC16))+1,255) & DU$1,[1]Sheet1!$C$1:$CY$1 & [1]Sheet1!$C$3:$CY$3,0))} -> 7.49 | DV17: 0.5 | DW17: =Euro_Area_Data!V14*10^9 -> #N/A | DX17: 1 | DY17: 0.5 | DZ17: {=INDEX([1]Sheet1!$C$6:$CY$72,MATCH($A17,[1]Sheet1!$A$6:$A$72,0),MATCH(MID(CELL("filename",BH16),FIND("]",CELL("filename",BH16))+1,255) & DZ$1,[1]Sheet1!$C$1:$CY$1 & [1]Sheet1!$C$3:$CY$3,0))} -> 8.73 | EA17: 2 | EE17: -5 | EH17: 0.75 | EI17: 0.05 | EJ17: 75 | EK17: =(EN17-EN16)/EN16*100 -> 11.857868 | EN17: =[2]EUCAM_output!$AE14 -> 0.25598844
... A30: 1990 | B30: =[2]EUCAM_output!$E27*10^9 -> 2.316421e+11 | I30: =[2]EUCAM_output!$W27*10^3 -> 5801920.5 | K30: =IF(A30<2030,I30,K29*J30/J29) -> 5801920.5 | L30: =[2]EUCAM_output!$G27 -> 63.654158 | O30: =[2]EUCAM_output!$H27 -> 63.051071 | R30: =[2]EUCAM_output!$L27 -> 3.6 | U30: =[2]EUCAM_output!$K27 -> 3.726822 | V30: 3.726822 | W30: 0.022677997 | X30: -0.012026614 | Y30: =[2]EUCAM_output!$AI27 -> 0.0088977438 | Z30: =[2]EUCAM_output!$M27 -> 1824.9736 | AC30: =[2]EUCAM_output!$AL27 -> 1818.378 | AD30: =[2]EUCAM_output!$T27*10^9 -> 7.161258e+11 | AI30: =CH30/EN30 -> 9.1836521e+09 | AJ30: 4.00048e+09 | AK30: =AJ30/EN30 -> 7.2009754e+09 | AM30: =AVERAGE($AL$35:$AL$63) -> 0.065166448 | AO30: 28511400000 | AP30: =AO30/EN30 -> 5.1321314e+10 | AQ30: 19017800000 | AR30: =(AQ30-AJ30)/EN30 -> 2.7031594e+10 | BB30: 2.3501469e+11 | BC30: =[2]EUCAM_output!$AG27*10^9 -> 1.3700994e+11 | BD30: =(BB30-B30)/B30*100 -> 1.4559506 | CH30: {=INDEX([1]Sheet1!$C$6:$CY$72,MATCH($A30,[1]Sheet1!$A$6:$A$72,0),MATCH(MID(CELL("filename",O29),FIND("]",CELL("filename",O29))+1,255) & CH$1,[1]Sheet1!$C$1:$CY$1 & [1]Sheet1!$C$3:$CY$3,0))} -> 5101950000 | DQ30: 1.27343 | DR30: {=INDEX([1]Sheet1!$C$6:$CY$72,MATCH($A30,[1]Sheet1!$A$6:$A$72,0),MATCH(MID(CELL("filename",AZ29),FIND("]",CELL("filename",AZ29))+1,255) & DR$1,[1]Sheet1!$C$1:$CY$1 & [1]Sheet1!$C$3:$CY$3,0))} -> 0 | DS30: {=INDEX([1]Sheet1!$C$6:$CY$72,MATCH($A30,[1]Sheet1!$A$6:$A$72,0),MATCH(MID(CELL("filename",BA29),FIND("]",CELL("filename",BA29))+1,255) & DS$1,[1]Sheet1!$C$1:$CY$1 & [1]Sheet1!$C$3:$CY$3,0))} -> 0 | DU30: {=INDEX([1]Sheet1!$C$6:$CY$72,MATCH($A30,[1]Sheet1!$A$6:$A$72,0),MATCH(MID(CELL("filename",BC29),FIND("]",CELL("filename",BC29))+1,255) & DU$1,[1]Sheet1!$C$1:$CY$1 & [1]Sheet1!$C$3:$CY$3,0))} -> 8.53 | DV30: 0.5 | DW30: =Euro_Area_Data!V27*10^9 -> #N/A | DX30: 1 | DY30: 0.5 | DZ30: {=INDEX([1]Sheet1!$C$6:$CY$72,MATCH($A30,[1]Sheet1!$A$6:$A$72,0),MATCH(MID(CELL("filename",BH29),FIND("]",CELL("filename",BH29))+1,255) & DZ$1,[1]Sheet1!$C$1:$CY$1 & [1]Sheet1!$C$3:$CY$3,0))} -> 8.77 | EA30: 2 | EE30: -5 | EH30: 0.75 | EI30: 0.05 | EJ30: 75 | EK30: =(EN30-EN29)/EN29*100 -> 3.9241089 | EN30: =[2]EUCAM_output!$AE27 -> 0.55554696
A31: 1991 | B31: =[2]EUCAM_output!$E28*10^9 -> 2.3915635e+11 | I31: =[2]EUCAM_output!$W28*10^3 -> 5873311.5 | K31: =IF(A31<2030,I31,K30*J31/J30) -> 5873311.5 | L31: =[2]EUCAM_output!$G28 -> 63.855685 | O31: =[2]EUCAM_output!$H28 -> 63.08808 | R31: =[2]EUCAM_output!$L28 -> 3.9 | U31: =[2]EUCAM_output!$K28 -> 3.802161 | V31: 3.802161 | W31: 0.021797768 | X31: -0.016651225 | Y31: =[2]EUCAM_output!$AI28 -> 0.012151225 | Z31: =[2]EUCAM_output!$M28 -> 1835.3923 | AC31: =[2]EUCAM_output!$AL28 -> 1815.4316 | AD31: =[2]EUCAM_output!$T28*10^9 -> 7.4025744e+11 | AI31: =CH31/EN31 -> 9.6280171e+09 | AJ31: 4.25255e+09 | AK31: =AJ31/EN31 -> 7.3811263e+09 | AM31: =AVERAGE($AL$35:$AL$63) -> 0.065166448 | AO31: 32009000000 | AP31: =AO31/EN31 -> 5.5557835e+10 | AQ31: 20402500000 | AR31: =(AQ31-AJ31)/EN31 -> 2.8031374e+10 | AT31: =AP31/B31*100 -> 23.230758 | BB31: 2.4310303e+11 | BC31: =[2]EUCAM_output!$AG28*10^9 -> 1.4688677e+11 | BD31: =(BB31-B31)/B31*100 -> 1.650247 | CH31: {=INDEX([1]Sheet1!$C$6:$CY$72,MATCH($A31,[1]Sheet1!$A$6:$A$72,0),MATCH(MID(CELL("filename",O30),FIND("]",CELL("filename",O30))+1,255) & CH$1,[1]Sheet1!$C$1:$CY$1 & [1]Sheet1!$C$3:$CY$3,0))} -> 5547070000 | DQ31: 1.23916 | DR31: {=INDEX([1]Sheet1!$C$6:$CY$72,MATCH($A31,[1]Sheet1!$A$6:$A$72,0),MATCH(MID(CELL("filename",AZ30),FIND("]",CELL("filename",AZ30))+1,255) & DR$1,[1]Sheet1!$C$1:$CY$1 & [1]Sheet1!$C$3:$CY$3,0))} -> 0 | DS31: {=INDEX([1]Sheet1!$C$6:$CY$72,MATCH($A31,[1]Sheet1!$A$6:$A$72,0),MATCH(MID(CELL("filename",BA30),FIND("]",CELL("filename",BA30))+1,255) & DS$1,[1]Sheet1!$C$1:$CY$1 & [1]Sheet1!$C$3:$CY$3,0))} -> 0 | DU31: {=INDEX([1]Sheet1!$C$6:$CY$72,MATCH($A31,[1]Sheet1!$A$6:$A$72,0),MATCH(MID(CELL("filename",BC30),FIND("]",CELL("filename",BC30))+1,255) & DU$1,[1]Sheet1!$C$1:$CY$1 & [1]Sheet1!$C$3:$CY$3,0))} -> 9.1 | DV31: 0.5 | DW31: =Euro_Area_Data!V28*10^9 -> #N/A | DX31: 1 | DY31: 0.5 | DZ31: {=INDEX([1]Sheet1!$C$6:$CY$72,MATCH($A31,[1]Sheet1!$A$6:$A$72,0),MATCH(MID(CELL("filename",BH30),FIND("]",CELL("filename",BH30))+1,255) & DZ$1,[1]Sheet1!$C$1:$CY$1 & [1]Sheet1!$C$3:$CY$3,0))} -> 8.56 | EA31: 2 | EE31: -5 | EH31: 0.75 | EI31: 0.05 | EJ31: 75 | EK31: =(EN31-EN30)/EN30*100 -> 3.7065091 | EN31: =[2]EUCAM_output!$AE28 -> 0.57613836
A32: 1992 | B32: =[2]EUCAM_output!$E29*10^9 -> 2.4625608e+11 | I32: =[2]EUCAM_output!$W29*10^3 -> 5950880.5 | K32: =IF(A32<2030,I32,K31*J32/J31) -> 5950880.5 | L32: =[2]EUCAM_output!$G29 -> 63.241038 | O32: =[2]EUCAM_output!$H29 -> 63.001847 | R32: =[2]EUCAM_output!$L29 -> 3.8 | U32: =[2]EUCAM_output!$K29 -> 3.871702 | V32: 3.871702 | W32: 0.016363086 | X32: -0.017672754 | Y32: =[2]EUCAM_output!$AI29 -> -0.0049583809 | Z32: =[2]EUCAM_output!$M29 -> 1803.8884 | AC32: =[2]EUCAM_output!$AL29 -> 1810.5278 | AD32: =[2]EUCAM_output!$T29*10^9 -> 7.6295222e+11 | AI32: =CH32/EN32 -> 9.8506862e+09 | AJ32: 4574640000 | AK32: =AJ32/EN32 -> 7.5594289e+09 | AM32: =AVERAGE($AL$35:$AL$63) -> 0.065166448 | AO32: 33706100000 | AP32: =AO32/EN32 -> 5.5698124e+10 | AQ32: 21956400000 | AR32: =(AQ32-AJ32)/EN32 -> 2.8722736e+10 | AT32: =AP32/B32*100 -> 22.617969 | BB32: 2.4819244e+11 | BC32: =[2]EUCAM_output!$AG29*10^9 -> 1.5517919e+11 | BD32: =(BB32-B32)/B32*100 -> 0.78632005 | CH32: {=INDEX([1]Sheet1!$C$6:$CY$72,MATCH($A32,[1]Sheet1!$A$6:$A$72,0),MATCH(MID(CELL("filename",O31),FIND("]",CELL("filename",O31))+1,255) & CH$1,[1]Sheet1!$C$1:$CY$1 & [1]Sheet1!$C$3:$CY$3,0))} -> 5961210000 | DQ32: 1.2981 | DR32: {=INDEX([1]Sheet1!$C$6:$CY$72,MATCH($A32,[1]Sheet1!$A$6:$A$72,0),MATCH(MID(CELL("filename",AZ31),FIND("]",CELL("filename",AZ31))+1,255) & DR$1,[1]Sheet1!$C$1:$CY$1 & [1]Sheet1!$C$3:$CY$3,0))} -> 0 | DS32: {=INDEX([1]Sheet1!$C$6:$CY$72,MATCH($A32,[1]Sheet1!$A$6:$A$72,0),MATCH(MID(CELL("filename",BA31),FIND("]",CELL("filename",BA31))+1,255) & DS$1,[1]Sheet1!$C$1:$CY$1 & [1]Sheet1!$C$3:$CY$3,0))} -> 0 | DU32: {=INDEX([1]Sheet1!$C$6:$CY$72,MATCH($A32,[1]Sheet1!$A$6:$A$72,0),MATCH(MID(CELL("filename",BC31),FIND("]",CELL("filename",BC31))+1,255) & DU$1,[1]Sheet1!$C$1:$CY$1 & [1]Sheet1!$C$3:$CY$3,0))} -> 9.32 | DV32: 0.5 | DW32: =Euro_Area_Data!V29*10^9 -> #N/A | DX32: 1 | DY32: 0.5 | DZ32: {=INDEX([1]Sheet1!$C$6:$CY$72,MATCH($A32,[1]Sheet1!$A$6:$A$72,0),MATCH(MID(CELL("filename",BH31),FIND("]",CELL("filename",BH31))+1,255) & DZ$1,[1]Sheet1!$C$1:$CY$1 & [1]Sheet1!$C$3:$CY$3,0))} -> 7.37 | EA32: 2 | EE32: -5 | EH32: 0.75 | EI32: 0.05 | EJ32: 75 | EK32: =(EN32-EN31)/EN31*100 -> 5.0367183 | EN32: =[2]EUCAM_output!$AE29 -> 0.60515683
A33: 1993 | B33: =[2]EUCAM_output!$E30*10^9 -> 2.5240638e+11 | I33: =[2]EUCAM_output!$W30*10^3 -> 6012349.5 | K33: =IF(A33<2030,I33,K32*J33/J32) -> 6012349.5 | L33: =[2]EUCAM_output!$G30 -> 62.581201 | O33: =[2]EUCAM_output!$H30 -> 62.858964 | R33: =[2]EUCAM_output!$L30 -> 4.3 | U33: =[2]EUCAM_output!$K30 -> 3.951558 | V33: 3.951558 | W33: 0.01073464 | X33: -0.014854452 | Y33: =[2]EUCAM_output!$AI30 -> -0.014813454 | Z33: =[2]EUCAM_output!$M30 -> 1801.25 | AC33: =[2]EUCAM_output!$AL30 -> 1805.4742 | AD33: =[2]EUCAM_output!$T30*10^9 -> 7.8362222e+11 | AI33: =CH33/EN33 -> 1.0491379e+10 | AJ33: 5051970000 | AK33: =AJ33/EN33 -> 7.7852832e+09 | AM33: =AVERAGE($AL$35:$AL$63) -> 0.065166448 | AO33: 35208200000 | AP33: =AO33/EN33 -> 5.4257212e+10 | AQ33: 23614800000 | AR33: =(AQ33-AJ33)/EN33 -> 2.8606046e+10 | AT33: =AP33/B33*100 -> 21.495975 | BB33: 2.4949994e+11 | BC33: =[2]EUCAM_output!$AG30*10^9 -> 1.6029765e+11 | BD33: =(BB33-B33)/B33*100 -> -1.1514924 | CH33: {=INDEX([1]Sheet1!$C$6:$CY$72,MATCH($A33,[1]Sheet1!$A$6:$A$72,0),MATCH(MID(CELL("filename",O32),FIND("]",CELL("filename",O32))+1,255) & CH$1,[1]Sheet1!$C$1:$CY$1 & [1]Sheet1!$C$3:$CY$3,0))} -> 6807990000 | DQ33: 1.171 | DR33: {=INDEX([1]Sheet1!$C$6:$CY$72,MATCH($A33,[1]Sheet1!$A$6:$A$72,0),MATCH(MID(CELL("filename",AZ32),FIND("]",CELL("filename",AZ32))+1,255) & DR$1,[1]Sheet1!$C$1:$CY$1 & [1]Sheet1!$C$3:$CY$3,0))} -> 0 | DS33: {=INDEX([1]Sheet1!$C$6:$CY$72,MATCH($A33,[1]Sheet1!$A$6:$A$72,0),MATCH(MID(CELL("filename",BA32),FIND("]",CELL("filename",BA32))+1,255) & DS$1,[1]Sheet1!$C$1:$CY$1 & [1]Sheet1!$C$3:$CY$3,0))} -> 0 | DU33: {=INDEX([1]Sheet1!$C$6:$CY$72,MATCH($A33,[1]Sheet1!$A$6:$A$72,0),MATCH(MID(CELL("filename",BC32),FIND("]",CELL("filename",BC32))+1,255) & DU$1,[1]Sheet1!$C$1:$CY$1 & [1]Sheet1!$C$3:$CY$3,0))} -> 7.23 | DV33: 0.5 | DW33: =Euro_Area_Data!V30*10^9 -> #N/A | DX33: 1 | DY33: 0.5 | DZ33: {=INDEX([1]Sheet1!$C$6:$CY$72,MATCH($A33,[1]Sheet1!$A$6:$A$72,0),MATCH(MID(CELL("filename",BH32),FIND("]",CELL("filename",BH32))+1,255) & DZ$1,[1]Sheet1!$C$1:$CY$1 & [1]Sheet1!$C$3:$CY$3,0))} -> 6.7 | EA33: 2 | EE33: -5 | EH33: 0.75 | EI33: 0.05 | EJ33: 75 | EK33: =(EN33-EN32)/EN32*100 -> 7.2305198 | EN33: =[2]EUCAM_output!$AE30 -> 0.64891281
A34: 1994 | B34: =[2]EUCAM_output!$E31*10^9 -> 2.5815899e+11 | I34: =[2]EUCAM_output!$W31*10^3 -> 6040309 | K34: =IF(A34<2030,I34,K33*J34/J33) -> 6040309 | L34: =[2]EUCAM_output!$G31 -> 62.474675 | O34: =[2]EUCAM_output!$H31 -> 62.749943 | R34: =[2]EUCAM_output!$L31 -> 4.6 | U34: =[2]EUCAM_output!$K31 -> 4.025289 | V34: 4.025289 | W34: 0.024229901 | X34: -0.017311854 | Y34: =[2]EUCAM_output!$AI31 -> -0.0054187832 | Z34: =[2]EUCAM_output!$M31 -> 1799.508 | AC34: =[2]EUCAM_output!$AL31 -> 1801.4142 | AD34: =[2]EUCAM_output!$T31*10^9 -> 8.0660424e+11 | AI34: =CH34/EN34 -> 1.0785486e+10 | AJ34: 5317520000 | AK34: =AJ34/EN34 -> 7.9432973e+09 | AM34: =AVERAGE($AL$35:$AL$63) -> 0.065166448 | AO34: 38255100000 | AP34: =AO34/EN34 -> 5.7145367e+10 | AQ34: 25827200000 | AR34: =(AQ34-AJ34)/EN34 -> 3.0637306e+10 | AT34: =AP34/B34*100 -> 22.135726 | BB34: 2.5549323e+11 | BC34: =[2]EUCAM_output!$AG31*10^9 -> 1.6829284e+11 | BD34: =(BB34-B34)/B34*100 -> -1.032604 | CH34: {=INDEX([1]Sheet1!$C$6:$CY$72,MATCH($A34,[1]Sheet1!$A$6:$A$72,0),MATCH(MID(CELL("filename",O33),FIND("]",CELL("filename",O33))+1,255) & CH$1,[1]Sheet1!$C$1:$CY$1 & [1]Sheet1!$C$3:$CY$3,0))} -> 7220180000 | DQ34: 1.18952 | DR34: {=INDEX([1]Sheet1!$C$6:$CY$72,MATCH($A34,[1]Sheet1!$A$6:$A$72,0),MATCH(MID(CELL("filename",AZ33),FIND("]",CELL("filename",AZ33))+1,255) & DR$1,[1]Sheet1!$C$1:$CY$1 & [1]Sheet1!$C$3:$CY$3,0))} -> 0 | DS34: {=INDEX([1]Sheet1!$C$6:$CY$72,MATCH($A34,[1]Sheet1!$A$6:$A$72,0),MATCH(MID(CELL("filename",BA33),FIND("]",CELL("filename",BA33))+1,255) & DS$1,[1]Sheet1!$C$1:$CY$1 & [1]Sheet1!$C$3:$CY$3,0))} -> 0 | DU34: {=INDEX([1]Sheet1!$C$6:$CY$72,MATCH($A34,[1]Sheet1!$A$6:$A$72,0),MATCH(MID(CELL("filename",BC33),FIND("]",CELL("filename",BC33))+1,255) & DU$1,[1]Sheet1!$C$1:$CY$1 & [1]Sheet1!$C$3:$CY$3,0))} -> 5.04 | DV34: 0.5 | DW34: =Euro_Area_Data!V31*10^9 -> #N/A | DX34: 1 | DY34: 0.5 | DZ34: {=INDEX([1]Sheet1!$C$6:$CY$72,MATCH($A34,[1]Sheet1!$A$6:$A$72,0),MATCH(MID(CELL("filename",BH33),FIND("]",CELL("filename",BH33))+1,255) & DZ$1,[1]Sheet1!$C$1:$CY$1 & [1]Sheet1!$C$3:$CY$3,0))} -> 7.03 | EA34: 2 | EE34: -5 | EH34: 0.75 | EI34: 0.05 | EJ34: 75 | EK34: =(EN34-EN33)/EN33*100 -> 3.1625255 | EN34: =[2]EUCAM_output!$AE31 -> 0.66943484
