Workbook

Sheet popproj
A1: date | B1: =[1]popt!C1 -> 2020 | C1: =[1]popt!D1 -> 2021 | D1: =[1]popt!E1 -> 2022 | E1: =[1]popt!F1 -> 2023 | F1: =[1]popt!G1 -> 2024 | G1: =[1]popt!H1 -> 2025 | H1: =[1]popt!I1 -> 2026 | I1: =[1]popt!J1 -> 2027 | ... AF1: =[1]popt!AG1 -> 2050
A2: =[1]popt!A2 -> BE_POPTF | E2: =VLOOKUP($A2,data_eurostat!$D$10:$AF$63,E$1-2021,0) -> 11742796 | F2: =VLOOKUP($A2,data_eurostat!$D$10:$AF$63,F$1-2021,0) -> 11832049 | G2: =VLOOKUP($A2,data_eurostat!$D$10:$AF$63,G$1-2021,0) -> 11911715 | H2: =VLOOKUP($A2,data_eurostat!$D$10:$AF$63,H$1-2021,0) -> 11964462 | I2: =VLOOKUP($A2,data_eurostat!$D$10:$AF$63,I$1-2021,0) -> 12010844 | J2: =VLOOKUP($A2,data_eurostat!$D$10:$AF$63,J$1-2021,0) -> 12050723 | K2: =VLOOKUP($A2,data_eurostat!$D$10:$AF$63,K$1-2021,0) -> 12088569 | L2: =VLOOKUP($A2,data_eurostat!$D$10:$AF$63,L$1-2021,0) -> 12125941 | ... AF2: =VLOOKUP($A2,data_eurostat!$D$10:$AF$63,AF$1-2021,0) -> 12673403
A3: =[1]popt!A3 -> BG_POPTF | E3: =VLOOKUP($A3,data_eurostat!$D$10:$AF$63,E$1-2021,0) -> 6544931 | F3: =VLOOKUP($A3,data_eurostat!$D$10:$AF$63,F$1-2021,0) -> 6499494 | G3: =VLOOKUP($A3,data_eurostat!$D$10:$AF$63,G$1-2021,0) -> 6487952 | H3: =VLOOKUP($A3,data_eurostat!$D$10:$AF$63,H$1-2021,0) -> 6453443 | I3: =VLOOKUP($A3,data_eurostat!$D$10:$AF$63,I$1-2021,0) -> 6415179 | J3: =VLOOKUP($A3,data_eurostat!$D$10:$AF$63,J$1-2021,0) -> 6372543 | K3: =VLOOKUP($A3,data_eurostat!$D$10:$AF$63,K$1-2021,0) -> 6330684 | L3: =VLOOKUP($A3,data_eurostat!$D$10:$AF$63,L$1-2021,0) -> 6288700 | ... AF3: =VLOOKUP($A3,data_eurostat!$D$10:$AF$63,AF$1-2021,0) -> 5601495
A4: =[1]popt!A4 -> CZ_POPTF | E4: =VLOOKUP($A4,data_eurostat!$D$10:$AF$63,E$1-2021,0) -> 10827529 | F4: =VLOOKUP($A4,data_eurostat!$D$10:$AF$63,F$1-2021,0) -> 10900555 | G4: =VLOOKUP($A4,data_eurostat!$D$10:$AF$63,G$1-2021,0) -> 10890826 | H4: =VLOOKUP($A4,data_eurostat!$D$10:$AF$63,H$1-2021,0) -> 10864885 | I4: =VLOOKUP($A4,data_eurostat!$D$10:$AF$63,I$1-2021,0) -> 10839981 | J4: =VLOOKUP($A4,data_eurostat!$D$10:$AF$63,J$1-2021,0) -> 10815675 | K4: =VLOOKUP($A4,data_eurostat!$D$10:$AF$63,K$1-2021,0) -> 10791798 | L4: =VLOOKUP($A4,data_eurostat!$D$10:$AF$63,L$1-2021,0) -> 10766896 | ... AF4: =VLOOKUP($A4,data_eurostat!$D$10:$AF$63,AF$1-2021,0) -> 10504795
A5: =[1]popt!A5 -> DK_POPTF | E5: =VLOOKUP($A5,data_eurostat!$D$10:$AF$63,E$1-2021,0) -> 5932654 | F5: =VLOOKUP($A5,data_eurostat!$D$10:$AF$63,F$1-2021,0) -> 5961249 | G5: =VLOOKUP($A5,data_eurostat!$D$10:$AF$63,G$1-2021,0) -> 5988583 | H5: =VLOOKUP($A5,data_eurostat!$D$10:$AF$63,H$1-2021,0) -> 6012733 | I5: =VLOOKUP($A5,data_eurostat!$D$10:$AF$63,I$1-2021,0) -> 6033979 | J5: =VLOOKUP($A5,data_eurostat!$D$10:$AF$63,J$1-2021,0) -> 6052294 | K5: =VLOOKUP($A5,data_eurostat!$D$10:$AF$63,K$1-2021,0) -> 6070553 | L5: =VLOOKUP($A5,data_eurostat!$D$10:$AF$63,L$1-2021,0) -> 6088094 | ... AF5: =VLOOKUP($A5,data_eurostat!$D$10:$AF$63,AF$1-2021,0) -> 6279381
A6: =[1]popt!A6 -> DE_POPTF | E6: =VLOOKUP($A6,data_eurostat!$D$10:$AF$63,E$1-2021,0) -> 83118501 | F6: =VLOOKUP($A6,data_eurostat!$D$10:$AF$63,F$1-2021,0) -> 83445000 | G6: =VLOOKUP($A6,data_eurostat!$D$10:$AF$63,G$1-2021,0) -> 83813997 | H6: =VLOOKUP($A6,data_eurostat!$D$10:$AF$63,H$1-2021,0) -> 83939569 | I6: =VLOOKUP($A6,data_eurostat!$D$10:$AF$63,I$1-2021,0) -> 83995717 | J6: =VLOOKUP($A6,data_eurostat!$D$10:$AF$63,J$1-2021,0) -> 83975579 | K6: =VLOOKUP($A6,data_eurostat!$D$10:$AF$63,K$1-2021,0) -> 83955036 | L6: =VLOOKUP($A6,data_eurostat!$D$10:$AF$63,L$1-2021,0) -> 83933644 | ... AF6: =VLOOKUP($A6,data_eurostat!$D$10:$AF$63,AF$1-2021,0) -> 83424094
A7: =[1]popt!A7 -> EE_POPTF | E7: =VLOOKUP($A7,data_eurostat!$D$10:$AF$63,E$1-2021,0) -> 1365884 | F7: =VLOOKUP($A7,data_eurostat!$D$10:$AF$63,F$1-2021,0) -> 1374687 | G7: =VLOOKUP($A7,data_eurostat!$D$10:$AF$63,G$1-2021,0) -> 1371536 | H7: =VLOOKUP($A7,data_eurostat!$D$10:$AF$63,H$1-2021,0) -> 1369302 | I7: =VLOOKUP($A7,data_eurostat!$D$10:$AF$63,I$1-2021,0) -> 1366422 | J7: =VLOOKUP($A7,data_eurostat!$D$10:$AF$63,J$1-2021,0) -> 1362876 | K7: =VLOOKUP($A7,data_eurostat!$D$10:$AF$63,K$1-2021,0) -> 1359329 | L7: =VLOOKUP($A7,data_eurostat!$D$10:$AF$63,L$1-2021,0) -> 1355793 | ... AF7: =VLOOKUP($A7,data_eurostat!$D$10:$AF$63,AF$1-2021,0) -> 1313669
A8: =[1]popt!A8 -> IE_POPTF | E8: =VLOOKUP($A8,data_eurostat!$D$10:$AF$63,E$1-2021,0) -> 5271395 | F8: =VLOOKUP($A8,data_eurostat!$D$10:$AF$63,F$1-2021,0) -> 5343805 | G8: =VLOOKUP($A8,data_eurostat!$D$10:$AF$63,G$1-2021,0) -> 5407528 | H8: =VLOOKUP($A8,data_eurostat!$D$10:$AF$63,H$1-2021,0) -> 5447903 | I8: =VLOOKUP($A8,data_eurostat!$D$10:$AF$63,I$1-2021,0) -> 5485591 | J8: =VLOOKUP($A8,data_eurostat!$D$10:$AF$63,J$1-2021,0) -> 5520536 | K8: =VLOOKUP($A8,data_eurostat!$D$10:$AF$63,K$1-2021,0) -> 5553828 | L8: =VLOOKUP($A8,data_eurostat!$D$10:$AF$63,L$1-2021,0) -> 5586364 | ... AF8: =VLOOKUP($A8,data_eurostat!$D$10:$AF$63,AF$1-2021,0) -> 6153874
A9: =[1]popt!A9 -> EL_POPTF | E9: =VLOOKUP($A9,data_eurostat!$D$10:$AF$63,E$1-2021,0) -> 10413982 | F9: =VLOOKUP($A9,data_eurostat!$D$10:$AF$63,F$1-2021,0) -> 10397193 | G9: =VLOOKUP($A9,data_eurostat!$D$10:$AF$63,G$1-2021,0) -> 10344746 | H9: =VLOOKUP($A9,data_eurostat!$D$10:$AF$63,H$1-2021,0) -> 10281050 | I9: =VLOOKUP($A9,data_eurostat!$D$10:$AF$63,I$1-2021,0) -> 10215575 | J9: =VLOOKUP($A9,data_eurostat!$D$10:$AF$63,J$1-2021,0) -> 10148648 | K9: =VLOOKUP($A9,data_eurostat!$D$10:$AF$63,K$1-2021,0) -> 10086609 | L9: =VLOOKUP($A9,data_eurostat!$D$10:$AF$63,L$1-2021,0) -> 10025864 | ... AF9: =VLOOKUP($A9,data_eurostat!$D$10:$AF$63,AF$1-2021,0) -> 8988949
A10: =[1]popt!A10 -> ES_POPTF | E10: =VLOOKUP($A10,data_eurostat!$D$10:$AF$63,E$1-2021,0) -> 48085361 | F10: =VLOOKUP($A10,data_eurostat!$D$10:$AF$63,F$1-2021,0) -> 48610458 | G10: =VLOOKUP($A10,data_eurostat!$D$10:$AF$63,G$1-2021,0) -> 49055897 | H10: =VLOOKUP($A10,data_eurostat!$D$10:$AF$63,H$1-2021,0) -> 49388542 | I10: =VLOOKUP($A10,data_eurostat!$D$10:$AF$63,I$1-2021,0) -> 49653994 | J10: =VLOOKUP($A10,data_eurostat!$D$10:$AF$63,J$1-2021,0) -> 49852117 | K10: =VLOOKUP($A10,data_eurostat!$D$10:$AF$63,K$1-2021,0) -> 50040564 | L10: =VLOOKUP($A10,data_eurostat!$D$10:$AF$63,L$1-2021,0) -> 50228237 | ... AF10: =VLOOKUP($A10,data_eurostat!$D$10:$AF$63,AF$1-2021,0) -> 52911773
A11: =[1]popt!A11 -> FR_POPTF | E11: =VLOOKUP($A11,data_eurostat!$D$10:$AF$63,E$1-2021,0) -> 68172977 | F11: =VLOOKUP($A11,data_eurostat!$D$10:$AF$63,F$1-2021,0) -> 68401997 | G11: =VLOOKUP($A11,data_eurostat!$D$10:$AF$63,G$1-2021,0) -> 68608043 | H11: =VLOOKUP($A11,data_eurostat!$D$10:$AF$63,H$1-2021,0) -> 68816000 | I11: =VLOOKUP($A11,data_eurostat!$D$10:$AF$63,I$1-2021,0) -> 69018296 | J11: =VLOOKUP($A11,data_eurostat!$D$10:$AF$63,J$1-2021,0) -> 69215616 | K11: =VLOOKUP($A11,data_eurostat!$D$10:$AF$63,K$1-2021,0) -> 69404727 | L11: =VLOOKUP($A11,data_eurostat!$D$10:$AF$63,L$1-2021,0) -> 69589304 | ... AF11: =VLOOKUP($A11,data_eurostat!$D$10:$AF$63,AF$1-2021,0) -> 72039010
A12: =[1]popt!A12 -> HR_POPTF | E12: =VLOOKUP($A12,data_eurostat!$D$10:$AF$63,E$1-2021,0) -> 3850894 | F12: =VLOOKUP($A12,data_eurostat!$D$10:$AF$63,F$1-2021,0) -> 3861967 | G12: =VLOOKUP($A12,data_eurostat!$D$10:$AF$63,G$1-2021,0) -> 3846017 | H12: =VLOOKUP($A12,data_eurostat!$D$10:$AF$63,H$1-2021,0) -> 3823802 | I12: =VLOOKUP($A12,data_eurostat!$D$10:$AF$63,I$1-2021,0) -> 3800359 | J12: =VLOOKUP($A12,data_eurostat!$D$10:$AF$63,J$1-2021,0) -> 3775435 | K12: =VLOOKUP($A12,data_eurostat!$D$10:$AF$63,K$1-2021,0) -> 3750966 | L12: =VLOOKUP($A12,data_eurostat!$D$10:$AF$63,L$1-2021,0) -> 3726678 | ... AF12: =VLOOKUP($A12,data_eurostat!$D$10:$AF$63,AF$1-2021,0) -> 3274676
A13: =[1]popt!A13 -> IT_POPTF | E13: =VLOOKUP($A13,data_eurostat!$D$10:$AF$63,E$1-2021,0) -> 58997201 | F13: =VLOOKUP($A13,data_eurostat!$D$10:$AF$63,F$1-2021,0) -> 58989749 | G13: =VLOOKUP($A13,data_eurostat!$D$10:$AF$63,G$1-2021,0) -> 58965448 | H13: =VLOOKUP($A13,data_eurostat!$D$10:$AF$63,H$1-2021,0) -> 58909795 | I13: =VLOOKUP($A13,data_eurostat!$D$10:$AF$63,I$1-2021,0) -> 58836452 | J13: =VLOOKUP($A13,data_eurostat!$D$10:$AF$63,J$1-2021,0) -> 58744103 | K13: =VLOOKUP($A13,data_eurostat!$D$10:$AF$63,K$1-2021,0) -> 58653817 | L13: =VLOOKUP($A13,data_eurostat!$D$10:$AF$63,L$1-2021,0) -> 58565206 | ... AF13: =VLOOKUP($A13,data_eurostat!$D$10:$AF$63,AF$1-2021,0) -> 55676723
... A28: =[1]popt!A28 -> SE_POPTF | E28: =VLOOKUP($A28,data_eurostat!$D$10:$AF$63,E$1-2021,0) -> 10558592 | F28: =VLOOKUP($A28,data_eurostat!$D$10:$AF$63,F$1-2021,0) -> 10586158 | G28: =VLOOKUP($A28,data_eurostat!$D$10:$AF$63,G$1-2021,0) -> 10647601 | H28: =VLOOKUP($A28,data_eurostat!$D$10:$AF$63,H$1-2021,0) -> 10709880 | I28: =VLOOKUP($A28,data_eurostat!$D$10:$AF$63,I$1-2021,0) -> 10773030 | J28: =VLOOKUP($A28,data_eurostat!$D$10:$AF$63,J$1-2021,0) -> 10836957 | K28: =VLOOKUP($A28,data_eurostat!$D$10:$AF$63,K$1-2021,0) -> 10898754 | L28: =VLOOKUP($A28,data_eurostat!$D$10:$AF$63,L$1-2021,0) -> 10958590 | ... AF28: =VLOOKUP($A28,data_eurostat!$D$10:$AF$63,AF$1-2021,0) -> 12035580
A29: UK_POPTF | E29: 68492495 | F29: 69226231 | G29: 69867979 | H29: 70414300 | I29: 70861913 | J29: 71208101 | K29: 71547662 | L29: 71879988 | M29: 72204574 | N29: 72521173 | O29: 72830021 | P29: 73131597 | Q29: 73426168 | R29: 73714089 | S29: 73995941 | T29: 74272334 | U29: 74543738 | V29: 74810478 | W29: 75072892 | X29: 75331209 | Y29: 75585236 | Z29: 75834507 | AA29: 76078686 | AB29: 76317480 | AC29: 76550535 | AD29: 76776460 | AE29: 76993637 | AF29: 77201483
A30: =[1]popa!A2 -> AT_POPAF | E30: =VLOOKUP($A30,data_eurostat!$D$10:$AF$63,E$1-2021,0) -> 6922716 | F30: =VLOOKUP($A30,data_eurostat!$D$10:$AF$63,F$1-2021,0) -> 6962381 | G30: =VLOOKUP($A30,data_eurostat!$D$10:$AF$63,G$1-2021,0) -> 6991767 | H30: =VLOOKUP($A30,data_eurostat!$D$10:$AF$63,H$1-2021,0) -> 7020736 | I30: =VLOOKUP($A30,data_eurostat!$D$10:$AF$63,I$1-2021,0) -> 7049453 | J30: =VLOOKUP($A30,data_eurostat!$D$10:$AF$63,J$1-2021,0) -> 7074267 | K30: =VLOOKUP($A30,data_eurostat!$D$10:$AF$63,K$1-2021,0) -> 7097713 | L30: =VLOOKUP($A30,data_eurostat!$D$10:$AF$63,L$1-2021,0) -> 7120512 | ... AF30: =VLOOKUP($A30,data_eurostat!$D$10:$AF$63,AF$1-2021,0) -> 7029086
A31: =[1]popa!A3 -> BE_POPAF | E31: =VLOOKUP($A31,data_eurostat!$D$10:$AF$63,E$1-2021,0) -> 8713622 | F31: =VLOOKUP($A31,data_eurostat!$D$10:$AF$63,F$1-2021,0) -> 8781869 | G31: =VLOOKUP($A31,data_eurostat!$D$10:$AF$63,G$1-2021,0) -> 8841283 | H31: =VLOOKUP($A31,data_eurostat!$D$10:$AF$63,H$1-2021,0) -> 8882325 | I31: =VLOOKUP($A31,data_eurostat!$D$10:$AF$63,I$1-2021,0) -> 8918000 | J31: =VLOOKUP($A31,data_eurostat!$D$10:$AF$63,J$1-2021,0) -> 8943923 | K31: =VLOOKUP($A31,data_eurostat!$D$10:$AF$63,K$1-2021,0) -> 8965183 | L31: =VLOOKUP($A31,data_eurostat!$D$10:$AF$63,L$1-2021,0) -> 8984021 | ... AF31: =VLOOKUP($A31,data_eurostat!$D$10:$AF$63,AF$1-2021,0) -> 8944746
A32: =[1]popa!A4 -> BG_POPAF | E32: =VLOOKUP($A32,data_eurostat!$D$10:$AF$63,E$1-2021,0) -> 4960389 | F32: =VLOOKUP($A32,data_eurostat!$D$10:$AF$63,F$1-2021,0) -> 4907337 | G32: =VLOOKUP($A32,data_eurostat!$D$10:$AF$63,G$1-2021,0) -> 4895085 | H32: =VLOOKUP($A32,data_eurostat!$D$10:$AF$63,H$1-2021,0) -> 4852191 | I32: =VLOOKUP($A32,data_eurostat!$D$10:$AF$63,I$1-2021,0) -> 4813316 | J32: =VLOOKUP($A32,data_eurostat!$D$10:$AF$63,J$1-2021,0) -> 4769502 | K32: =VLOOKUP($A32,data_eurostat!$D$10:$AF$63,K$1-2021,0) -> 4725757 | L32: =VLOOKUP($A32,data_eurostat!$D$10:$AF$63,L$1-2021,0) -> 4686503 | ... AF32: =VLOOKUP($A32,data_eurostat!$D$10:$AF$63,AF$1-2021,0) -> 3945835
A33: =[1]popa!A5 -> CY_POPAF | E33: =VLOOKUP($A33,data_eurostat!$D$10:$AF$63,E$1-2021,0) -> 706207 | F33: =VLOOKUP($A33,data_eurostat!$D$10:$AF$63,F$1-2021,0) -> 713963 | G33: =VLOOKUP($A33,data_eurostat!$D$10:$AF$63,G$1-2021,0) -> 719014 | H33: =VLOOKUP($A33,data_eurostat!$D$10:$AF$63,H$1-2021,0) -> 719995 | I33: =VLOOKUP($A33,data_eurostat!$D$10:$AF$63,I$1-2021,0) -> 720509 | J33: =VLOOKUP($A33,data_eurostat!$D$10:$AF$63,J$1-2021,0) -> 721402 | K33: =VLOOKUP($A33,data_eurostat!$D$10:$AF$63,K$1-2021,0) -> 721851 | L33: =VLOOKUP($A33,data_eurostat!$D$10:$AF$63,L$1-2021,0) -> 722527 | ... AF33: =VLOOKUP($A33,data_eurostat!$D$10:$AF$63,AF$1-2021,0) -> 730542
A34: =[1]popa!A6 -> CZ_POPAF | E34: =VLOOKUP($A34,data_eurostat!$D$10:$AF$63,E$1-2021,0) -> 8134790 | F34: =VLOOKUP($A34,data_eurostat!$D$10:$AF$63,F$1-2021,0) -> 8128502 | G34: =VLOOKUP($A34,data_eurostat!$D$10:$AF$63,G$1-2021,0) -> 8113346 | H34: =VLOOKUP($A34,data_eurostat!$D$10:$AF$63,H$1-2021,0) -> 8084439 | I34: =VLOOKUP($A34,data_eurostat!$D$10:$AF$63,I$1-2021,0) -> 8049524 | J34: =VLOOKUP($A34,data_eurostat!$D$10:$AF$63,J$1-2021,0) -> 8018625 | K34: =VLOOKUP($A34,data_eurostat!$D$10:$AF$63,K$1-2021,0) -> 7990724 | L34: =VLOOKUP($A34,data_eurostat!$D$10:$AF$63,L$1-2021,0) -> 7967838 | ... AF34: =VLOOKUP($A34,data_eurostat!$D$10:$AF$63,AF$1-2021,0) -> 7519955
A35: =[1]popa!A7 -> DE_POPAF | E35: =VLOOKUP($A35,data_eurostat!$D$10:$AF$63,E$1-2021,0) -> 62375443 | F35: =VLOOKUP($A35,data_eurostat!$D$10:$AF$63,F$1-2021,0) -> 62623030 | G35: =VLOOKUP($A35,data_eurostat!$D$10:$AF$63,G$1-2021,0) -> 62827058 | H35: =VLOOKUP($A35,data_eurostat!$D$10:$AF$63,H$1-2021,0) -> 62822509 | I35: =VLOOKUP($A35,data_eurostat!$D$10:$AF$63,I$1-2021,0) -> 62760002 | J35: =VLOOKUP($A35,data_eurostat!$D$10:$AF$63,J$1-2021,0) -> 62649872 | K35: =VLOOKUP($A35,data_eurostat!$D$10:$AF$63,K$1-2021,0) -> 62554857 | L35: =VLOOKUP($A35,data_eurostat!$D$10:$AF$63,L$1-2021,0) -> 62470615 | ... AF35: =VLOOKUP($A35,data_eurostat!$D$10:$AF$63,AF$1-2021,0) -> 59193299
A36: =[1]popa!A8 -> DK_POPAF | E36: =VLOOKUP($A36,data_eurostat!$D$10:$AF$63,E$1-2021,0) -> 4396013 | F36: =VLOOKUP($A36,data_eurostat!$D$10:$AF$63,F$1-2021,0) -> 4412392 | G36: =VLOOKUP($A36,data_eurostat!$D$10:$AF$63,G$1-2021,0) -> 4429113 | H36: =VLOOKUP($A36,data_eurostat!$D$10:$AF$63,H$1-2021,0) -> 4441187 | I36: =VLOOKUP($A36,data_eurostat!$D$10:$AF$63,I$1-2021,0) -> 4448394 | J36: =VLOOKUP($A36,data_eurostat!$D$10:$AF$63,J$1-2021,0) -> 4451598 | K36: =VLOOKUP($A36,data_eurostat!$D$10:$AF$63,K$1-2021,0) -> 4452236 | L36: =VLOOKUP($A36,data_eurostat!$D$10:$AF$63,L$1-2021,0) -> 4454833 | ... AF36: =VLOOKUP($A36,data_eurostat!$D$10:$AF$63,AF$1-2021,0) -> 4436784
A37: =[1]popa!A9 -> EE_POPAF | E37: =VLOOKUP($A37,data_eurostat!$D$10:$AF$63,E$1-2021,0) -> 1015410 | F37: =VLOOKUP($A37,data_eurostat!$D$10:$AF$63,F$1-2021,0) -> 1033559 | G37: =VLOOKUP($A37,data_eurostat!$D$10:$AF$63,G$1-2021,0) -> 1033272 | H37: =VLOOKUP($A37,data_eurostat!$D$10:$AF$63,H$1-2021,0) -> 1033870 | I37: =VLOOKUP($A37,data_eurostat!$D$10:$AF$63,I$1-2021,0) -> 1032421 | J37: =VLOOKUP($A37,data_eurostat!$D$10:$AF$63,J$1-2021,0) -> 1030143 | K37: =VLOOKUP($A37,data_eurostat!$D$10:$AF$63,K$1-2021,0) -> 1027796 | L37: =VLOOKUP($A37,data_eurostat!$D$10:$AF$63,L$1-2021,0) -> 1024866 | ... AF37: =VLOOKUP($A37,data_eurostat!$D$10:$AF$63,AF$1-2021,0) -> 952094
A38: =[1]popa!A10 -> EL_POPAF | E38: =VLOOKUP($A38,data_eurostat!$D$10:$AF$63,E$1-2021,0) -> 7813497 | F38: =VLOOKUP($A38,data_eurostat!$D$10:$AF$63,F$1-2021,0) -> 7750993 | G38: =VLOOKUP($A38,data_eurostat!$D$10:$AF$63,G$1-2021,0) -> 7738963 | H38: =VLOOKUP($A38,data_eurostat!$D$10:$AF$63,H$1-2021,0) -> 7705742 | I38: =VLOOKUP($A38,data_eurostat!$D$10:$AF$63,I$1-2021,0) -> 7661805 | J38: =VLOOKUP($A38,data_eurostat!$D$10:$AF$63,J$1-2021,0) -> 7615175 | K38: =VLOOKUP($A38,data_eurostat!$D$10:$AF$63,K$1-2021,0) -> 7567476 | L38: =VLOOKUP($A38,data_eurostat!$D$10:$AF$63,L$1-2021,0) -> 7515730 | ... AF38: =VLOOKUP($A38,data_eurostat!$D$10:$AF$63,AF$1-2021,0) -> 6148828
A39: =[1]popa!A11 -> ES_POPAF | E39: =VLOOKUP($A39,data_eurostat!$D$10:$AF$63,E$1-2021,0) -> 36763280 | F39: =VLOOKUP($A39,data_eurostat!$D$10:$AF$63,F$1-2021,0) -> 37243770 | G39: =VLOOKUP($A39,data_eurostat!$D$10:$AF$63,G$1-2021,0) -> 37655415 | H39: =VLOOKUP($A39,data_eurostat!$D$10:$AF$63,H$1-2021,0) -> 37992409 | I39: =VLOOKUP($A39,data_eurostat!$D$10:$AF$63,I$1-2021,0) -> 38258690 | J39: =VLOOKUP($A39,data_eurostat!$D$10:$AF$63,J$1-2021,0) -> 38436036 | K39: =VLOOKUP($A39,data_eurostat!$D$10:$AF$63,K$1-2021,0) -> 38578198 | L39: =VLOOKUP($A39,data_eurostat!$D$10:$AF$63,L$1-2021,0) -> 38727824 | ... AF39: =VLOOKUP($A39,data_eurostat!$D$10:$AF$63,AF$1-2021,0) -> 37215753
A40: =[1]popa!A12 -> FI_POPAF | E40: =VLOOKUP($A40,data_eurostat!$D$10:$AF$63,E$1-2021,0) -> 4149181 | F40: =VLOOKUP($A40,data_eurostat!$D$10:$AF$63,F$1-2021,0) -> 4170087 | G40: =VLOOKUP($A40,data_eurostat!$D$10:$AF$63,G$1-2021,0) -> 4185099 | H40: =VLOOKUP($A40,data_eurostat!$D$10:$AF$63,H$1-2021,0) -> 4186151 | I40: =VLOOKUP($A40,data_eurostat!$D$10:$AF$63,I$1-2021,0) -> 4187385 | J40: =VLOOKUP($A40,data_eurostat!$D$10:$AF$63,J$1-2021,0) -> 4185442 | K40: =VLOOKUP($A40,data_eurostat!$D$10:$AF$63,K$1-2021,0) -> 4185124 | L40: =VLOOKUP($A40,data_eurostat!$D$10:$AF$63,L$1-2021,0) -> 4183674 | ... AF40: =VLOOKUP($A40,data_eurostat!$D$10:$AF$63,AF$1-2021,0) -> 4083937
A41: =[1]popa!A13 -> FR_POPAF | E41: =VLOOKUP($A41,data_eurostat!$D$10:$AF$63,E$1-2021,0) -> 49563406 | F41: =VLOOKUP($A41,data_eurostat!$D$10:$AF$63,F$1-2021,0) -> 49648358 | G41: =VLOOKUP($A41,data_eurostat!$D$10:$AF$63,G$1-2021,0) -> 49690277 | H41: =VLOOKUP($A41,data_eurostat!$D$10:$AF$63,H$1-2021,0) -> 49743822 | I41: =VLOOKUP($A41,data_eurostat!$D$10:$AF$63,I$1-2021,0) -> 49808515 | J41: =VLOOKUP($A41,data_eurostat!$D$10:$AF$63,J$1-2021,0) -> 49859159 | K41: =VLOOKUP($A41,data_eurostat!$D$10:$AF$63,K$1-2021,0) -> 49912125 | L41: =VLOOKUP($A41,data_eurostat!$D$10:$AF$63,L$1-2021,0) -> 49954347 | ... AF41: =VLOOKUP($A41,data_eurostat!$D$10:$AF$63,AF$1-2021,0) -> 48962176
... A56: =[1]popa!A28 -> SK_POPAF | E56: =VLOOKUP($A56,data_eurostat!$D$10:$AF$63,E$1-2021,0) -> 4252471 | F56: =VLOOKUP($A56,data_eurostat!$D$10:$AF$63,F$1-2021,0) -> 4256899 | G56: =VLOOKUP($A56,data_eurostat!$D$10:$AF$63,G$1-2021,0) -> 4262264 | H56: =VLOOKUP($A56,data_eurostat!$D$10:$AF$63,H$1-2021,0) -> 4239474 | I56: =VLOOKUP($A56,data_eurostat!$D$10:$AF$63,I$1-2021,0) -> 4214452 | J56: =VLOOKUP($A56,data_eurostat!$D$10:$AF$63,J$1-2021,0) -> 4190166 | K56: =VLOOKUP($A56,data_eurostat!$D$10:$AF$63,K$1-2021,0) -> 4166475 | L56: =VLOOKUP($A56,data_eurostat!$D$10:$AF$63,L$1-2021,0) -> 4143189 | ... AF56: =VLOOKUP($A56,data_eurostat!$D$10:$AF$63,AF$1-2021,0) -> 3746995
A57: UK_POPAF | E57: 50606052 | F57: 51230433 | G57: 51803494 | H57: 52320910 | I57: 52765493 | J57: 53094557 | K57: 53400737 | L57: 53708568 | M57: 54004079 | N57: 54259159 | O57: 54474769 | P57: 54669087 | Q57: 54837213 | R57: 54961225 | S57: 55069694 | T57: 55129348 | U57: 55174238 | V57: 55216594 | W57: 55269662 | X57: 55324912 | Y57: 55388768 | Z57: 55454807 | AA57: 55541235 | AB57: 55612095 | AC57: 55713036 | AD57: 55842438 | AE57: 55999658 | AF57: 56166308
A58: US_POPTF | E58: 334906305 | F58: 336482168 | G58: 338016259 | H58: 339513045 | I58: 340970496 | J58: 342384777 | K58: 343753791 | L58: 345073565 | M58: 346339264 | N58: 347545098 | O58: 348701812 | P58: 349807647 | Q58: 350861084 | R58: 351860944 | S58: 352806047 | T58: 353695674 | U58: 354529853 | V58: 355309062 | W58: 356033543 | X58: 356705435 | Y58: 357327409 | Z58: 357903394 | AA58: 358437973 | AB58: 358935938 | AC58: 359400325 | AD58: 359835763 | AE58: 360246998 | AF58: 360638734
A59: US_POPAF | E59: 250897599 | F59: 251802668 | G59: 252615050 | H59: 253281965 | I59: 253832033 | J59: 254328551 | K59: 254773384 | L59: 255179717 | M59: 255535040 | N59: 255693830 | O59: 255780115 | P59: 255813715 | Q59: 255792929 | R59: 255663572 | S59: 255674341 | T59: 255702030 | U59: 255775146 | V59: 255966573 | W59: 256315339 | X59: 256737012 | Y59: 257195478 | Z59: 257607729 | AA59: 257920825 | AB59: 258206100 | AC59: 258698158 | AD59: 259346509 | AE59: 260038055 | AF59: 260673802

Sheet Sheet1
A1: YEAR | B1: US_POPTF | C1: US_POPAF
A2: 2016 | B2: 323127513 | C2: 241538579
A3: 2017 | B3: 325511184 | C3: 243253958
A4: 2018 | B4: 327891911 | C4: 244741701
A5: 2019 | B5: 330268840 | C5: 246364915
A6: 2020 | B6: 332639102 | C6: 247968047
A7: 2021 | B7: 334998398 | C7: 249598423
A8: 2022 | B8: 337341954 | C8: 250528351
A9: 2023 | B9: 339665118 | C9: 251622650
A10: 2024 | B10: 341963408 | C10: 252613076
A11: 2025 | B11: 344234377 | C11: 253570527
A12: 2026 | B12: 346481182 | C12: 254515348
A13: 2027 | B13: 348695115 | C13: 255371874
... A46: 2060 | B46: 404483055 | C46: 287265482

Sheet old
A1: SF22 | B1: 2020 | C1: 2021 | D1: 2022 | E1: 2023 | F1: 2024 | G1: 2025 | H1: 2026 | I1: 2027 | J1: 2028 | K1: 2029 | L1: 2030 | M1: 2031 | N1: 2032 | O1: 2033 | P1: 2034 | Q1: 2035 | R1: 2036 | S1: 2037 | T1: 2038 | U1: 2039 | V1: 2040 | W1: 2041 | X1: 2042 | Y1: 2043 | Z1: 2044 | AA1: 2045 | AB1: 2046 | AC1: 2047 | AD1: 2048 | AE1: 2049 | AF1: 2050 | AG1: 2051 | AH1: 2052 | AI1: 2053 | AJ1: 2054 | AK1: 2055 | AL1: 2056 | AM1: 2057 | AN1: 2058 | AO1: 2059 | AP1: 2060 | AQ1: 2061 | AR1: 2062 | AS1: 2063 | AT1: 2064 | AU1: 2065 | AV1: 2066 | AW1: 2067 | AX1: 2068 | AY1: 2069 | AZ1: 2070 | BA1: 2071 | BB1: 2072 | BC1: 2073 | BD1: 2074 | BE1: 2075 | BF1: 2076 | BG1: 2077 | BH1: 2078 | BI1: 2079 | BJ1: 2080 | BK1: 2081 | BL1: 2082 | BM1: 2083 | BN1: 2084 | BO1: 2085
A2: BE_POPTF | D2: 11617623 | E2: 11730662 | F2: 11789713 | G2: 11829411 | H2: 11867591 | I2: 11904193 | J2: 11939128 | K2: 11974068 | L2: 12009045 | M2: 12043620 | N2: 12077617 | O2: 12111191 | P2: 12144363 | Q2: 12179830 | R2: 12214931 | S2: 12248705 | T2: 12281680 | U2: 12313370 | V2: 12343820 | W2: 12372923 | X2: 12400520 | Y2: 12426469 | Z2: 12450782 | AA2: 12473485 | AB2: 12494640 | AC2: 12513752 | AD2: 12530891 | AE2: 12545914 | AF2: 12559197 | AG2: 12570761 | AH2: 12581004 | AI2: 12589870 | AJ2: 12597856 | AK2: 12604824 | AL2: 12611231 | AM2: 12617107 | AN2: 12622480 | AO2: 12627303 | AP2: 12631664 | AQ2: 12636103 | AR2: 12640805 | AS2: 12645800 | AT2: 12650972 | AU2: 12656450 | AV2: 12662438 | AW2: 12668438 | AX2: 12674489 | AY2: 12680664 | AZ2: 12687096 | BA2: 12693582 | BB2: 12700043 | BC2: 12706144 | BD2: 12711980 | BE2: 12717035 | BF2: 12721437 | BG2: 12724744 | BH2: 12726961 | BI2: 12727913 | BJ2: 12727839 | BK2: 12726444 | BL2: 12723966 | BM2: 12720261 | BN2: 12715529 | BO2: 12709791
A3: BG_POPTF | D3: 6838937 | E3: 6941042 | F3: 6918672 | G3: 6860349 | H3: 6802438 | I3: 6744339 | J3: 6685753 | K3: 6629192 | L3: 6574153 | M3: 6520799 | N3: 6469093 | O3: 6419371 | P3: 6372608 | Q3: 6333689 | R3: 6295791 | S3: 6258695 | T3: 6222478 | U3: 6188057 | V3: 6155181 | W3: 6123000 | X3: 6091727 | Y3: 6061097 | Z3: 6030905 | AA3: 6001378 | AB3: 5971941 | AC3: 5942884 | AD3: 5914113 | AE3: 5885720 | AF3: 5857619 | AG3: 5829653 | AH3: 5802057 | AI3: 5774417 | AJ3: 5747135 | AK3: 5719739 | AL3: 5692072 | AM3: 5663896 | AN3: 5635318 | AO3: 5606566 | AP3: 5577599 | AQ3: 5548327 | AR3: 5519364 | AS3: 5490261 | AT3: 5461787 | AU3: 5434519 | AV3: 5407825 | AW3: 5381520 | AX3: 5355969 | AY3: 5331321 | AZ3: 5307774 | BA3: 5285325 | BB3: 5263974 | BC3: 5243725 | BD3: 5224730 | BE3: 5207097 | BF3: 5190244 | BG3: 5174411 | BH3: 5159594 | BI3: 5145717 | BJ3: 5133224 | BK3: 5121743 | BL3: 5111421 | BM3: 5102175 | BN3: 5093994 | BO3: 5086931
A4: CZ_POPTF | D4: 10516707 | E4: 10963888 | F4: 11049464 | G4: 11017341 | H4: 10984063 | I4: 10950186 | J4: 10914981 | K4: 10882453 | L4: 10851301 | M4: 10820816 | N4: 10791009 | O4: 10762565 | P4: 10735818 | Q4: 10728942 | R4: 10723210 | S4: 10718041 | T4: 10715647 | U4: 10715072 | V4: 10716445 | W4: 10718698 | X4: 10721656 | Y4: 10725079 | Z4: 10729080 | AA4: 10733221 | AB4: 10736500 | AC4: 10739354 | AD4: 10742301 | AE4: 10744955 | AF4: 10747331 | AG4: 10749229 | AH4: 10750188 | AI4: 10750103 | AJ4: 10749615 | AK4: 10747298 | AL4: 10743901 | AM4: 10739096 | AN4: 10732283 | AO4: 10724053 | AP4: 10713330 | AQ4: 10701227 | AR4: 10687990 | AS4: 10673795 | AT4: 10658868 | AU4: 10643474 | AV4: 10627866 | AW4: 10612344 | AX4: 10597167 | AY4: 10582613 | AZ4: 10568913 | BA4: 10556713 | BB4: 10546115 | BC4: 10537745 | BD4: 10531463 | BE4: 10526487 | BF4: 10523131 | BG4: 10520575 | BH4: 10519397 | BI4: 10519352 | BJ4: 10520741 | BK4: 10523190 | BL4: 10526760 | BM4: 10531115 | BN4: 10536140 | BO4: 10541581
A5: DK_POPTF | D5: 5873420 | E5: 5927971 | F5: 5959324 | G5: 5979924 | H5: 5998728 | I5: 6015778 | J5: 6030799 | K5: 6045664 | L5: 6059699 | M5: 6072787 | N5: 6084707 | O5: 6094990 | P5: 6103659 | Q5: 6112281 | R5: 6119841 | S5: 6126427 | T5: 6132658 | U5: 6137167 | V5: 6140844 | W5: 6143867 | X5: 6145947 | Y5: 6147433 | Z5: 6148485 | AA5: 6149190 | AB5: 6149637 | AC5: 6149902 | AD5: 6150023 | AE5: 6150065 | AF5: 6150048 | AG5: 6150086 | AH5: 6150233 | AI5: 6150611 | AJ5: 6151463 | AK5: 6152708 | AL5: 6154374 | AM5: 6156225 | AN5: 6158510 | AO5: 6160870 | AP5: 6163606 | AQ5: 6166409 | AR5: 6169084 | AS5: 6171775 | AT5: 6174342 | AU5: 6176804 | AV5: 6179236 | AW5: 6181224 | AX5: 6182924 | AY5: 6184563 | AZ5: 6186068 | BA5: 6187363 | BB5: 6188499 | BC5: 6189318 | BD5: 6189992 | BE5: 6190185 | BF5: 6190109 | BG5: 6189285 | BH5: 6188033 | BI5: 6186313 | BJ5: 6184150 | BK5: 6181613 | BL5: 6179001 | BM5: 6175968 | BN5: 6172601 | BO5: 6168918
A6: DE_POPTF | D6: 83237124 | E6: 84551929 | F6: 85041941 | G6: 85207514 | H6: 85309747 | I6: 85351038 | J6: 85324918 | K6: 85304262 | L6: 85284256 | M6: 85263378 | N6: 85242159 | O6: 85221140 | P6: 85200309 | Q6: 85216229 | R6: 85222956 | S6: 85222134 | T6: 85214796 | U6: 85201421 | V6: 85183945 | W6: 85161965 | X6: 85135219 | Y6: 85104193 | Z6: 85069388 | AA6: 85031168 | AB6: 84994058 | AC6: 84953444 | AD6: 84910816 | AE6: 84863602 | AF6: 84813866 | AG6: 84762803 | AH6: 84713028 | AI6: 84664073 | AJ6: 84617558 | AK6: 84569064 | AL6: 84523578 | AM6: 84472323 | AN6: 84421998 | AO6: 84375463 | AP6: 84332583 | AQ6: 84295878 | AR6: 84268651 | AS6: 84250509 | AT6: 84236965 | AU6: 84229131 | AV6: 84227028 | AW6: 84226221 | AX6: 84227558 | AY6: 84230483 | AZ6: 84234786 | BA6: 84239057 | BB6: 84241672 | BC6: 84242757 | BD6: 84241664 | BE6: 84235857 | BF6: 84228074 | BG6: 84215797 | BH6: 84202668 | BI6: 84188020 | BJ6: 84174853 | BK6: 84161973 | BL6: 84151712 | BM6: 84141472 | BN6: 84131834 | BO6: 84122425
A7: EE_POPTF | D7: 1331796 | E7: 1371817 | F7: 1380158 | G7: 1377519 | H7: 1374354 | I7: 1370686 | J7: 1366487 | K7: 1362440 | L7: 1358611 | M7: 1354919 | N7: 1351464 | O7: 1348287 | P7: 1345410 | Q7: 1344440 | R7: 1343742 | S7: 1343195 | T7: 1342917 | U7: 1342596 | V7: 1342365 | W7: 1342193 | X7: 1342075 | Y7: 1341983 | Z7: 1341849 | AA7: 1341698 | AB7: 1341520 | AC7: 1341293 | AD7: 1341001 | AE7: 1340698 | AF7: 1340292 | AG7: 1339770 | AH7: 1339162 | AI7: 1338517 | AJ7: 1337827 | AK7: 1336995 | AL7: 1335974 | AM7: 1334669 | AN7: 1333247 | AO7: 1331575 | AP7: 1329771 | AQ7: 1327870 | AR7: 1325957 | AS7: 1323973 | AT7: 1321991 | AU7: 1319996 | AV7: 1318041 | AW7: 1316075 | AX7: 1314135 | AY7: 1312225 | AZ7: 1310424 | BA7: 1308733 | BB7: 1307120 | BC7: 1305614 | BD7: 1304183 | BE7: 1302767 | BF7: 1301406 | BG7: 1299986 | BH7: 1298562 | BI7: 1297149 | BJ7: 1295795 | BK7: 1294533 | BL7: 1293365 | BM7: 1292245 | BN7: 1291303 | BO7: 1290471
A8: IE_POPTF | D8: 5060004 | E8: 5174288 | F8: 5225872 | G8: 5257383 | H8: 5289027 | I8: 5320882 | J8: 5353001 | K8: 5384987 | L8: 5416927 | M8: 5448839 | N8: 5480752 | O8: 5512649 | P8: 5544510 | Q8: 5579300 | R8: 5613640 | S8: 5647461 | T8: 5680696 | U8: 5713719 | V8: 5746237 | W8: 5778101 | X8: 5809118 | Y8: 5839214 | Z8: 5868260 | AA8: 5896376 | AB8: 5922998 | AC8: 5947651 | AD8: 5970284 | AE8: 5990781 | AF8: 6009043 | AG8: 6025282 | AH8: 6039347 | AI8: 6051381 | AJ8: 6061631 | AK8: 6070015 | AL8: 6076778 | AM8: 6081984 | AN8: 6085790 | AO8: 6088310 | AP8: 6089682 | AQ8: 6090048 | AR8: 6089576 | AS8: 6088758 | AT8: 6087491 | AU8: 6085867 | AV8: 6083927 | AW8: 6081835 | AX8: 6079653 | AY8: 6077389 | AZ8: 6075058 | BA8: 6072792 | BB8: 6070637 | BC8: 6068857 | BD8: 6067237 | BE8: 6065588 | BF8: 6063908 | BG8: 6062034 | BH8: 6059810 | BI8: 6057208 | BJ8: 6054127 | BK8: 6050632 | BL8: 6046840 | BM8: 6042601 | BN8: 6037760 | BO8: 6032265
A9: EL_POPTF | D9: 10459782 | E9: 10416542 | F9: 10371572 | G9: 10320364 | H9: 10266269 | I9: 10209059 | J9: 10149281 | K9: 10090457 | L9: 10032545 | M9: 9975534 | N9: 9919670 | O9: 9865215 | P9: 9811524 | Q9: 9758893 | R9: 9706313 | S9: 9653946 | T9: 9602624 | U9: 9551283 | V9: 9500551 | W9: 9449830 | X9: 9399068 | Y9: 9347774 | Z9: 9296025 | AA9: 9243610 | AB9: 9190441 | AC9: 9135766 | AD9: 9080046 | AE9: 9023227 | AF9: 8964997 | AG9: 8905511 | AH9: 8844943 | AI9: 8783471 | AJ9: 8721823 | AK9: 8659463 | AL9: 8597149 | AM9: 8534668 | AN9: 8472324 | AO9: 8410131 | AP9: 8348550 | AQ9: 8287694 | AR9: 8227626 | AS9: 8168549 | AT9: 8110570 | AU9: 8053878 | AV9: 7998997 | AW9: 7945854 | AX9: 7894744 | AY9: 7845709 | AZ9: 7798839 | BA9: 7754493 | BB9: 7712682 | BC9: 7673456 | BD9: 7637089 | BE9: 7603245 | BF9: 7571611 | BG9: 7541939 | BH9: 7514507 | BI9: 7489004 | BJ9: 7465776 | BK9: 7444785 | BL9: 7425902 | BM9: 7408778 | BN9: 7393506 | BO9: 7379838
A10: ES_POPTF | D10: 47432893 | E10: 47980384 | F10: 48346319 | G10: 48614060 | H10: 48822977 | I10: 48973279 | J10: 49069647 | K10: 49167929 | L10: 49266930 | M10: 49363835 | N10: 49460401 | O10: 49558800 | P10: 49656906 | Q10: 49760920 | R10: 49863657 | S10: 49963357 | T10: 50059915 | U10: 50151068 | V10: 50237193 | W10: 50316009 | X10: 50386688 | Y10: 50446259 | Z10: 50494168 | AA10: 50527425 | AB10: 50546422 | AC10: 50549427 | AD10: 50536302 | AE10: 50506074 | AF10: 50460161 | AG10: 50398375 | AH10: 50321260 | AI10: 50229855 | AJ10: 50125793 | AK10: 50009648 | AL10: 49882766 | AM10: 49746489 | AN10: 49603252 | AO10: 49452799 | AP10: 49296369 | AQ10: 49136315 | AR10: 48974497 | AS10: 48812479 | AT10: 48650472 | AU10: 48491039 | AV10: 48334959 | AW10: 48182062 | AX10: 48033330 | AY10: 47890985 | AZ10: 47754790 | BA10: 47624951 | BB10: 47502401 | BC10: 47386924 | BD10: 47280333 | BE10: 47178564 | BF10: 47083172 | BG10: 46994389 | BH10: 46910698 | BI10: 46830839 | BJ10: 46756869 | BK10: 46686758 | BL10: 46619145 | BM10: 46551977 | BN10: 46484009 | BO10: 46415099
A11: FR_POPTF | D11: 67871925 | E11: 68227636 | F11: 68467799 | G11: 68658223 | H11: 68828579 | I11: 68981139 | J11: 69115954 | K11: 69251760 | L11: 69386211 | M11: 69519142 | N11: 69650285 | O11: 69777352 | P11: 69901472 | Q11: 70026306 | R11: 70146754 | S11: 70260672 | T11: 70361168 | U11: 70451362 | V11: 70527060 | W11: 70587568 | X11: 70634002 | Y11: 70670568 | Z11: 70695165 | AA11: 70709758 | AB11: 70717939 | AC11: 70714336 | AD11: 70700903 | AE11: 70674366 | AF11: 70641762 | AG11: 70603509 | AH11: 70560384 | AI11: 70511976 | AJ11: 70460377 | AK11: 70405341 | AL11: 70348454 | AM11: 70289005 | AN11: 70228598 | AO11: 70166118 | AP11: 70104683 | AQ11: 70046545 | AR11: 69991349 | AS11: 69938547 | AT11: 69889952 | AU11: 69844912 | AV11: 69807421 | AW11: 69771572 | AX11: 69737651 | AY11: 69705215 | AZ11: 69674928 | BA11: 69645712 | BB11: 69618102 | BC11: 69588975 | BD11: 69559535 | BE11: 69528454 | BF11: 69496450 | BG11: 69460178 | BH11: 69420996 | BI11: 69377820 | BJ11: 69331696 | BK11: 69280933 | BL11: 69226563 | BM11: 69168739 | BN11: 69108424 | BO11: 69046355
A12: HR_POPTF | D12: 3862305 | E12: 3854381 | F12: 3834008 | G12: 3810628 | H12: 3788113 | I12: 3766531 | J12: 3734553 | K12: 3713774 | L12: 3693206 | M12: 3673118 | N12: 3653106 | O12: 3633026 | P12: 3612777 | Q12: 3593292 | R12: 3573579 | S12: 3553941 | T12: 3534199 | U12: 3514879 | V12: 3495577 | W12: 3476348 | X12: 3457226 | Y12: 3438219 | Z12: 3419333 | AA12: 3400681 | AB12: 3382150 | AC12: 3363736 | AD12: 3345555 | AE12: 3327609 | AF12: 3310003 | AG12: 3292537 | AH12: 3275286 | AI12: 3258328 | AJ12: 3241722 | AK12: 3225297 | AL12: 3209234 | AM12: 3193560 | AN12: 3177954 | AO12: 3162822 | AP12: 3148039 | AQ12: 3133657 | AR12: 3119809 | AS12: 3106285 | AT12: 3092937 | AU12: 3079755 | AV12: 3066786 | AW12: 3053953 | AX12: 3041405 | AY12: 3029168 | AZ12: 3017290 | BA12: 3005897 | BB12: 2994743 | BC12: 2983966 | BD12: 2973722 | BE12: 2963931 | BF12: 2954455 | BG12: 2945222 | BH12: 2936474 | BI12: 2927987 | BJ12: 2919932 | BK12: 2912165 | BL12: 2904851 | BM12: 2897877 | BN12: 2891372 | BO12: 2885156
A13: IT_POPTF | D13: 59030133 | E13: 59058615 | F13: 59011788 | G13: 58951070 | H13: 58898864 | I13: 58857408 | J13: 58825941 | K13: 58797473 | L13: 58773783 | M13: 58748917 | N13: 58724221 | O13: 58698879 | P13: 58673850 | Q13: 58655761 | R13: 58634551 | S13: 58611890 | T13: 58585665 | U13: 58554890 | V13: 58519597 | W13: 58474892 | X13: 58419277 | Y13: 58352120 | Z13: 58273305 | AA13: 58180562 | AB13: 58074759 | AC13: 57955574 | AD13: 57824037 | AE13: 57677994 | AF13: 57518500 | AG13: 57345588 | AH13: 57158971 | AI13: 56960929 | AJ13: 56754057 | AK13: 56536819 | AL13: 56312447 | AM13: 56081388 | AN13: 55846897 | AO13: 55608272 | AP13: 55368858 | AQ13: 55131061 | AR13: 54897516 | AS13: 54669636 | AT13: 54449230 | AU13: 54236954 | AV13: 54034943 | AW13: 53842372 | AX13: 53660290 | AY13: 53490142 | AZ13: 53332659 | BA13: 53185807 | BB13: 53049977 | BC13: 52924263 | BD13: 52808211 | BE13: 52700144 | BF13: 52598911 | BG13: 52502707 | BH13: 52410959 | BI13: 52321192 | BJ13: 52233701 | BK13: 52146675 | BL13: 52059478 | BM13: 51971090 | BN13: 51880414 | BO13: 51787022
... A28: SE_POPTF | D28: 10452326 | E28: 10561077 | F28: 10640372 | G28: 10705814 | H28: 10770866 | I28: 10835254 | J28: 10898809 | K28: 10960521 | L28: 11020442 | M28: 11078730 | N28: 11135601 | O28: 11191339 | P28: 11246226 | Q28: 11302547 | R28: 11358405 | S28: 11414057 | T28: 11469696 | U28: 11525438 | V28: 11581390 | W28: 11637509 | X28: 11693771 | Y28: 11750034 | Z28: 11806183 | AA28: 11862065 | AB28: 11917473 | AC28: 11972194 | AD28: 12026025 | AE28: 12078774 | AF28: 12130240 | AG28: 12180268 | AH28: 12228784 | AI28: 12275697 | AJ28: 12321107 | AK28: 12365036 | AL28: 12408042 | AM28: 12449352 | AN28: 12488967 | AO28: 12526881 | AP28: 12563488 | AQ28: 12598963 | AR28: 12633438 | AS28: 12667044 | AT28: 12699881 | AU28: 12732058 | AV28: 12763656 | AW28: 12794708 | AX28: 12825244 | AY28: 12855228 | AZ28: 12884585 | BA28: 12913241 | BB28: 12941201 | BC28: 12968420 | BD28: 12994875 | BE28: 13020332 | BF28: 13044915 | BG28: 13067683 | BH28: 13089091 | BI28: 13108827 | BJ28: 13127074 | BK28: 13143596 | BL28: 13158787 | BM28: 13172124 | BN28: 13184043 | BO28: 13194563
A29: UK_POPTF | E29: 68350236 | F29: 69025203 | G29: 69630376 | H29: 70160187 | I29: 70612833 | J29: 70985959 | K29: 71350151 | L29: 71705282 | M29: 72051458 | N29: 72388988 | O29: 72717937 | P29: 73038609 | Q29: 73351615 | R29: 73658795 | S29: 73962122 | T29: 74262408 | U29: 74560211 | V29: 74855850 | W29: 75148911 | X29: 75438895 | Y29: 75725757 | Z29: 76009334 | AA29: 76288178 | AB29: 76560631 | AC29: 76826213 | AD29: 77084491 | AE29: 77334961 | AF29: 77577467 | AG29: 77812181 | AH29: 78039348 | AI29: 78259294 | AJ29: 78472657 | AK29: 78680453 | AL29: 78883741 | AM29: 79083702 | AN29: 79281150 | AO29: 79477080 | AP29: 79672491 | AQ29: 79867988 | AR29: 80064118 | AS29: 80261160 | AT29: 80459378 | AU29: 80659071 | AV29: 80859998 | AW29: 81061772 | AX29: 81263927 | AY29: 81465839 | AZ29: 81666879 | BA29: 81866259 | BB29: 82063118 | BC29: 82256657 | BD29: 82446074 | BE29: 82630720 | BF29: 82809953 | BG29: 82983359 | BH29: 83150611 | BI29: 83311560 | BJ29: 83466167 | BK29: 83614660 | BL29: 83757210 | BM29: 83894174 | BN29: 84026020 | BO29: 84153250
A30: AT_POPAF | D30: 6837668 | E30: 6884008 | F30: 6890532 | G30: 6888193 | H30: 6894192 | I30: 6906336 | J30: 6920644 | K30: 6934297 | L30: 6947847 | M30: 6957388 | N30: 6963136 | O30: 6966648 | P30: 6966279 | Q30: 6963053 | R30: 6954376 | S30: 6941532 | T30: 6924718 | U30: 6905049 | V30: 6884333 | W30: 6863664 | X30: 6842876 | Y30: 6821666 | Z30: 6799625 | AA30: 6780274 | AB30: 6767638 | AC30: 6757394 | AD30: 6750017 | AE30: 6747524 | AF30: 6744479 | AG30: 6743121 | AH30: 6744861 | AI30: 6746817 | AJ30: 6747912 | AK30: 6747125 | AL30: 6740614 | AM30: 6731070 | AN30: 6720536 | AO30: 6712268 | AP30: 6703061 | AQ30: 6693792 | AR30: 6684356 | AS30: 6674157 | AT30: 6661440 | AU30: 6648499 | AV30: 6634555 | AW30: 6619195 | AX30: 6604991 | AY30: 6591852 | AZ30: 6580420 | BA30: 6571310 | BB30: 6560773 | BC30: 6552768 | BD30: 6546787 | BE30: 6542890 | BF30: 6538096 | BG30: 6535898 | BH30: 6531019 | BI30: 6526720 | BJ30: 6520299 | BK30: 6513551 | BL30: 6507759 | BM30: 6503589 | BN30: 6498049 | BO30: 6493838
A31: BE_POPAF | D31: 8620913 | E31: 8700781 | F31: 8745294 | G31: 8777211 | H31: 8809345 | I31: 8839596 | J31: 8863414 | K31: 8884048 | L31: 8902370 | M31: 8915326 | N31: 8925632 | O31: 8931044 | P31: 8932208 | Q31: 8931546 | R31: 8927990 | S31: 8926072 | T31: 8919742 | U31: 8910053 | V31: 8897737 | W31: 8888916 | X31: 8882734 | Y31: 8879622 | Z31: 8876445 | AA31: 8872965 | AB31: 8868129 | AC31: 8864333 | AD31: 8862986 | AE31: 8865212 | AF31: 8870026 | AG31: 8878108 | AH31: 8884620 | AI31: 8889420 | AJ31: 8892907 | AK31: 8894577 | AL31: 8893769 | AM31: 8894287 | AN31: 8895176 | AO31: 8897635 | AP31: 8898714 | AQ31: 8899331 | AR31: 8896340 | AS31: 8891743 | AT31: 8882680 | AU31: 8872449 | AV31: 8858874 | AW31: 8843509 | AX31: 8828032 | AY31: 8814977 | AZ31: 8804948 | BA31: 8794530 | BB31: 8782990 | BC31: 8770884 | BD31: 8759789 | BE31: 8748184 | BF31: 8734708 | BG31: 8722996 | BH31: 8712103 | BI31: 8700112 | BJ31: 8685138 | BK31: 8667613 | BL31: 8647230 | BM31: 8625782 | BN31: 8601471 | BO31: 8577613
A32: BG_POPAF | D32: 5225350 | E32: 5276346 | F32: 5248276 | G32: 5198698 | H32: 5144388 | I32: 5099573 | J32: 5051513 | K32: 5002429 | L32: 4958488 | M32: 4912939 | N32: 4868583 | O32: 4827204 | P32: 4786176 | Q32: 4751956 | R32: 4715001 | S32: 4677908 | T32: 4642327 | U32: 4606429 | V32: 4571967 | W32: 4539055 | X32: 4507048 | Y32: 4473537 | Z32: 4430829 | AA32: 4386515 | AB32: 4343815 | AC32: 4303327 | AD32: 4264719 | AE32: 4221808 | AF32: 4174603 | AG32: 4130551 | AH32: 4087440 | AI32: 4046412 | AJ32: 4008955 | AK32: 3971913 | AL32: 3939112 | AM32: 3907097 | AN32: 3875914 | AO32: 3844335 | AP32: 3812404 | AQ32: 3780743 | AR32: 3747479 | AS32: 3715319 | AT32: 3681338 | AU32: 3649923 | AV32: 3621779 | AW32: 3598865 | AX32: 3580946 | AY32: 3566124 | AZ32: 3555179 | BA32: 3549574 | BB32: 3544155 | BC32: 3543933 | BD32: 3542140 | BE32: 3534806 | BF32: 3527736 | BG32: 3523675 | BH32: 3519651 | BI32: 3514814 | BJ32: 3508572 | BK32: 3500863 | BL32: 3492243 | BM32: 3482916 | BN32: 3471371 | BO32: 3457073
A33: CY_POPAF | D33: 695462 | E33: 709371 | F33: 715171 | G33: 717843 | H33: 719941 | I33: 720955 | J33: 721689 | K33: 721931 | L33: 722274 | M33: 722402 | N33: 722469 | O33: 722030 | P33: 721325 | Q33: 721002 | R33: 720851 | S33: 721001 | T33: 721076 | U33: 721233 | V33: 721523 | W33: 721940 | X33: 722371 | Y33: 722807 | Z33: 723204 | AA33: 723645 | AB33: 723979 | AC33: 724327 | AD33: 724073 | AE33: 723904 | AF33: 724127 | AG33: 724514 | AH33: 723825 | AI33: 723374 | AJ33: 722372 | AK33: 721322 | AL33: 719721 | AM33: 718089 | AN33: 716695 | AO33: 714606 | AP33: 712302 | AQ33: 709798 | AR33: 707034 | AS33: 704511 | AT33: 701422 | AU33: 698962 | AV33: 696424 | AW33: 693976 | AX33: 690804 | AY33: 688263 | AZ33: 686135 | BA33: 684098 | BB33: 682237 | BC33: 680832 | BD33: 680015 | BE33: 679638 | BF33: 679338 | BG33: 679233 | BH33: 679762 | BI33: 680325 | BJ33: 680854 | BK33: 681553 | BL33: 682018 | BM33: 682631 | BN33: 682695 | BO33: 682479
A34: CZ_POPAF | D34: 7929063 | E34: 8224322 | F34: 8269181 | G34: 8231638 | H34: 8191300 | I34: 8142550 | J34: 8094870 | K34: 8051773 | L34: 8015470 | M34: 7982455 | N34: 7954188 | O34: 7931820 | P34: 7914840 | Q34: 7921203 | R34: 7925238 | S34: 7932616 | T34: 7927257 | U34: 7917210 | V34: 7904503 | W34: 7894439 | X34: 7886413 | Y34: 7877638 | Z34: 7867238 | AA34: 7850001 | AB34: 7826270 | AC34: 7796843 | AD34: 7760095 | AE34: 7710522 | AF34: 7652462 | AG34: 7597383 | AH34: 7546187 | AI34: 7500058 | AJ34: 7457977 | AK34: 7421270 | AL34: 7398201 | AM34: 7382451 | AN34: 7367151 | AO34: 7354427 | AP34: 7340761 | AQ34: 7326744 | AR34: 7314697 | AS34: 7303647 | AT34: 7286368 | AU34: 7274269 | AV34: 7259677 | AW34: 7244710 | AX34: 7234320 | AY34: 7223166 | AZ34: 7221746 | BA34: 7228201 | BB34: 7238509 | BC34: 7248415 | BD34: 7258290 | BE34: 7268598 | BF34: 7276248 | BG34: 7282672 | BH34: 7286904 | BI34: 7290829 | BJ34: 7292263 | BK34: 7287438 | BL34: 7280751 | BM34: 7267176 | BN34: 7249359 | BO34: 7234509
A35: DE_POPAF | D35: 62334912 | E35: 63278314 | F35: 63587857 | G35: 63590437 | H35: 63540350 | I35: 63436754 | J35: 63290512 | K35: 63162756 | L35: 63047503 | M35: 62935081 | N35: 62830308 | O35: 62703145 | P35: 62551585 | Q35: 62372775 | R35: 62160562 | S35: 61928904 | T35: 61633810 | U35: 61332230 | V35: 61024896 | W35: 60736830 | X35: 60449802 | Y35: 60189024 | Z35: 59952165 | AA35: 59760081 | AB35: 59636777 | AC35: 59541849 | AD35: 59523904 | AE35: 59561990 | AF35: 59598927 | AG35: 59639850 | AH35: 59655422 | AI35: 59651931 | AJ35: 59637584 | AK35: 59605907 | AL35: 59528924 | AM35: 59447072 | AN35: 59353215 | AO35: 59274831 | AP35: 59194283 | AQ35: 59105030 | AR35: 58989512 | AS35: 58856408 | AT35: 58693587 | AU35: 58550224 | AV35: 58390298 | AW35: 58300923 | AX35: 58231025 | AY35: 58165136 | AZ35: 58114123 | BA35: 58061931 | BB35: 57982556 | BC35: 57883485 | BD35: 57805046 | BE35: 57731345 | BF35: 57658032 | BG35: 57614766 | BH35: 57585424 | BI35: 57562427 | BJ35: 57538283 | BK35: 57518043 | BL35: 57507522 | BM35: 57482108 | BN35: 57448174 | BO35: 57429632
A36: DK_POPAF | D36: 4361591 | E36: 4387415 | F36: 4399159 | G36: 4404628 | H36: 4409246 | I36: 4410313 | J36: 4408425 | K36: 4403999 | L36: 4401391 | M36: 4398811 | N36: 4398674 | O36: 4398115 | P36: 4396602 | Q36: 4396271 | R36: 4393437 | S36: 4392850 | T36: 4386105 | U36: 4380371 | V36: 4373910 | W36: 4366187 | X36: 4356140 | Y36: 4350866 | Z36: 4349778 | AA36: 4350569 | AB36: 4350506 | AC36: 4347108 | AD36: 4342089 | AE36: 4339287 | AF36: 4335480 | AG36: 4330089 | AH36: 4328952 | AI36: 4329502 | AJ36: 4329213 | AK36: 4329959 | AL36: 4331047 | AM36: 4334503 | AN36: 4337114 | AO36: 4340243 | AP36: 4341797 | AQ36: 4340749 | AR36: 4337672 | AS36: 4333501 | AT36: 4326088 | AU36: 4316705 | AV36: 4305268 | AW36: 4293528 | AX36: 4279297 | AY36: 4266067 | AZ36: 4250753 | BA36: 4236098 | BB36: 4223647 | BC36: 4211646 | BD36: 4201306 | BE36: 4191836 | BF36: 4182583 | BG36: 4176567 | BH36: 4172214 | BI36: 4167020 | BJ36: 4161556 | BK36: 4155795 | BL36: 4149484 | BM36: 4143578 | BN36: 4136482 | BO36: 4131073
A37: EE_POPAF | D37: 989033 | E37: 1018630 | F37: 1025981 | G37: 1024751 | H37: 1024234 | I37: 1021734 | J37: 1018390 | K37: 1015255 | L37: 1011695 | M37: 1008258 | N37: 1005414 | O37: 1002164 | P37: 999467 | Q37: 997730 | R37: 995198 | S37: 992759 | T37: 989330 | U37: 987354 | V37: 985358 | W37: 983678 | X37: 981938 | Y37: 980112 | Z37: 977454 | AA37: 974159 | AB37: 970433 | AC37: 966479 | AD37: 962710 | AE37: 959453 | AF37: 956147 | AG37: 953056 | AH37: 949952 | AI37: 946953 | AJ37: 944430 | AK37: 941818 | AL37: 938945 | AM37: 935804 | AN37: 932434 | AO37: 928264 | AP37: 923858 | AQ37: 919466 | AR37: 914846 | AS37: 909414 | AT37: 903389 | AU37: 897703 | AV37: 892837 | AW37: 889576 | AX37: 886526 | AY37: 885130 | AZ37: 884415 | BA37: 884152 | BB37: 883867 | BC37: 884297 | BD37: 884955 | BE37: 885424 | BF37: 885224 | BG37: 885233 | BH37: 884902 | BI37: 884506 | BJ37: 883455 | BK37: 881824 | BL37: 879918 | BM37: 877280 | BN37: 874365 | BO37: 871696
A38: EL_POPAF | D38: 7834213 | E38: 7804526 | F38: 7779706 | G38: 7752511 | H38: 7713396 | I38: 7662866 | J38: 7608885 | K38: 7551457 | L38: 7489857 | M38: 7426102 | N38: 7361199 | O38: 7295767 | P38: 7228336 | Q38: 7155821 | R38: 7085448 | S38: 7021650 | T38: 6950446 | U38: 6881887 | V38: 6810140 | W38: 6735198 | X38: 6655648 | Y38: 6571533 | Z38: 6486532 | AA38: 6406916 | AB38: 6329956 | AC38: 6254175 | AD38: 6179391 | AE38: 6105306 | AF38: 6028255 | AG38: 5952833 | AH38: 5878328 | AI38: 5807018 | AJ38: 5736846 | AK38: 5667254 | AL38: 5599000 | AM38: 5538096 | AN38: 5480762 | AO38: 5427905 | AP38: 5382953 | AQ38: 5344557 | AR38: 5311584 | AS38: 5283776 | AT38: 5255285 | AU38: 5231880 | AV38: 5208265 | AW38: 5187467 | AX38: 5168177 | AY38: 5151603 | AZ38: 5135014 | BA38: 5119215 | BB38: 5105156 | BC38: 5092500 | BD38: 5081539 | BE38: 5071716 | BF38: 5059105 | BG38: 5045792 | BH38: 5030590 | BI38: 5014725 | BJ38: 4999031 | BK38: 4981465 | BL38: 4962553 | BM38: 4942385 | BN38: 4918929 | BO38: 4895454
A39: ES_POPAF | D39: 36069646 | E39: 36574611 | F39: 36928514 | G39: 37204985 | H39: 37444610 | I39: 37626201 | J39: 37721644 | K39: 37795859 | L39: 37878077 | M39: 37932661 | N39: 37962593 | O39: 37939343 | P39: 37880087 | Q39: 37799883 | R39: 37687162 | S39: 37573290 | T39: 37438534 | U39: 37281191 | V39: 37094416 | W39: 36914749 | X39: 36730769 | Y39: 36530701 | Z39: 36334646 | AA39: 36131751 | AB39: 35922836 | AC39: 35704211 | AD39: 35475693 | AE39: 35244568 | AF39: 34998546 | AG39: 34749032 | AH39: 34495999 | AI39: 34257352 | AJ39: 34029573 | AK39: 33831903 | AL39: 33652975 | AM39: 33502394 | AN39: 33376025 | AO39: 33276973 | AP39: 33190144 | AQ39: 33117502 | AR39: 33055777 | AS39: 32999497 | AT39: 32939846 | AU39: 32881275 | AV39: 32821200 | AW39: 32758063 | AX39: 32681971 | AY39: 32610153 | AZ39: 32543628 | BA39: 32473294 | BB39: 32394852 | BC39: 32305217 | BD39: 32214951 | BE39: 32107068 | BF39: 31986790 | BG39: 31865026 | BH39: 31740127 | BI39: 31598349 | BJ39: 31451118 | BK39: 31301092 | BL39: 31143874 | BM39: 30984156 | BN39: 30807299 | BO39: 30652837
A40: FI_POPAF | D40: 4120392 | E40: 4153337 | F40: 4158243 | G40: 4154219 | H40: 4150766 | I40: 4146272 | J40: 4137211 | K40: 4129702 | L40: 4121059 | M40: 4110970 | N40: 4098631 | O40: 4085737 | P40: 4072495 | Q40: 4057213 | R40: 4042293 | S40: 4029861 | T40: 4013146 | U40: 3997985 | V40: 3984115 | W40: 3971527 | X40: 3959278 | Y40: 3947172 | Z40: 3936278 | AA40: 3929213 | AB40: 3923017 | AC40: 3918369 | AD40: 3915172 | AE40: 3913541 | AF40: 3906722 | AG40: 3897010 | AH40: 3885756 | AI40: 3874634 | AJ40: 3864094 | AK40: 3853396 | AL40: 3841992 | AM40: 3829596 | AN40: 3814244 | AO40: 3797587 | AP40: 3781311 | AQ40: 3765950 | AR40: 3751314 | AS40: 3736556 | AT40: 3717353 | AU40: 3697728 | AV40: 3675785 | AW40: 3653881 | AX40: 3630486 | AY40: 3608884 | AZ40: 3586929 | BA40: 3566386 | BB40: 3547684 | BC40: 3530158 | BD40: 3514563 | BE40: 3498154 | BF40: 3482683 | BG40: 3467890 | BH40: 3453439 | BI40: 3437963 | BJ40: 3421466 | BK40: 3404702 | BL40: 3386534 | BM40: 3368311 | BN40: 3349193 | BO40: 3329154
A41: FR_POPAF | D41: 49384199 | E41: 49519112 | F41: 49586835 | G41: 49627382 | H41: 49659296 | I41: 49691311 | J41: 49696281 | K41: 49708077 | L41: 49707992 | M41: 49686693 | N41: 49644897 | O41: 49580350 | P41: 49504300 | Q41: 49411432 | R41: 49304636 | S41: 49202779 | T41: 49148035 | U41: 49051394 | V41: 48941609 | W41: 48836971 | X41: 48734115 | Y41: 48653826 | Z41: 48572025 | AA41: 48484593 | AB41: 48394122 | AC41: 48287754 | AD41: 48179495 | AE41: 48089020 | AF41: 48037105 | AG41: 48023422 | AH41: 48032316 | AI41: 48021090 | AJ41: 48009518 | AK41: 47980388 | AL41: 47905033 | AM41: 47836688 | AN41: 47766447 | AO41: 47731512 | AP41: 47677578 | AQ41: 47611211 | AR41: 47534133 | AS41: 47458578 | AT41: 47375666 | AU41: 47296217 | AV41: 47217251 | AW41: 47149376 | AX41: 47085998 | AY41: 47046501 | AZ41: 47006365 | BA41: 46951042 | BB41: 46890675 | BC41: 46831543 | BD41: 46759781 | BE41: 46682253 | BF41: 46562621 | BG41: 46452817 | BH41: 46348176 | BI41: 46247560 | BJ41: 46140631 | BK41: 46030755 | BL41: 45907280 | BM41: 45794199 | BN41: 45674902 | BO41: 45557111
... A56: SK_POPAF | D56: 4218091 | E56: 4264815 | F56: 4259330 | G56: 4239336 | H56: 4215643 | I56: 4189810 | J56: 4164780 | K56: 4140109 | L56: 4115676 | M56: 4091261 | N56: 4068800 | O56: 4048402 | P56: 4029007 | Q56: 4015337 | R56: 4000053 | S56: 3985166 | T56: 3969440 | U56: 3951883 | V56: 3933635 | W56: 3916324 | X56: 3899488 | Y56: 3883865 | Z56: 3867781 | AA56: 3848699 | AB56: 3827783 | AC56: 3804381 | AD56: 3777368 | AE56: 3746620 | AF56: 3712962 | AG56: 3679577 | AH56: 3645041 | AI56: 3610714 | AJ56: 3576708 | AK56: 3542716 | AL56: 3512747 | AM56: 3484148 | AN56: 3455652 | AO56: 3427654 | AP56: 3399771 | AQ56: 3371873 | AR56: 3346242 | AS56: 3322576 | AT56: 3298549 | AU56: 3277171 | AV56: 3255575 | AW56: 3234588 | AX56: 3216286 | AY56: 3198779 | AZ56: 3186405 | BA56: 3177789 | BB56: 3169899 | BC56: 3162478 | BD56: 3156164 | BE56: 3150653 | BF56: 3145606 | BG56: 3143232 | BH56: 3141317 | BI56: 3138440 | BJ56: 3133891 | BK56: 3128022 | BL56: 3123053 | BM56: 3117774 | BN56: 3110075 | BO56: 3100692
A57: UK_POPAF | E57: 50565232 | F57: 51090144 | G57: 51581523 | H57: 52040729 | I57: 52445289 | J57: 52754389 | K57: 53039068 | L57: 53324747 | M57: 53596510 | N57: 53827042 | O57: 54018784 | P57: 54186018 | Q57: 54328716 | R57: 54421856 | S57: 54506185 | T57: 54545054 | U57: 54615000 | V57: 54684507 | W57: 54764175 | X57: 54845230 | Y57: 54934202 | Z57: 55024561 | AA57: 55134853 | AB57: 55228240 | AC57: 55351148 | AD57: 55503102 | AE57: 55683092 | AF57: 55871935 | AG57: 56074297 | AH57: 56293362 | AI57: 56501360 | AJ57: 56661375 | AK57: 56792094 | AL57: 56925055 | AM57: 57063460 | AN57: 57196732 | AO57: 57327396 | AP57: 57428524 | AQ57: 57518560 | AR57: 57593288 | AS57: 57640247 | AT57: 57685379 | AU57: 57713946 | AV57: 57727447 | AW57: 57738973 | AX57: 57763266 | AY57: 57779224 | AZ57: 57805200 | BA57: 57834642 | BB57: 57848881 | BC57: 57869694 | BD57: 57886165 | BE57: 57916447 | BF57: 57948230 | BG57: 57975548 | BH57: 57998142 | BI57: 58012651 | BJ57: 58028234 | BK57: 58047279 | BL57: 58055601 | BM57: 58038952 | BN57: 58029583 | BO57: 58017252
A58: US_POPTF | D58: 333287557 | E58: 334906305 | F58: 336482168 | G58: 338016259 | H58: 339513045 | I58: 340970496 | J58: 342384777 | K58: 343753791 | L58: 345073565 | M58: 346339264 | N58: 347545098 | O58: 348701812 | P58: 349807647 | Q58: 350861084 | R58: 351860944 | S58: 352806047 | T58: 353695674 | U58: 354529853 | V58: 355309062 | W58: 356033543 | X58: 356705435 | Y58: 357327409 | Z58: 357903394 | AA58: 358437973 | AB58: 358935938 | AC58: 359400325 | AD58: 359835763 | AE58: 360246998 | AF58: 360638734 | AG58: 361015337 | AH58: 361380913 | AI58: 361739492 | AJ58: 362094696 | AK58: 362449657 | AL58: 362807020 | AM58: 363168681 | AN58: 363535845 | AO58: 363908874 | AP58: 364287256 | AQ58: 364670485 | AR58: 365056681 | AS58: 365443472 | AT58: 365828051 | AU58: 366207441 | AV58: 366578659 | AW58: 366938404 | AX58: 367283143 | AY58: 367609110 | AZ58: 367912529 | BA58: 368190295 | BB58: 368440720 | BC58: 368662821 | BD58: 368855708 | BE58: 369018330 | BF58: 369150061 | BG58: 369250247 | BH58: 369318787 | BI58: 369356023 | BJ58: 369362531 | BK58: 369339625 | BL58: 369289076 | BM58: 369213005 | BN58: 369113662 | BO58: 368992800
A59: US_POPAF | D59: 249843757 | E59: 250897599 | F59: 251802668 | G59: 252615050 | H59: 253281965 | I59: 253832033 | J59: 254328551 | K59: 254773384 | L59: 255179717 | M59: 255535040 | N59: 255693830 | O59: 255780115 | P59: 255813715 | Q59: 255792929 | R59: 255663572 | S59: 255674341 | T59: 255702030 | U59: 255775146 | V59: 255966573 | W59: 256315339 | X59: 256737012 | Y59: 257195478 | Z59: 257607729 | AA59: 257920825 | AB59: 258206100 | AC59: 258698158 | AD59: 259346509 | AE59: 260038055 | AF59: 260673802 | AG59: 261340291 | AH59: 261894052 | AI59: 262397703 | AJ59: 262816150 | AK59: 263085591 | AL59: 263321737 | AM59: 263491920 | AN59: 263635299 | AO59: 263803043 | AP59: 263872762 | AQ59: 263913821 | AR59: 263932075 | AS59: 263880684 | AT59: 263735725 | AU59: 263457478 | AV59: 263159632 | AW59: 262882704 | AX59: 262652006 | AY59: 262440431 | AZ59: 262260834 | BA59: 262100534 | BB59: 261912265 | BC59: 261654911 | BD59: 261300158 | BE59: 260780136 | BF59: 260189275 | BG59: 259799659 | BH59: 259498174 | BI59: 259145701 | BJ59: 258796966 | BK59: 258395555 | BL59: 257915286 | BM59: 257408837 | BN59: 257013044 | BO59: 256667544

Sheet compare to previous update
A1: =popproj!A1 -> date | B1: =popproj!B1 -> 2020 | C1: =popproj!C1 -> 2021 | D1: =popproj!D1 -> 2022 | E1: =popproj!E1 -> 2023 | F1: =popproj!F1 -> 2024 | G1: =popproj!G1 -> 2025 | H1: =popproj!H1 -> 2026 | ... BO1: =popproj!BO1 -> 0
A2: =popproj!A2 -> BE_POPTF | D2: =IF(popproj!D2-old!D2=0,"",(popproj!D2-old!D2)/old!D2) -> -1 | E2: =IF(popproj!E2-old!E2=0,"",(popproj!E2-old!E2)/old!E2) -> 0.0010343832 | F2: =IF(popproj!F2-old!F2=0,"",(popproj!F2-old!F2)/old!F2) -> 0.0035909271 | G2: =IF(popproj!G2-old!G2=0,"",(popproj!G2-old!G2)/old!G2) -> 0.0069575738 | H2: =IF(popproj!H2-old!H2=0,"",(popproj!H2-old!H2)/old!H2) -> 0.0081626507 | I2: =IF(popproj!I2-old!I2=0,"",(popproj!I2-old!I2)/old!I2) -> 0.0089591121 | J2: =IF(popproj!J2-old!J2=0,"",(popproj!J2-old!J2)/old!J2) -> 0.0093469975 | K2: =IF(popproj!K2-old!K2=0,"",(popproj!K2-old!K2)/old!K2) -> 0.0095624144 | ... BO2: =IF(popproj!BO2-old!BO2=0,"",(popproj!BO2-old!BO2)/old!BO2) -> -1
A3: =popproj!A3 -> BG_POPTF | D3: =IF(popproj!D3-old!D3=0,"",(popproj!D3-old!D3)/old!D3) -> -1 | E3: =IF(popproj!E3-old!E3=0,"",(popproj!E3-old!E3)/old!E3) -> -0.057067945 | F3: =IF(popproj!F3-old!F3=0,"",(popproj!F3-old!F3)/old!F3) -> -0.060586482 | G3: =IF(popproj!G3-old!G3=0,"",(popproj!G3-old!G3)/old!G3) -> -0.054282515 | H3: =IF(popproj!H3-old!H3=0,"",(popproj!H3-old!H3)/old!H3) -> -0.0513044 | I3: =IF(popproj!I3-old!I3=0,"",(popproj!I3-old!I3)/old!I3) -> -0.048805376 | J3: =IF(popproj!J3-old!J3=0,"",(popproj!J3-old!J3)/old!J3) -> -0.046847378 | K3: =IF(popproj!K3-old!K3=0,"",(popproj!K3-old!K3)/old!K3) -> -0.045029319 | ... BO3: =IF(popproj!BO3-old!BO3=0,"",(popproj!BO3-old!BO3)/old!BO3) -> -1
A4: =popproj!A4 -> CZ_POPTF | D4: =IF(popproj!D4-old!D4=0,"",(popproj!D4-old!D4)/old!D4) -> -1 | E4: =IF(popproj!E4-old!E4=0,"",(popproj!E4-old!E4)/old!E4) -> -0.012437103 | F4: =IF(popproj!F4-old!F4=0,"",(popproj!F4-old!F4)/old!F4) -> -0.013476581 | G4: =IF(popproj!G4-old!G4=0,"",(popproj!G4-old!G4)/old!G4) -> -0.011483261 | H4: =IF(popproj!H4-old!H4=0,"",(popproj!H4-old!H4)/old!H4) -> -0.010850083 | I4: =IF(popproj!I4-old!I4=0,"",(popproj!I4-old!I4)/old!I4) -> -0.010064213 | J4: =IF(popproj!J4-old!J4=0,"",(popproj!J4-old!J4)/old!J4) -> -0.0090981377 | K4: =IF(popproj!K4-old!K4=0,"",(popproj!K4-old!K4)/old!K4) -> -0.0083303829 | ... BO4: =IF(popproj!BO4-old!BO4=0,"",(popproj!BO4-old!BO4)/old!BO4) -> -1
A5: =popproj!A5 -> DK_POPTF | D5: =IF(popproj!D5-old!D5=0,"",(popproj!D5-old!D5)/old!D5) -> -1 | E5: =IF(popproj!E5-old!E5=0,"",(popproj!E5-old!E5)/old!E5) -> 0.00078998362 | F5: =IF(popproj!F5-old!F5=0,"",(popproj!F5-old!F5)/old!F5) -> 0.00032302322 | G5: =IF(popproj!G5-old!G5=0,"",(popproj!G5-old!G5)/old!G5) -> 0.0014480117 | H5: =IF(popproj!H5-old!H5=0,"",(popproj!H5-old!H5)/old!H5) -> 0.0023346616 | I5: =IF(popproj!I5-old!I5=0,"",(popproj!I5-old!I5)/old!I5) -> 0.0030255438 | J5: =IF(popproj!J5-old!J5=0,"",(popproj!J5-old!J5)/old!J5) -> 0.0035642043 | K5: =IF(popproj!K5-old!K5=0,"",(popproj!K5-old!K5)/old!K5) -> 0.0041168348 | ... BO5: =IF(popproj!BO5-old!BO5=0,"",(popproj!BO5-old!BO5)/old!BO5) -> -1
A6: =popproj!A6 -> DE_POPTF | D6: =IF(popproj!D6-old!D6=0,"",(popproj!D6-old!D6)/old!D6) -> -1 | E6: =IF(popproj!E6-old!E6=0,"",(popproj!E6-old!E6)/old!E6) -> -0.016953226 | F6: =IF(popproj!F6-old!F6=0,"",(popproj!F6-old!F6)/old!F6) -> -0.018778276 | G6: =IF(popproj!G6-old!G6=0,"",(popproj!G6-old!G6)/old!G6) -> -0.016354391 | H6: =IF(popproj!H6-old!H6=0,"",(popproj!H6-old!H6)/old!H6) -> -0.016061213 | I6: =IF(popproj!I6-old!I6=0,"",(popproj!I6-old!I6)/old!I6) -> -0.015879373 | J6: =IF(popproj!J6-old!J6=0,"",(popproj!J6-old!J6)/old!J6) -> -0.015814126 | K6: =IF(popproj!K6-old!K6=0,"",(popproj!K6-old!K6)/old!K6) -> -0.015816631 | ... BO6: =IF(popproj!BO6-old!BO6=0,"",(popproj!BO6-old!BO6)/old!BO6) -> -1
A7: =popproj!A7 -> EE_POPTF | D7: =IF(popproj!D7-old!D7=0,"",(popproj!D7-old!D7)/old!D7) -> -1 | E7: =IF(popproj!E7-old!E7=0,"",(popproj!E7-old!E7)/old!E7) -> -0.0043249209 | F7: =IF(popproj!F7-old!F7=0,"",(popproj!F7-old!F7)/old!F7) -> -0.0039640389 | G7: =IF(popproj!G7-old!G7=0,"",(popproj!G7-old!G7)/old!G7) -> -0.0043433158 | H7: =IF(popproj!H7-old!H7=0,"",(popproj!H7-old!H7)/old!H7) -> -0.0036759088 | I7: =IF(popproj!I7-old!I7=0,"",(popproj!I7-old!I7)/old!I7) -> -0.0031108511 | J7: =IF(popproj!J7-old!J7=0,"",(popproj!J7-old!J7)/old!J7) -> -0.0026425425 | K7: =IF(popproj!K7-old!K7=0,"",(popproj!K7-old!K7)/old!K7) -> -0.0022834033 | ... BO7: =IF(popproj!BO7-old!BO7=0,"",(popproj!BO7-old!BO7)/old!BO7) -> -1
A8: =popproj!A8 -> IE_POPTF | D8: =IF(popproj!D8-old!D8=0,"",(popproj!D8-old!D8)/old!D8) -> -1 | E8: =IF(popproj!E8-old!E8=0,"",(popproj!E8-old!E8)/old!E8) -> 0.01876722 | F8: =IF(popproj!F8-old!F8=0,"",(popproj!F8-old!F8)/old!F8) -> 0.022567143 | G8: =IF(popproj!G8-old!G8=0,"",(popproj!G8-old!G8)/old!G8) -> 0.028558886 | H8: =IF(popproj!H8-old!H8=0,"",(popproj!H8-old!H8)/old!H8) -> 0.030038795 | I8: =IF(popproj!I8-old!I8=0,"",(popproj!I8-old!I8)/old!I8) -> 0.030955206 | J8: =IF(popproj!J8-old!J8=0,"",(popproj!J8-old!J8)/old!J8) -> 0.031297397 | K8: =IF(popproj!K8-old!K8=0,"",(popproj!K8-old!K8)/old!K8) -> 0.031354022 | ... BO8: =IF(popproj!BO8-old!BO8=0,"",(popproj!BO8-old!BO8)/old!BO8) -> -1
A9: =popproj!A9 -> EL_POPTF | D9: =IF(popproj!D9-old!D9=0,"",(popproj!D9-old!D9)/old!D9) -> -1 | E9: =IF(popproj!E9-old!E9=0,"",(popproj!E9-old!E9)/old!E9) -> -0.00024576294 | F9: =IF(popproj!F9-old!F9=0,"",(popproj!F9-old!F9)/old!F9) -> 0.0024703102 | G9: =IF(popproj!G9-old!G9=0,"",(popproj!G9-old!G9)/old!G9) -> 0.0023625136 | H9: =IF(popproj!H9-old!H9=0,"",(popproj!H9-old!H9)/old!H9) -> 0.0014397636 | I9: =IF(popproj!I9-old!I9=0,"",(popproj!I9-old!I9)/old!I9) -> 0.00063825667 | J9: =IF(popproj!J9-old!J9=0,"",(popproj!J9-old!J9)/old!J9) -> -6.236895e-05 | K9: =IF(popproj!K9-old!K9=0,"",(popproj!K9-old!K9)/old!K9) -> -0.00038135042 | ... BO9: =IF(popproj!BO9-old!BO9=0,"",(popproj!BO9-old!BO9)/old!BO9) -> -1
A10: =popproj!A10 -> ES_POPTF | D10: =IF(popproj!D10-old!D10=0,"",(popproj!D10-old!D10)/old!D10) -> -1 | E10: =IF(popproj!E10-old!E10=0,"",(popproj!E10-old!E10)/old!E10) -> 0.002187915 | F10: =IF(popproj!F10-old!F10=0,"",(popproj!F10-old!F10)/old!F10) -> 0.005463477 | G10: =IF(popproj!G10-old!G10=0,"",(popproj!G10-old!G10)/old!G10) -> 0.0090886669 | H10: =IF(popproj!H10-old!H10=0,"",(popproj!H10-old!H10)/old!H10) -> 0.011583993 | I10: =IF(popproj!I10-old!I10=0,"",(popproj!I10-old!I10)/old!I10) -> 0.013899723 | J10: =IF(popproj!J10-old!J10=0,"",(popproj!J10-old!J10)/old!J10) -> 0.01594611 | K10: =IF(popproj!K10-old!K10=0,"",(popproj!K10-old!K10)/old!K10) -> 0.017748053 | ... BO10: =IF(popproj!BO10-old!BO10=0,"",(popproj!BO10-old!BO10)/old!BO10) -> -1
A11: =popproj!A11 -> FR_POPTF | D11: =IF(popproj!D11-old!D11=0,"",(popproj!D11-old!D11)/old!D11) -> -1 | E11: =IF(popproj!E11-old!E11=0,"",(popproj!E11-old!E11)/old!E11) -> -0.00080112698 | F11: =IF(popproj!F11-old!F11=0,"",(popproj!F11-old!F11)/old!F11) -> -0.00096106492 | G11: =IF(popproj!G11-old!G11=0,"",(popproj!G11-old!G11)/old!G11) -> -0.00073086657 | H11: =IF(popproj!H11-old!H11=0,"",(popproj!H11-old!H11)/old!H11) -> -0.00018275839 | I11: =IF(popproj!I11-old!I11=0,"",(popproj!I11-old!I11)/old!I11) -> 0.00053865449 | J11: =IF(popproj!J11-old!J11=0,"",(popproj!J11-old!J11)/old!J11) -> 0.0014419536 | K11: =IF(popproj!K11-old!K11=0,"",(popproj!K11-old!K11)/old!K11) -> 0.0022088536 | ... BO11: =IF(popproj!BO11-old!BO11=0,"",(popproj!BO11-old!BO11)/old!BO11) -> -1
